Workbook
Name _: '[1]1999 BUDGET'!#REF!
Name __: '[1]1999 BUDGET'!#REF!
Name ___: '[1]1999 BUDGET'!#REF!
Name ____: '[1]1999 BUDGET'!#REF!
Name ________________TX3: {#N/A,#N/A,FALSE,"Aging Summary";#N/A,#N/A,FALSE,"Ratio Analysis";#N/A,#N/A,FALSE,"Test 120 Day Accts";#N/A,#N/A,FALSE,"Tickmarks"}
Name ________________TX3: {#N/A,#N/A,FALSE,"Aging Summary";#N/A,#N/A,FALSE,"Ratio Analysis";#N/A,#N/A,FALSE,"Test 120 Day Accts";#N/A,#N/A,FALSE,"Tickmarks"}
Name ________________TX3: {#N/A,#N/A,FALSE,"Aging Summary";#N/A,#N/A,FALSE,"Ratio Analysis";#N/A,#N/A,FALSE,"Test 120 Day Accts";#N/A,#N/A,FALSE,"Tickmarks"}
Name ________________TX3: {#N/A,#N/A,FALSE,"Aging Summary";#N/A,#N/A,FALSE,"Ratio Analysis";#N/A,#N/A,FALSE,"Test 120 Day Accts";#N/A,#N/A,FALSE,"Tickmarks"}
Name _______________TX2: {#N/A,#N/A,FALSE,"Aging Summary";#N/A,#N/A,FALSE,"Ratio Analysis";#N/A,#N/A,FALSE,"Test 120 Day Accts";#N/A,#N/A,FALSE,"Tickmarks"}
Name _______________TX2: {#N/A,#N/A,FALSE,"Aging Summary";#N/A,#N/A,FALSE,"Ratio Analysis";#N/A,#N/A,FALSE,"Test 120 Day Accts";#N/A,#N/A,FALSE,"Tickmarks"}
Name _______________TX2: {#N/A,#N/A,FALSE,"Aging Summary";#N/A,#N/A,FALSE,"Ratio Analysis";#N/A,#N/A,FALSE,"Test 120 Day Accts";#N/A,#N/A,FALSE,"Tickmarks"}
Name _______________TX2: {#N/A,#N/A,FALSE,"Aging Summary";#N/A,#N/A,FALSE,"Ratio Analysis";#N/A,#N/A,FALSE,"Test 120 Day Accts";#N/A,#N/A,FALSE,"Tickmarks"}
Name ____________OK2: {#N/A,#N/A,FALSE,"Cover";#N/A,#N/A,FALSE,"LUMI";#N/A,#N/A,FALSE,"COMD";#N/A,#N/A,FALSE,"Valuation";#N/A,#N/A,FALSE,"Assumptions";#N/A,#N/A,FALSE,"Pooling";#N/A,#N/A,FALSE,"BalanceSheet"}
Name ____________OK2: {#N/A,#N/A,FALSE,"Cover";#N/A,#N/A,FALSE,"LUMI";#N/A,#N/A,FALSE,"COMD";#N/A,#N/A,FALSE,"Valuation";#N/A,#N/A,FALSE,"Assumptions";#N/A,#N/A,FALSE,"Pooling";#N/A,#N/A,FALSE,"BalanceSheet"}
Name ____________OK2: {#N/A,#N/A,FALSE,"Cover";#N/A,#N/A,FALSE,"LUMI";#N/A,#N/A,FALSE,"COMD";#N/A,#N/A,FALSE,"Valuation";#N/A,#N/A,FALSE,"Assumptions";#N/A,#N/A,FALSE,"Pooling";#N/A,#N/A,FALSE,"BalanceSheet"}
Name ____________OK2: {#N/A,#N/A,FALSE,"Cover";#N/A,#N/A,FALSE,"LUMI";#N/A,#N/A,FALSE,"COMD";#N/A,#N/A,FALSE,"Valuation";#N/A,#N/A,FALSE,"Assumptions";#N/A,#N/A,FALSE,"Pooling";#N/A,#N/A,FALSE,"BalanceSheet"}
Name ___________k: {#N/A,#N/A,TRUE,"A-site";#N/A,#N/A,TRUE,"B-Buildings";#N/A,#N/A,TRUE,"c-out-of-fence";#N/A,#N/A,TRUE,"d-proj.infr.";#N/A,#N/A,TRUE,"e- land"}
Name ___________k: {#N/A,#N/A,TRUE,"A-site";#N/A,#N/A,TRUE,"B-Buildings";#N/A,#N/A,TRUE,"c-out-of-fence";#N/A,#N/A,TRUE,"d-proj.infr.";#N/A,#N/A,TRUE,"e- land"}
Name ___________k: {#N/A,#N/A,TRUE,"A-site";#N/A,#N/A,TRUE,"B-Buildings";#N/A,#N/A,TRUE,"c-out-of-fence";#N/A,#N/A,TRUE,"d-proj.infr.";#N/A,#N/A,TRUE,"e- land"}
Name ___________k: {#N/A,#N/A,TRUE,"A-site";#N/A,#N/A,TRUE,"B-Buildings";#N/A,#N/A,TRUE,"c-out-of-fence";#N/A,#N/A,TRUE,"d-proj.infr.";#N/A,#N/A,TRUE,"e- land"}
Name ___________OK2: {#N/A,#N/A,FALSE,"Cover";#N/A,#N/A,FALSE,"LUMI";#N/A,#N/A,FALSE,"COMD";#N/A,#N/A,FALSE,"Valuation";#N/A,#N/A,FALSE,"Assumptions";#N/A,#N/A,FALSE,"Pooling";#N/A,#N/A,FALSE,"BalanceSheet"}
Name ___________OK2: {#N/A,#N/A,FALSE,"Cover";#N/A,#N/A,FALSE,"LUMI";#N/A,#N/A,FALSE,"COMD";#N/A,#N/A,FALSE,"Valuation";#N/A,#N/A,FALSE,"Assumptions";#N/A,#N/A,FALSE,"Pooling";#N/A,#N/A,FALSE,"BalanceSheet"}
Name ___________OK2: {#N/A,#N/A,FALSE,"Cover";#N/A,#N/A,FALSE,"LUMI";#N/A,#N/A,FALSE,"COMD";#N/A,#N/A,FALSE,"Valuation";#N/A,#N/A,FALSE,"Assumptions";#N/A,#N/A,FALSE,"Pooling";#N/A,#N/A,FALSE,"BalanceSheet"}
Name ___________OK2: {#N/A,#N/A,FALSE,"Cover";#N/A,#N/A,FALSE,"LUMI";#N/A,#N/A,FALSE,"COMD";#N/A,#N/A,FALSE,"Valuation";#N/A,#N/A,FALSE,"Assumptions";#N/A,#N/A,FALSE,"Pooling";#N/A,#N/A,FALSE,"BalanceSheet"}
Name ___________w: {#N/A,#N/A,TRUE,"A-site";#N/A,#N/A,TRUE,"B-Buildings";#N/A,#N/A,TRUE,"c-out-of-fence";#N/A,#N/A,TRUE,"d-proj.infr.";#N/A,#N/A,TRUE,"e- land"}
Name ___________w: {#N/A,#N/A,TRUE,"A-site";#N/A,#N/A,TRUE,"B-Buildings";#N/A,#N/A,TRUE,"c-out-of-fence";#N/A,#N/A,TRUE,"d-proj.infr.";#N/A,#N/A,TRUE,"e- land"}
Name ___________w: {#N/A,#N/A,TRUE,"A-site";#N/A,#N/A,TRUE,"B-Buildings";#N/A,#N/A,TRUE,"c-out-of-fence";#N/A,#N/A,TRUE,"d-proj.infr.";#N/A,#N/A,TRUE,"e- land"}
Name ___________w: {#N/A,#N/A,TRUE,"A-site";#N/A,#N/A,TRUE,"B-Buildings";#N/A,#N/A,TRUE,"c-out-of-fence";#N/A,#N/A,TRUE,"d-proj.infr.";#N/A,#N/A,TRUE,"e- land"}
Name __________OK2: {#N/A,#N/A,FALSE,"Cover";#N/A,#N/A,FALSE,"LUMI";#N/A,#N/A,FALSE,"COMD";#N/A,#N/A,FALSE,"Valuation";#N/A,#N/A,FALSE,"Assumptions";#N/A,#N/A,FALSE,"Pooling";#N/A,#N/A,FALSE,"BalanceSheet"}
Name __________OK2: {#N/A,#N/A,FALSE,"Cover";#N/A,#N/A,FALSE,"LUMI";#N/A,#N/A,FALSE,"COMD";#N/A,#N/A,FALSE,"Valuation";#N/A,#N/A,FALSE,"Assumptions";#N/A,#N/A,FALSE,"Pooling";#N/A,#N/A,FALSE,"BalanceSheet"}
Name __________OK2: {#N/A,#N/A,FALSE,"Cover";#N/A,#N/A,FALSE,"LUMI";#N/A,#N/A,FALSE,"COMD";#N/A,#N/A,FALSE,"Valuation";#N/A,#N/A,FALSE,"Assumptions";#N/A,#N/A,FALSE,"Pooling";#N/A,#N/A,FALSE,"BalanceSheet"}
Name __________OK2: {#N/A,#N/A,FALSE,"Cover";#N/A,#N/A,FALSE,"LUMI";#N/A,#N/A,FALSE,"COMD";#N/A,#N/A,FALSE,"Valuation";#N/A,#N/A,FALSE,"Assumptions";#N/A,#N/A,FALSE,"Pooling";#N/A,#N/A,FALSE,"BalanceSheet"}
Name _________key1: '[2]Inc & Exp Assump (1)'!#REF!
Name _________key1: '[2]Inc & Exp Assump (1)'!#REF!
Name _________key2: '[2]Inc & Exp Assump (1)'!#REF!
Name _________key2: '[2]Inc & Exp Assump (1)'!#REF!
Name _________OK2: {#N/A,#N/A,FALSE,"Cover";#N/A,#N/A,FALSE,"LUMI";#N/A,#N/A,FALSE,"COMD";#N/A,#N/A,FALSE,"Valuation";#N/A,#N/A,FALSE,"Assumptions";#N/A,#N/A,FALSE,"Pooling";#N/A,#N/A,FALSE,"BalanceSheet"}
Name _________OK2: {#N/A,#N/A,FALSE,"Cover";#N/A,#N/A,FALSE,"LUMI";#N/A,#N/A,FALSE,"COMD";#N/A,#N/A,FALSE,"Valuation";#N/A,#N/A,FALSE,"Assumptions";#N/A,#N/A,FALSE,"Pooling";#N/A,#N/A,FALSE,"BalanceSheet"}
Name _________OK2: {#N/A,#N/A,FALSE,"Cover";#N/A,#N/A,FALSE,"LUMI";#N/A,#N/A,FALSE,"COMD";#N/A,#N/A,FALSE,"Valuation";#N/A,#N/A,FALSE,"Assumptions";#N/A,#N/A,FALSE,"Pooling";#N/A,#N/A,FALSE,"BalanceSheet"}
Name _________OK2: {#N/A,#N/A,FALSE,"Cover";#N/A,#N/A,FALSE,"LUMI";#N/A,#N/A,FALSE,"COMD";#N/A,#N/A,FALSE,"Valuation";#N/A,#N/A,FALSE,"Assumptions";#N/A,#N/A,FALSE,"Pooling";#N/A,#N/A,FALSE,"BalanceSheet"}
Name ________key1: '[2]Inc & Exp Assump (1)'!#REF!
Name ________key1: '[2]Inc & Exp Assump (1)'!#REF!
Name ________key2: '[2]Inc & Exp Assump (1)'!#REF!
Name ________key2: '[2]Inc & Exp Assump (1)'!#REF!
Name ________OK2: {#N/A,#N/A,FALSE,"Cover";#N/A,#N/A,FALSE,"LUMI";#N/A,#N/A,FALSE,"COMD";#N/A,#N/A,FALSE,"Valuation";#N/A,#N/A,FALSE,"Assumptions";#N/A,#N/A,FALSE,"Pooling";#N/A,#N/A,FALSE,"BalanceSheet"}
Name ________OK2: {#N/A,#N/A,FALSE,"Cover";#N/A,#N/A,FALSE,"LUMI";#N/A,#N/A,FALSE,"COMD";#N/A,#N/A,FALSE,"Valuation";#N/A,#N/A,FALSE,"Assumptions";#N/A,#N/A,FALSE,"Pooling";#N/A,#N/A,FALSE,"BalanceSheet"}
Name ________OK2: {#N/A,#N/A,FALSE,"Cover";#N/A,#N/A,FALSE,"LUMI";#N/A,#N/A,FALSE,"COMD";#N/A,#N/A,FALSE,"Valuation";#N/A,#N/A,FALSE,"Assumptions";#N/A,#N/A,FALSE,"Pooling";#N/A,#N/A,FALSE,"BalanceSheet"}
Name ________OK2: {#N/A,#N/A,FALSE,"Cover";#N/A,#N/A,FALSE,"LUMI";#N/A,#N/A,FALSE,"COMD";#N/A,#N/A,FALSE,"Valuation";#N/A,#N/A,FALSE,"Assumptions";#N/A,#N/A,FALSE,"Pooling";#N/A,#N/A,FALSE,"BalanceSheet"}
Name _______a1: {"Assump",#N/A,TRUE,"Proforma";"first",#N/A,TRUE,"Proforma";"second",#N/A,TRUE,"Proforma";"lease1",#N/A,TRUE,"Proforma";"lease2",#N/A,TRUE,"Proforma"}
Name _______a1: {"Assump",#N/A,TRUE,"Proforma";"first",#N/A,TRUE,"Proforma";"second",#N/A,TRUE,"Proforma";"lease1",#N/A,TRUE,"Proforma";"lease2",#N/A,TRUE,"Proforma"}
Name _______a1: {"Assump",#N/A,TRUE,"Proforma";"first",#N/A,TRUE,"Proforma";"second",#N/A,TRUE,"Proforma";"lease1",#N/A,TRUE,"Proforma";"lease2",#N/A,TRUE,"Proforma"}
Name _______a1: {"Assump",#N/A,TRUE,"Proforma";"first",#N/A,TRUE,"Proforma";"second",#N/A,TRUE,"Proforma";"lease1",#N/A,TRUE,"Proforma";"lease2",#N/A,TRUE,"Proforma"}
Name _______key1: '[2]Inc & Exp Assump (1)'!#REF!
Name _______key1: '[2]Inc & Exp Assump (1)'!#REF!
Name _______key2: '[2]Inc & Exp Assump (1)'!#REF!
Name _______key2: '[2]Inc & Exp Assump (1)'!#REF!
Name _______OK2: {#N/A,#N/A,FALSE,"Cover";#N/A,#N/A,FALSE,"LUMI";#N/A,#N/A,FALSE,"COMD";#N/A,#N/A,FALSE,"Valuation";#N/A,#N/A,FALSE,"Assumptions";#N/A,#N/A,FALSE,"Pooling";#N/A,#N/A,FALSE,"BalanceSheet"}
Name _______OK2: {#N/A,#N/A,FALSE,"Cover";#N/A,#N/A,FALSE,"LUMI";#N/A,#N/A,FALSE,"COMD";#N/A,#N/A,FALSE,"Valuation";#N/A,#N/A,FALSE,"Assumptions";#N/A,#N/A,FALSE,"Pooling";#N/A,#N/A,FALSE,"BalanceSheet"}
Name _______OK2: {#N/A,#N/A,FALSE,"Cover";#N/A,#N/A,FALSE,"LUMI";#N/A,#N/A,FALSE,"COMD";#N/A,#N/A,FALSE,"Valuation";#N/A,#N/A,FALSE,"Assumptions";#N/A,#N/A,FALSE,"Pooling";#N/A,#N/A,FALSE,"BalanceSheet"}
Name _______OK2: {#N/A,#N/A,FALSE,"Cover";#N/A,#N/A,FALSE,"LUMI";#N/A,#N/A,FALSE,"COMD";#N/A,#N/A,FALSE,"Valuation";#N/A,#N/A,FALSE,"Assumptions";#N/A,#N/A,FALSE,"Pooling";#N/A,#N/A,FALSE,"BalanceSheet"}

Sheet Summary & Assumptions
C1: 425 Colorado Street - Glendale, CA
C4: Property Information | J4: Sources & Uses
C5: Name | H5: Glendale Office Multi Conversion | J5: Sources | K5: At Close | L5: Post Close | M5: Total | N5: $/Unit | O5: $/GSF | P5: % Total
C6: Address | H6: 425 Colorado Ave | J6: Acquisition Loan | K6: =L24 -> 15840000 | L6: =-K6 -> -15840000 | M6: =K6+L6 -> 0
C7: City, State | H7: Glendale, CA | J7: Senior Construction Loan | K7: 0 | L7: =L29 -> 32469958 | M7: =K7+L7 -> 32469958 | N7: =$M7/$D$34 -> 225485.82 | O7: =$M7/$H$16 -> 318.58279 | P7: =M7/$M$19 -> 0.551227
C8: Zip | H8: 91205 | J8: Equity | K8: =K19-SUM(K6:K7) -> 13905817 | L8: =M8-K8 -> 12529100 | M8: =M19-SUM(M6:M7) -> 26434917 | N8: =$M8/$D$34 -> 183575.82 | O8: =$M8/$H$16 -> 259.36928 | P8: =M8/$M$19 -> 0.448773
J9: Total Sources | K9: =SUM(K6:K8) -> 29745817 | L9: =SUM(L6:L8) -> 29159058 | M9: =SUM(M6:M8) -> 58904875 | N9: =M9/$D$34 -> 409061.63 | O9: =$M9/$H$16 -> 577.95207 | P9: =SUM(P7:P8) -> 1
C10: Project Size | J10: Uses | K10: At Close | L10: Post Close | M10: Total | P10: % Total
C11: Total Gross SF | H11: =SUM(H12:H15) -> 132765 | J11: Land Costs | K11: ='Budget & Draw Schedule'!W13 -> 28800000 | L11: 0 | M11: =K11+L11 -> 28800000 | N11: =$M11/$D$34 -> 200000 | O11: =$M11/$H$16 -> 282.57457 | P11: =M11/$M$19 -> 0.48892388
C12: Gross Unit SF | H12: 110465 | J12: Hard Costs | K12: ='Budget & Draw Schedule'!W23 -> 0 | L12: ='Budget & Draw Schedule'!G23 -> 19954574 | M12: =K12+L12 -> 19954574 | N12: =$M12/$D$34 -> 138573.43 | O12: =$M12/$H$16 -> 195.78663 | P12: =M12/$M$19 -> 0.33875929
C13: Gross Amenity SF | H13: 7500 | J13: Soft Costs | K13: ='Budget & Draw Schedule'!W39 -> 497817.29 | L13: ='Budget & Draw Schedule'!G39-'Summary & Assumptions'!K13 -> 4864205.3 | M13: =K13+L13 -> 5362022.6 | N13: =$M13/$D$34 -> 37236.268 | O13: =$M13/$H$16 -> 52.610112 | P13: =M13/$M$19 -> 0.091028503
C14: Gross Outdoor/Circulation SF | H14: 14800 | J14: Total Unlevered Uses | K14: =SUM(K11:K13) -> 29297817 | L14: =SUM(L11:L13) -> 24818779 | M14: =M11+M12+M13 -> 54116596 | N14: =$M14/$D$34 -> 375809.7 | O14: =$M14/$H$16 -> 530.97131 | P14: =SUM(P11:P13) -> 0.91871167
C15: Ground Floor Retail SF | H15: 0 | J15: Financing Costs | K15: ='Budget & Draw Schedule'!W50 -> 448000 | L15: =M15-K15 -> 324699.58 | M15: ='Budget & Draw Schedule'!G50-SUM('Budget & Draw Schedule'!G48:G49) -> 772699.58 | P15: =M15/$M$19 -> 0.013117753
C16: Net Residential Square Feet | H16: =E34 -> 101920 | J16: Net Interest Reserve | K16: =SUM(K17:K18) -> 0 | L16: =SUM(L17:L18) -> 4015579.3 | M16: =SUM(M17:M18) -> 4015579.3 | P16: =SUM(P17:P18) -> 0.068170577
C17: Parking Spaces | H17: 365 | J17: Gross Senior Debt Interest | K17: ='Budget & Draw Schedule'!W48 -> 0 | L17: =M17-K17 -> 6505033.1 | M17: ='Budget & Draw Schedule'!G48 -> 6505033.1 | P17: =M17/$M$19 -> 0.11043285
C18: Parking Ratio | H18: =H17/'Unit Mix'!F19 -> 2.3856209 | J18: NOI to Offset Interest | K18: ='Budget & Draw Schedule'!W49 -> 0 | L18: =M18-K18 -> -2489453.8 | M18: ='Budget & Draw Schedule'!G49 -> -2489453.8 | P18: =M18/$M$19 -> -0.042262271
J19: Total Uses | K19: =SUM(K14:K16) -> 29745817 | L19: =SUM(L14:L16) -> 29159058 | M19: =SUM(M14:M16) -> 58904875 | N19: =M19/$D$34 -> 409061.63 | P19: =SUM(P14:P16) -> 1
C20: Unit Mix Summary
C21: Type | D21: # of Units | E21: NSF | F21: NSF/Unit | G21: $/Unit | H21: $/NSF | J21: Acquisition Loan Assumptions | N21: Sale Assumptions
C22: ='Unit Mix'!C7 -> Studio A | D22: ='Unit Mix'!D7 -> 8 | E22: ='Unit Mix'!H7 -> 4480 | F22: =E22/D22 -> 560 | G22: =SUMPRODUCT('Unit Mix'!I7,'Unit Mix'!D7)/SUM('Unit Mix'!D7) -> 2500 | H22: =SUMPRODUCT('Unit Mix'!K7,'Unit Mix'!H7)/SUM('Unit Mix'!H7) -> 4.4642857 | J22: Purchase Price | L22: 28800000 | N22: Inputs
C23: ='Unit Mix'!C8 -> Studio A - Affordable | D23: ='Unit Mix'!D8 -> 12 | E23: ='Unit Mix'!H8 -> 6720 | F23: =E23/D23 -> 560 | G23: =SUMPRODUCT('Unit Mix'!I8,'Unit Mix'!D8)/SUM('Unit Mix'!D8) -> 1400 | H23: =SUMPRODUCT('Unit Mix'!K8,'Unit Mix'!H8)/SUM('Unit Mix'!H8) -> 2.5 | J23: LTC | L23: 0.55 | N23: Hold Period | P23: =H52 -> 5.0833333
C24: ='Unit Mix'!C9 -> Studio B | D24: ='Unit Mix'!D9 -> 30 | E24: ='Unit Mix'!H9 -> 16800 | F24: =E24/D24 -> 560 | G24: =SUMPRODUCT('Unit Mix'!I9,'Unit Mix'!D9)/SUM('Unit Mix'!D9) -> 2600 | H24: =SUMPRODUCT('Unit Mix'!K9,'Unit Mix'!H9)/SUM('Unit Mix'!H9) -> 4.6428571 | J24: Acquisition Loan Proceeds | L24: =L22*L23 -> 15840000 | N24: Exit | P24: =H51 -> 46599
C25: ='Unit Mix'!C10 -> Studio B - Affordable | D25: ='Unit Mix'!D10 -> 10 | E25: ='Unit Mix'!H10 -> 5600 | F25: =E25/D25 -> 560 | G25: =SUMPRODUCT('Unit Mix'!I10,'Unit Mix'!D10)/SUM('Unit Mix'!D10) -> 1400 | H25: =SUMPRODUCT('Unit Mix'!K10,'Unit Mix'!H10)/SUM('Unit Mix'!H10) -> 2.5 | J25: Interest Rate | L25: 0.0575 | N25: Exit Cap Rate | P25: 0.0475
C26: ='Unit Mix'!C11 -> Studio C | D26: ='Unit Mix'!D11 -> 30 | E26: ='Unit Mix'!H11 -> 18000 | F26: =E26/D26 -> 600 | G26: =SUMPRODUCT('Unit Mix'!I11,'Unit Mix'!D11)/SUM('Unit Mix'!D11) -> 2700 | H26: =SUMPRODUCT('Unit Mix'!K11,'Unit Mix'!H11)/SUM('Unit Mix'!H11) -> 4.5 | N26: Sales Cost | P26: 0.01
C27: ='Unit Mix'!C12 -> 1 Bed / 1 Bath | D27: ='Unit Mix'!D12 -> 6 | E27: ='Unit Mix'!H12 -> 4710 | F27: =E27/D27 -> 785 | G27: =SUMPRODUCT('Unit Mix'!I12,'Unit Mix'!D12)/SUM('Unit Mix'!D12) -> 2800 | H27: =SUMPRODUCT('Unit Mix'!K12,'Unit Mix'!H12)/SUM('Unit Mix'!H12) -> 3.566879 | J27: Construction Loan Assumptions | N27: Outputs
C28: ='Unit Mix'!C13 -> 1 Bed / 1 Bath - A (Corner unit) | D28: ='Unit Mix'!D13 -> 13 | E28: ='Unit Mix'!H13 -> 12610 | F28: =E28/D28 -> 970 | G28: =SUMPRODUCT('Unit Mix'!I13,'Unit Mix'!D13)/SUM('Unit Mix'!D13) -> 3000 | H28: =SUMPRODUCT('Unit Mix'!K13,'Unit Mix'!H13)/SUM('Unit Mix'!H13) -> 3.0927835 | J28: LTC | L28: 0.6 | N28: Forward 12 Mo. NOI at Sale | P28: =SUMIF('Annual CFs'!$I$6:$S$6,ROUNDDOWN('Summary & Assumptions'!P23,1)+2,'Annual CFs'!$I$46:$S$46) -> 4266430.9
C29: ='Unit Mix'!C14 -> 1 Bed / 1 Bath - B (Regular Unit) | D29: ='Unit Mix'!D14 -> 16 | E29: ='Unit Mix'!H14 -> 14380 | F29: =E29/D29 -> 898.75 | G29: =SUMPRODUCT('Unit Mix'!I14,'Unit Mix'!D14)/SUM('Unit Mix'!D14) -> 2900 | H29: =SUMPRODUCT('Unit Mix'!K14,'Unit Mix'!H14)/SUM('Unit Mix'!H14) -> 3.2267038 | J29: Construction Loan Proceeds | L29: =M14*L28 -> 32469958 | M29: =M14*L28 -> 32469958 | N29: Sale Value | P29: =P28/P25 -> 89819599
C30: ='Unit Mix'!C15 -> 2 Bed / 2 Bath | D30: ='Unit Mix'!D15 -> 8 | E30: ='Unit Mix'!H15 -> 8800 | F30: =E30/D30 -> 1100 | G30: =SUMPRODUCT('Unit Mix'!I15,'Unit Mix'!D15)/SUM('Unit Mix'!D15) -> 3800 | H30: =SUMPRODUCT('Unit Mix'!K15,'Unit Mix'!H15)/SUM('Unit Mix'!H15) -> 3.4545455 | J30: Libor | L30: {=INDEX(LIBOR!$F$10:$F$130,MATCH('Summary & Assumptions'!H38,LIBOR!$D$10:$D$130,0))} -> 0.0010088 | N30: Sale Price | P30: =P29-(P29*$P$26) -> 88921403
C31: ='Unit Mix'!C16 -> Live Work Loft - A | D31: ='Unit Mix'!D16 -> 3 | E31: ='Unit Mix'!H16 -> 3300 | F31: =E31/D31 -> 1100 | G31: =SUMPRODUCT('Unit Mix'!I16,'Unit Mix'!D16)/SUM('Unit Mix'!D16) -> 3850 | H31: =SUMPRODUCT('Unit Mix'!K16,'Unit Mix'!H16)/SUM('Unit Mix'!H16) -> 3.5 | J31: Libor Cap | L31: 0.03 | T31: Return Sensitivity
C32: ='Unit Mix'!C17 -> Live Work Loft - B | D32: ='Unit Mix'!D17 -> 7 | E32: ='Unit Mix'!H17 -> 5420 | F32: =E32/D32 -> 774.28571 | G32: =SUMPRODUCT('Unit Mix'!I17,'Unit Mix'!D17)/SUM('Unit Mix'!D17) -> 3000 | H32: =SUMPRODUCT('Unit Mix'!K17,'Unit Mix'!H17)/SUM('Unit Mix'!H17) -> 3.8745387 | J32: Libor Floor | L32: 0.0025 | N32: Equity Return Summary | T32: Avg. Rent | U32: Exit Cap
C33: ='Unit Mix'!C18 -> Live Work Loft - C | D33: ='Unit Mix'!D18 -> 1 | E33: ='Unit Mix'!H18 -> 1100 | F33: =E33/D33 -> 1100 | G33: =SUMPRODUCT('Unit Mix'!I18,'Unit Mix'!D18)/SUM('Unit Mix'!D18) -> 4000 | H33: =SUMPRODUCT('Unit Mix'!K18,'Unit Mix'!H18)/SUM('Unit Mix'!H18) -> 3.6363636 | J33: Effective Libor | L33: =IF(L30>L31,L31,IF(L30<L32,L32,L30)) -> 0.0025 | N33: Contributions | P33: ='Budget & Draw Schedule'!P101 -> 26434917 | T33: =+TEXT(P36,"0.0%")&"/"&TEXT(P37,"0.0x") -> 20.5%/1.3x | U33: 0.04 | V33: =U33+0.0025 -> 0.0425 | W33: =V33+0.0025 -> 0.045 | X33: =W33+0.0025 -> 0.0475 | Y33: =X33+0.0025 -> 0.05
C34: Total / Wtd. Avg. | D34: =SUM(D22:D33) -> 144 | E34: =SUM(E22:E33) -> 101920 | F34: =E34/D34 -> 707.77778 | G34: =SUMPRODUCT(G22:G33,D22:D33)/D34 -> 2631.5972 | H34: =G34/F34 -> 3.7181122 | J34: Spread | L34: 0.04 | N34: Distributions | P34: ='Budget & Draw Schedule'!P102 -> 59870612 | T34: =+T35-0.05 -> 3.65 | U34: 26.9%/2.0x | V34: 24.5%/1.7x | W34: 22.3%/1.5x | X34: 20.1%/1.3x | Y34: 18.0%/1.1x
C35: Live | H35: =H34 -> 3.7181122 | J35: Interest Rate | L35: =L33+L34 -> 0.0425 | N35: Profit | P35: ='Budget & Draw Schedule'!P103 -> 33435695 | T35: =+T36-0.05 -> 3.7 | U35: 27.6%/2.1x | V35: 25.2%/1.8x | W35: 22.9%/1.6x | X35: 20.8%/1.4x | Y35: 18.7%/1.2x
N36: IRR | P36: ='Budget & Draw Schedule'!P104 -> 0.2045109 | T36: 3.75 | U36: 28.2%/2.1x | V36: 25.9%/1.9x | W36: 23.6%/1.6x | X36: 21.4%/1.4x | Y36: 19.4%/1.2x
C37: Timing Assumptions | J37: Return Metrics | N37: Equity Multiple | P37: ='Budget & Draw Schedule'!P105 -> 1.2648307 | T37: =+T36+0.05 -> 3.8 | U37: 28.9%/2.2x | V37: 26.5%/2.0x | W37: 24.3%/1.7x | X37: 22.1%/1.5x | Y37: 20.0%/1.3x
C38: Model Start | H38: 44713 | K38: Stabilized | L38: Stabilized | T38: =+T37+0.05 -> 3.85 | U38: 29.5%/2.3x | V38: 27.1%/2.0x | W38: 24.9%/1.8x | X38: 22.8%/1.6x | Y38: 20.7%/1.4x
C39: Predevelopment Period | H39: 24 | K39: Untrended | L39: Trended (Yr 5) | T39: =+T38+0.05 -> 3.9 | U39: 30.1%/2.4x | V39: 27.8%/2.1x | W39: 25.5%/1.8x | X39: 23.4%/1.6x | Y39: 21.3%/1.4x
C40: Land Close | H40: 44713 | J40: Net Operating Income | K40: ='Annual CFs'!G46 -> 3520935.5 | L40: ='Annual CFs'!M46 -> 4021520.3 | T40: =+T39+0.05 -> 3.95 | U40: 30.7%/2.4x | V40: 28.4%/2.2x | W40: 26.1%/1.9x | X40: 24.0%/1.7x | Y40: 22.0%/1.5x
C41: Construction Start Date | H41: =EOMONTH(H38,H39)+1 -> 45474 | J41: Return on Cost | K41: =K40/$M$19 -> 0.059773244 | L41: =L40/$M$19 -> 0.068271435
C42: Construction Period | H42: 18 | J42: Debt Yield | K42: =K40/$M$7 -> 0.10843671 | L42: =L40/$M$7 -> 0.12385358
...

Sheet Annual CFs
C4: Annual Cash Flow Proforma
G5: Stabilized | I5: 2022 | J5: 2023 | K5: 2024 | L5: 2025 | M5: 2026 | N5: 2027 | O5: 2028 | P5: 2029 | Q5: 2030 | R5: 2031 | S5: 2032
C6: Year | G6: Untrended | I6: 1 | J6: =I6+1 -> 2 | K6: =J6+1 -> 3 | L6: =K6+1 -> 4 | M6: =L6+1 -> 5 | N6: =M6+1 -> 6 | O6: =N6+1 -> 7 | P6: =O6+1 -> 8 | Q6: =P6+1 -> 9 | ... S6: =R6+1 -> 11
C8: Income
C9: Rental Income | G9: ='Unit Mix'!M19 -> 4547400 | I9: =SUMIF('Monthly CFs'!$G$5:$EI$5,'Annual CFs'!I$6,'Monthly CFs'!$G38:$EI38) -> 0 | J9: =SUMIF('Monthly CFs'!$G$5:$EI$5,'Annual CFs'!J$6,'Monthly CFs'!$G38:$EI38) -> 0 | K9: =SUMIF('Monthly CFs'!$G$5:$EI$5,'Annual CFs'!K$6,'Monthly CFs'!$G38:$EI38) -> 0 | L9: =SUMIF('Monthly CFs'!$G$5:$EI$5,'Annual CFs'!L$6,'Monthly CFs'!$G38:$EI38) -> 2001429.7 | M9: =SUMIF('Monthly CFs'!$G$5:$EI$5,'Annual CFs'!M$6,'Monthly CFs'!$G38:$EI38) -> 5118138.8 | N9: =SUMIF('Monthly CFs'!$G$5:$EI$5,'Annual CFs'!N$6,'Monthly CFs'!$G38:$EI38) -> 5271682.9 | O9: =SUMIF('Monthly CFs'!$G$5:$EI$5,'Annual CFs'!O$6,'Monthly CFs'!$G38:$EI38) -> 5429833.4 | P9: =SUMIF('Monthly CFs'!$G$5:$EI$5,'Annual CFs'!P$6,'Monthly CFs'!$G38:$EI38) -> 5592728.4 | ... S9: =SUMIF('Monthly CFs'!$G$5:$EI$5,'Annual CFs'!S$6,'Monthly CFs'!$G38:$EI38) -> 6111325.3
C10: Potential Gross Rent | G10: =SUM(G9) -> 4547400 | I10: =SUM(I9) -> 0 | J10: =SUM(J9) -> 0 | K10: =SUM(K9) -> 0 | L10: =SUM(L9) -> 2001429.7 | M10: =SUM(M9) -> 5118138.8 | N10: =SUM(N9) -> 5271682.9 | O10: =SUM(O9) -> 5429833.4 | P10: =SUM(P9) -> 5592728.4 | ... S10: =SUM(S9) -> 6111325.3
C12: Losses to GPR
C13: Market Vacancy | E13: ='Growth Rates'!G20 -> 0.05 | G13: =-$G$10*E13 -> -227370 | I13: =SUMIF('Monthly CFs'!$G$5:$EI$5,'Annual CFs'!I$6,'Monthly CFs'!$G42:$EI42) -> 0 | J13: =SUMIF('Monthly CFs'!$G$5:$EI$5,'Annual CFs'!J$6,'Monthly CFs'!$G42:$EI42) -> 0 | K13: =SUMIF('Monthly CFs'!$G$5:$EI$5,'Annual CFs'!K$6,'Monthly CFs'!$G42:$EI42) -> 0 | L13: =SUMIF('Monthly CFs'!$G$5:$EI$5,'Annual CFs'!L$6,'Monthly CFs'!$G42:$EI42) -> -20704.445 | M13: =SUMIF('Monthly CFs'!$G$5:$EI$5,'Annual CFs'!M$6,'Monthly CFs'!$G42:$EI42) -> -255906.94 | N13: =SUMIF('Monthly CFs'!$G$5:$EI$5,'Annual CFs'!N$6,'Monthly CFs'!$G42:$EI42) -> -263584.15 | O13: =SUMIF('Monthly CFs'!$G$5:$EI$5,'Annual CFs'!O$6,'Monthly CFs'!$G42:$EI42) -> -271491.67 | P13: =SUMIF('Monthly CFs'!$G$5:$EI$5,'Annual CFs'!P$6,'Monthly CFs'!$G42:$EI42) -> -279636.42 | ... S13: =SUMIF('Monthly CFs'!$G$5:$EI$5,'Annual CFs'!S$6,'Monthly CFs'!$G42:$EI42) -> -305566.27
C14: Non-Rev Beds | E14: ='Growth Rates'!I20 -> 0.0025 | G14: =-$G$10*E14 -> -11368.5 | I14: =SUMIF('Monthly CFs'!$G$5:$EI$5,'Annual CFs'!I$6,'Monthly CFs'!$G43:$EI43) -> 0 | J14: =SUMIF('Monthly CFs'!$G$5:$EI$5,'Annual CFs'!J$6,'Monthly CFs'!$G43:$EI43) -> 0 | K14: =SUMIF('Monthly CFs'!$G$5:$EI$5,'Annual CFs'!K$6,'Monthly CFs'!$G43:$EI43) -> 0 | L14: =SUMIF('Monthly CFs'!$G$5:$EI$5,'Annual CFs'!L$6,'Monthly CFs'!$G43:$EI43) -> -5003.5742 | M14: =SUMIF('Monthly CFs'!$G$5:$EI$5,'Annual CFs'!M$6,'Monthly CFs'!$G43:$EI43) -> -12795.347 | N14: =SUMIF('Monthly CFs'!$G$5:$EI$5,'Annual CFs'!N$6,'Monthly CFs'!$G43:$EI43) -> -13179.207 | O14: =SUMIF('Monthly CFs'!$G$5:$EI$5,'Annual CFs'!O$6,'Monthly CFs'!$G43:$EI43) -> -13574.584 | P14: =SUMIF('Monthly CFs'!$G$5:$EI$5,'Annual CFs'!P$6,'Monthly CFs'!$G43:$EI43) -> -13981.821 | ... S14: =SUMIF('Monthly CFs'!$G$5:$EI$5,'Annual CFs'!S$6,'Monthly CFs'!$G43:$EI43) -> -15278.313
C15: Bad Debt | E15: ='Growth Rates'!J20 -> 0.0075 | G15: =-$G$10*E15 -> -34105.5 | I15: =SUMIF('Monthly CFs'!$G$5:$EI$5,'Annual CFs'!I$6,'Monthly CFs'!$G44:$EI44) -> 0 | J15: =SUMIF('Monthly CFs'!$G$5:$EI$5,'Annual CFs'!J$6,'Monthly CFs'!$G44:$EI44) -> 0 | K15: =SUMIF('Monthly CFs'!$G$5:$EI$5,'Annual CFs'!K$6,'Monthly CFs'!$G44:$EI44) -> 0 | L15: =SUMIF('Monthly CFs'!$G$5:$EI$5,'Annual CFs'!L$6,'Monthly CFs'!$G44:$EI44) -> -15010.723 | M15: =SUMIF('Monthly CFs'!$G$5:$EI$5,'Annual CFs'!M$6,'Monthly CFs'!$G44:$EI44) -> -38386.041 | N15: =SUMIF('Monthly CFs'!$G$5:$EI$5,'Annual CFs'!N$6,'Monthly CFs'!$G44:$EI44) -> -39537.622 | O15: =SUMIF('Monthly CFs'!$G$5:$EI$5,'Annual CFs'!O$6,'Monthly CFs'!$G44:$EI44) -> -40723.751 | P15: =SUMIF('Monthly CFs'!$G$5:$EI$5,'Annual CFs'!P$6,'Monthly CFs'!$G44:$EI44) -> -41945.463 | ... S15: =SUMIF('Monthly CFs'!$G$5:$EI$5,'Annual CFs'!S$6,'Monthly CFs'!$G44:$EI44) -> -45834.94
C16: Concessions | E16: ='Growth Rates'!K20 -> 0.0025 | G16: =-$G$10*E16 -> -11368.5 | I16: =SUMIF('Monthly CFs'!$G$5:$EI$5,'Annual CFs'!I$6,'Monthly CFs'!$G45:$EI45) -> 0 | J16: =SUMIF('Monthly CFs'!$G$5:$EI$5,'Annual CFs'!J$6,'Monthly CFs'!$G45:$EI45) -> 0 | K16: =SUMIF('Monthly CFs'!$G$5:$EI$5,'Annual CFs'!K$6,'Monthly CFs'!$G45:$EI45) -> 0 | L16: =SUMIF('Monthly CFs'!$G$5:$EI$5,'Annual CFs'!L$6,'Monthly CFs'!$G45:$EI45) -> -20014.297 | M16: =SUMIF('Monthly CFs'!$G$5:$EI$5,'Annual CFs'!M$6,'Monthly CFs'!$G45:$EI45) -> -12795.347 | N16: =SUMIF('Monthly CFs'!$G$5:$EI$5,'Annual CFs'!N$6,'Monthly CFs'!$G45:$EI45) -> -13179.207 | O16: =SUMIF('Monthly CFs'!$G$5:$EI$5,'Annual CFs'!O$6,'Monthly CFs'!$G45:$EI45) -> -13574.584 | P16: =SUMIF('Monthly CFs'!$G$5:$EI$5,'Annual CFs'!P$6,'Monthly CFs'!$G45:$EI45) -> -13981.821 | ... S16: =SUMIF('Monthly CFs'!$G$5:$EI$5,'Annual CFs'!S$6,'Monthly CFs'!$G45:$EI45) -> -15278.313
C17: Total Losses to GPR | G17: =SUM(G13:G16) -> -284212.5 | I17: =SUM(I13:I16) -> 0 | J17: =SUM(J13:J16) -> 0 | K17: =SUM(K13:K16) -> 0 | L17: =SUM(L13:L16) -> -60733.038 | M17: =SUM(M13:M16) -> -319883.67 | N17: =SUM(N13:N16) -> -329480.18 | O17: =SUM(O13:O16) -> -339364.59 | P17: =SUM(P13:P16) -> -349545.53 | ... S17: =SUM(S13:S16) -> -381957.83
C19: Effective Rental Income | G19: =G17+G10 -> 4263187.5 | I19: =I17+I10 -> 0 | J19: =J17+J10 -> 0 | K19: =K17+K10 -> 0 | L19: =L17+L10 -> 1940696.6 | M19: =M17+M10 -> 4798255.1 | N19: =N17+N10 -> 4942202.7 | O19: =O17+O10 -> 5090468.8 | P19: =P17+P10 -> 5243182.9 | ... S19: =S17+S10 -> 5729367.5
C21: Other Income
C22: Parking Permit Fees | G22: ='OI & Expense Growth'!F7 -> 438000 | I22: =SUMIF('Monthly CFs'!$G$5:$EI$5,'Annual CFs'!I$6,'Monthly CFs'!$G51:$EI51) -> 0 | J22: =SUMIF('Monthly CFs'!$G$5:$EI$5,'Annual CFs'!J$6,'Monthly CFs'!$G51:$EI51) -> 0 | K22: =SUMIF('Monthly CFs'!$G$5:$EI$5,'Annual CFs'!K$6,'Monthly CFs'!$G51:$EI51) -> 0 | L22: =SUMIF('Monthly CFs'!$G$5:$EI$5,'Annual CFs'!L$6,'Monthly CFs'!$G51:$EI51) -> 176416.67 | M22: =SUMIF('Monthly CFs'!$G$5:$EI$5,'Annual CFs'!M$6,'Monthly CFs'!$G51:$EI51) -> 451140 | N22: =SUMIF('Monthly CFs'!$G$5:$EI$5,'Annual CFs'!N$6,'Monthly CFs'!$G51:$EI51) -> 464674.2 | O22: =SUMIF('Monthly CFs'!$G$5:$EI$5,'Annual CFs'!O$6,'Monthly CFs'!$G51:$EI51) -> 478614.43 | P22: =SUMIF('Monthly CFs'!$G$5:$EI$5,'Annual CFs'!P$6,'Monthly CFs'!$G51:$EI51) -> 492972.86 | ... S22: =SUMIF('Monthly CFs'!$G$5:$EI$5,'Annual CFs'!S$6,'Monthly CFs'!$G51:$EI51) -> 538684.75
C23: Utility Charge | G23: ='OI & Expense Growth'!F8 -> 129600 | I23: =SUMIF('Monthly CFs'!$G$5:$EI$5,'Annual CFs'!I$6,'Monthly CFs'!$G52:$EI52) -> 0 | J23: =SUMIF('Monthly CFs'!$G$5:$EI$5,'Annual CFs'!J$6,'Monthly CFs'!$G52:$EI52) -> 0 | K23: =SUMIF('Monthly CFs'!$G$5:$EI$5,'Annual CFs'!K$6,'Monthly CFs'!$G52:$EI52) -> 0 | L23: =SUMIF('Monthly CFs'!$G$5:$EI$5,'Annual CFs'!L$6,'Monthly CFs'!$G52:$EI52) -> 52200 | M23: =SUMIF('Monthly CFs'!$G$5:$EI$5,'Annual CFs'!M$6,'Monthly CFs'!$G52:$EI52) -> 133488 | N23: =SUMIF('Monthly CFs'!$G$5:$EI$5,'Annual CFs'!N$6,'Monthly CFs'!$G52:$EI52) -> 137492.64 | O23: =SUMIF('Monthly CFs'!$G$5:$EI$5,'Annual CFs'!O$6,'Monthly CFs'!$G52:$EI52) -> 141617.42 | P23: =SUMIF('Monthly CFs'!$G$5:$EI$5,'Annual CFs'!P$6,'Monthly CFs'!$G52:$EI52) -> 145865.94 | ... S23: =SUMIF('Monthly CFs'!$G$5:$EI$5,'Annual CFs'!S$6,'Monthly CFs'!$G52:$EI52) -> 159391.65
C24: Utility Billing Income | G24: ='OI & Expense Growth'!F9 -> 60480 | I24: =SUMIF('Monthly CFs'!$G$5:$EI$5,'Annual CFs'!I$6,'Monthly CFs'!$G53:$EI53) -> 0 | J24: =SUMIF('Monthly CFs'!$G$5:$EI$5,'Annual CFs'!J$6,'Monthly CFs'!$G53:$EI53) -> 0 | K24: =SUMIF('Monthly CFs'!$G$5:$EI$5,'Annual CFs'!K$6,'Monthly CFs'!$G53:$EI53) -> 0 | L24: =SUMIF('Monthly CFs'!$G$5:$EI$5,'Annual CFs'!L$6,'Monthly CFs'!$G53:$EI53) -> 24360 | M24: =SUMIF('Monthly CFs'!$G$5:$EI$5,'Annual CFs'!M$6,'Monthly CFs'!$G53:$EI53) -> 62294.4 | N24: =SUMIF('Monthly CFs'!$G$5:$EI$5,'Annual CFs'!N$6,'Monthly CFs'!$G53:$EI53) -> 64163.232 | O24: =SUMIF('Monthly CFs'!$G$5:$EI$5,'Annual CFs'!O$6,'Monthly CFs'!$G53:$EI53) -> 66088.129 | P24: =SUMIF('Monthly CFs'!$G$5:$EI$5,'Annual CFs'!P$6,'Monthly CFs'!$G53:$EI53) -> 68070.773 | ... S24: =SUMIF('Monthly CFs'!$G$5:$EI$5,'Annual CFs'!S$6,'Monthly CFs'!$G53:$EI53) -> 74382.771
C25: Retail Income (NNN) | G25: ='OI & Expense Growth'!F10 -> 0 | I25: =SUMIF('Monthly CFs'!$G$5:$EI$5,'Annual CFs'!I$6,'Monthly CFs'!$G54:$EI54) -> 0 | J25: =SUMIF('Monthly CFs'!$G$5:$EI$5,'Annual CFs'!J$6,'Monthly CFs'!$G54:$EI54) -> 0 | K25: =SUMIF('Monthly CFs'!$G$5:$EI$5,'Annual CFs'!K$6,'Monthly CFs'!$G54:$EI54) -> 0 | L25: =SUMIF('Monthly CFs'!$G$5:$EI$5,'Annual CFs'!L$6,'Monthly CFs'!$G54:$EI54) -> 0 | M25: =SUMIF('Monthly CFs'!$G$5:$EI$5,'Annual CFs'!M$6,'Monthly CFs'!$G54:$EI54) -> 0 | N25: =SUMIF('Monthly CFs'!$G$5:$EI$5,'Annual CFs'!N$6,'Monthly CFs'!$G54:$EI54) -> 0 | O25: =SUMIF('Monthly CFs'!$G$5:$EI$5,'Annual CFs'!O$6,'Monthly CFs'!$G54:$EI54) -> 0 | P25: =SUMIF('Monthly CFs'!$G$5:$EI$5,'Annual CFs'!P$6,'Monthly CFs'!$G54:$EI54) -> 0 | ... S25: =SUMIF('Monthly CFs'!$G$5:$EI$5,'Annual CFs'!S$6,'Monthly CFs'!$G54:$EI54) -> 0
C26: Total Other Income | G26: =SUM(G22:G25) -> 628080 | I26: =SUM(I22:I25) -> 0 | J26: =SUM(J22:J25) -> 0 | K26: =SUM(K22:K25) -> 0 | L26: =SUM(L22:L25) -> 252976.67 | M26: =SUM(M22:M25) -> 646922.4 | N26: =SUM(N22:N25) -> 666330.07 | O26: =SUM(O22:O25) -> 686319.97 | P26: =SUM(P22:P25) -> 706909.57 | ... S26: =SUM(S22:S25) -> 772459.18
C28: Effective Gross Income | G28: =G19+G26 -> 4891267.5 | I28: =I19+I26 -> 0 | J28: =J19+J26 -> 0 | K28: =K19+K26 -> 0 | L28: =L19+L26 -> 2193673.3 | M28: =M19+M26 -> 5445177.5 | N28: =N19+N26 -> 5608532.8 | O28: =O19+O26 -> 5776788.8 | P28: =P19+P26 -> 5950092.5 | ... S28: =S19+S26 -> 6501826.7
C30: Controllable Expenses
C31: Payroll | G31: ='OI & Expense Growth'!F13 -> 115200 | I31: =SUMIF('Monthly CFs'!$G$5:$EI$5,'Annual CFs'!I$6,'Monthly CFs'!$G60:$EI60) -> 0 | J31: =SUMIF('Monthly CFs'!$G$5:$EI$5,'Annual CFs'!J$6,'Monthly CFs'!$G60:$EI60) -> 0 | K31: =SUMIF('Monthly CFs'!$G$5:$EI$5,'Annual CFs'!K$6,'Monthly CFs'!$G60:$EI60) -> 0 | L31: =SUMIF('Monthly CFs'!$G$5:$EI$5,'Annual CFs'!L$6,'Monthly CFs'!$G60:$EI60) -> 46400 | M31: =SUMIF('Monthly CFs'!$G$5:$EI$5,'Annual CFs'!M$6,'Monthly CFs'!$G60:$EI60) -> 118656 | N31: =SUMIF('Monthly CFs'!$G$5:$EI$5,'Annual CFs'!N$6,'Monthly CFs'!$G60:$EI60) -> 122215.68 | O31: =SUMIF('Monthly CFs'!$G$5:$EI$5,'Annual CFs'!O$6,'Monthly CFs'!$G60:$EI60) -> 125882.15 | P31: =SUMIF('Monthly CFs'!$G$5:$EI$5,'Annual CFs'!P$6,'Monthly CFs'!$G60:$EI60) -> 129658.61 | ... S31: =SUMIF('Monthly CFs'!$G$5:$EI$5,'Annual CFs'!S$6,'Monthly CFs'!$G60:$EI60) -> 141681.47
C32: Marketing & Advertising | G32: ='OI & Expense Growth'!F14 -> 64800 | I32: =SUMIF('Monthly CFs'!$G$5:$EI$5,'Annual CFs'!I$6,'Monthly CFs'!$G61:$EI61) -> 0 | J32: =SUMIF('Monthly CFs'!$G$5:$EI$5,'Annual CFs'!J$6,'Monthly CFs'!$G61:$EI61) -> 0 | K32: =SUMIF('Monthly CFs'!$G$5:$EI$5,'Annual CFs'!K$6,'Monthly CFs'!$G61:$EI61) -> 0 | L32: =SUMIF('Monthly CFs'!$G$5:$EI$5,'Annual CFs'!L$6,'Monthly CFs'!$G61:$EI61) -> 26100 | M32: =SUMIF('Monthly CFs'!$G$5:$EI$5,'Annual CFs'!M$6,'Monthly CFs'!$G61:$EI61) -> 66744 | N32: =SUMIF('Monthly CFs'!$G$5:$EI$5,'Annual CFs'!N$6,'Monthly CFs'!$G61:$EI61) -> 68746.32 | O32: =SUMIF('Monthly CFs'!$G$5:$EI$5,'Annual CFs'!O$6,'Monthly CFs'!$G61:$EI61) -> 70808.71 | P32: =SUMIF('Monthly CFs'!$G$5:$EI$5,'Annual CFs'!P$6,'Monthly CFs'!$G61:$EI61) -> 72932.971 | ... S32: =SUMIF('Monthly CFs'!$G$5:$EI$5,'Annual CFs'!S$6,'Monthly CFs'!$G61:$EI61) -> 79695.826
C33: Repairs & Maintenance | G33: ='OI & Expense Growth'!F15 -> 61200 | I33: =SUMIF('Monthly CFs'!$G$5:$EI$5,'Annual CFs'!I$6,'Monthly CFs'!$G62:$EI62) -> 0 | J33: =SUMIF('Monthly CFs'!$G$5:$EI$5,'Annual CFs'!J$6,'Monthly CFs'!$G62:$EI62) -> 0 | K33: =SUMIF('Monthly CFs'!$G$5:$EI$5,'Annual CFs'!K$6,'Monthly CFs'!$G62:$EI62) -> 0 | L33: =SUMIF('Monthly CFs'!$G$5:$EI$5,'Annual CFs'!L$6,'Monthly CFs'!$G62:$EI62) -> 24650 | M33: =SUMIF('Monthly CFs'!$G$5:$EI$5,'Annual CFs'!M$6,'Monthly CFs'!$G62:$EI62) -> 63036 | N33: =SUMIF('Monthly CFs'!$G$5:$EI$5,'Annual CFs'!N$6,'Monthly CFs'!$G62:$EI62) -> 64927.08 | O33: =SUMIF('Monthly CFs'!$G$5:$EI$5,'Annual CFs'!O$6,'Monthly CFs'!$G62:$EI62) -> 66874.892 | P33: =SUMIF('Monthly CFs'!$G$5:$EI$5,'Annual CFs'!P$6,'Monthly CFs'!$G62:$EI62) -> 68881.139 | ... S33: =SUMIF('Monthly CFs'!$G$5:$EI$5,'Annual CFs'!S$6,'Monthly CFs'!$G62:$EI62) -> 75268.281
C34: Turnover | G34: ='OI & Expense Growth'!F16 -> 88500 | I34: =SUMIF('Monthly CFs'!$G$5:$EI$5,'Annual CFs'!I$6,'Monthly CFs'!$G63:$EI63) -> 0 | J34: =SUMIF('Monthly CFs'!$G$5:$EI$5,'Annual CFs'!J$6,'Monthly CFs'!$G63:$EI63) -> 0 | K34: =SUMIF('Monthly CFs'!$G$5:$EI$5,'Annual CFs'!K$6,'Monthly CFs'!$G63:$EI63) -> 0 | L34: =SUMIF('Monthly CFs'!$G$5:$EI$5,'Annual CFs'!L$6,'Monthly CFs'!$G63:$EI63) -> 35645.833 | M34: =SUMIF('Monthly CFs'!$G$5:$EI$5,'Annual CFs'!M$6,'Monthly CFs'!$G63:$EI63) -> 91155 | N34: =SUMIF('Monthly CFs'!$G$5:$EI$5,'Annual CFs'!N$6,'Monthly CFs'!$G63:$EI63) -> 93889.65 | O34: =SUMIF('Monthly CFs'!$G$5:$EI$5,'Annual CFs'!O$6,'Monthly CFs'!$G63:$EI63) -> 96706.34 | P34: =SUMIF('Monthly CFs'!$G$5:$EI$5,'Annual CFs'!P$6,'Monthly CFs'!$G63:$EI63) -> 99607.53 | ... S34: =SUMIF('Monthly CFs'!$G$5:$EI$5,'Annual CFs'!S$6,'Monthly CFs'!$G63:$EI63) -> 108843.84
C35: General & Administrative | G35: ='OI & Expense Growth'!F17 -> 50400 | I35: =SUMIF('Monthly CFs'!$G$5:$EI$5,'Annual CFs'!I$6,'Monthly CFs'!$G64:$EI64) -> 0 | J35: =SUMIF('Monthly CFs'!$G$5:$EI$5,'Annual CFs'!J$6,'Monthly CFs'!$G64:$EI64) -> 0 | K35: =SUMIF('Monthly CFs'!$G$5:$EI$5,'Annual CFs'!K$6,'Monthly CFs'!$G64:$EI64) -> 0 | L35: =SUMIF('Monthly CFs'!$G$5:$EI$5,'Annual CFs'!L$6,'Monthly CFs'!$G64:$EI64) -> 20300 | M35: =SUMIF('Monthly CFs'!$G$5:$EI$5,'Annual CFs'!M$6,'Monthly CFs'!$G64:$EI64) -> 51912 | N35: =SUMIF('Monthly CFs'!$G$5:$EI$5,'Annual CFs'!N$6,'Monthly CFs'!$G64:$EI64) -> 53469.36 | O35: =SUMIF('Monthly CFs'!$G$5:$EI$5,'Annual CFs'!O$6,'Monthly CFs'!$G64:$EI64) -> 55073.441 | P35: =SUMIF('Monthly CFs'!$G$5:$EI$5,'Annual CFs'!P$6,'Monthly CFs'!$G64:$EI64) -> 56725.644 | ... S35: =SUMIF('Monthly CFs'!$G$5:$EI$5,'Annual CFs'!S$6,'Monthly CFs'!$G64:$EI64) -> 61985.643
C36: Total Controllable Expenses | G36: =SUM(G31:G35) -> 380100 | I36: =SUM(I31:I35) -> 0 | J36: =SUM(J31:J35) -> 0 | K36: =SUM(K31:K35) -> 0 | L36: =SUM(L31:L35) -> 153095.83 | M36: =SUM(M31:M35) -> 391503 | N36: =SUM(N31:N35) -> 403248.09 | O36: =SUM(O31:O35) -> 415345.53 | P36: =SUM(P31:P35) -> 427805.9 | ... S36: =SUM(S31:S35) -> 467475.06
C38: Non-Controllable Expenses
C39: Real Estate Taxes | G39: ='OI & Expense Growth'!F20 -> 548294 | I39: =SUMIF('Monthly CFs'!$G$5:$EI$5,'Annual CFs'!I$6,'Monthly CFs'!$G68:$EI68) -> 313356.1 | J39: =SUMIF('Monthly CFs'!$G$5:$EI$5,'Annual CFs'!J$6,'Monthly CFs'!$G68:$EI68) -> 313356.1 | K39: =SUMIF('Monthly CFs'!$G$5:$EI$5,'Annual CFs'!K$6,'Monthly CFs'!$G68:$EI68) -> 313356.1 | L39: =SUMIF('Monthly CFs'!$G$5:$EI$5,'Annual CFs'!L$6,'Monthly CFs'!$G68:$EI68) -> 430825.05 | M39: =SUMIF('Monthly CFs'!$G$5:$EI$5,'Annual CFs'!M$6,'Monthly CFs'!$G68:$EI68) -> 564742.82 | N39: =SUMIF('Monthly CFs'!$G$5:$EI$5,'Annual CFs'!N$6,'Monthly CFs'!$G68:$EI68) -> 581685.1 | O39: =SUMIF('Monthly CFs'!$G$5:$EI$5,'Annual CFs'!O$6,'Monthly CFs'!$G68:$EI68) -> 599135.66 | P39: =SUMIF('Monthly CFs'!$G$5:$EI$5,'Annual CFs'!P$6,'Monthly CFs'!$G68:$EI68) -> 617109.73 | ... S39: =SUMIF('Monthly CFs'!$G$5:$EI$5,'Annual CFs'!S$6,'Monthly CFs'!$G68:$EI68) -> 674332.46
C40: Insurance | G40: ='OI & Expense Growth'!F21 -> 79200 | I40: =SUMIF('Monthly CFs'!$G$5:$EI$5,'Annual CFs'!I$6,'Monthly CFs'!$G69:$EI69) -> 39600 | J40: =SUMIF('Monthly CFs'!$G$5:$EI$5,'Annual CFs'!J$6,'Monthly CFs'!$G69:$EI69) -> 39600 | K40: =SUMIF('Monthly CFs'!$G$5:$EI$5,'Annual CFs'!K$6,'Monthly CFs'!$G69:$EI69) -> 39600 | L40: =SUMIF('Monthly CFs'!$G$5:$EI$5,'Annual CFs'!L$6,'Monthly CFs'!$G69:$EI69) -> 59400 | M40: =SUMIF('Monthly CFs'!$G$5:$EI$5,'Annual CFs'!M$6,'Monthly CFs'!$G69:$EI69) -> 81576 | N40: =SUMIF('Monthly CFs'!$G$5:$EI$5,'Annual CFs'!N$6,'Monthly CFs'!$G69:$EI69) -> 84023.28 | O40: =SUMIF('Monthly CFs'!$G$5:$EI$5,'Annual CFs'!O$6,'Monthly CFs'!$G69:$EI69) -> 86543.978 | P40: =SUMIF('Monthly CFs'!$G$5:$EI$5,'Annual CFs'!P$6,'Monthly CFs'!$G69:$EI69) -> 89140.298 | ... S40: =SUMIF('Monthly CFs'!$G$5:$EI$5,'Annual CFs'!S$6,'Monthly CFs'!$G69:$EI69) -> 97406.01
C41: Utilities | G41: ='OI & Expense Growth'!F22 -> 216000 | I41: =SUMIF('Monthly CFs'!$G$5:$EI$5,'Annual CFs'!I$6,'Monthly CFs'!$G70:$EI70) -> 0 | J41: =SUMIF('Monthly CFs'!$G$5:$EI$5,'Annual CFs'!J$6,'Monthly CFs'!$G70:$EI70) -> 0 | K41: =SUMIF('Monthly CFs'!$G$5:$EI$5,'Annual CFs'!K$6,'Monthly CFs'!$G70:$EI70) -> 0 | L41: =SUMIF('Monthly CFs'!$G$5:$EI$5,'Annual CFs'!L$6,'Monthly CFs'!$G70:$EI70) -> 87000 | M41: =SUMIF('Monthly CFs'!$G$5:$EI$5,'Annual CFs'!M$6,'Monthly CFs'!$G70:$EI70) -> 222480 | N41: =SUMIF('Monthly CFs'!$G$5:$EI$5,'Annual CFs'!N$6,'Monthly CFs'!$G70:$EI70) -> 229154.4 | O41: =SUMIF('Monthly CFs'!$G$5:$EI$5,'Annual CFs'!O$6,'Monthly CFs'!$G70:$EI70) -> 236029.03 | P41: =SUMIF('Monthly CFs'!$G$5:$EI$5,'Annual CFs'!P$6,'Monthly CFs'!$G70:$EI70) -> 243109.9 | ... S41: =SUMIF('Monthly CFs'!$G$5:$EI$5,'Annual CFs'!S$6,'Monthly CFs'!$G70:$EI70) -> 265652.75
C42: Management Fee | E42: ='Growth Rates'!O20 -> 0.03 | G42: =E42*G28 -> 146738.02 | I42: =SUMIF('Monthly CFs'!$G$5:$EI$5,'Annual CFs'!I$6,'Monthly CFs'!$G71:$EI71) -> 0 | J42: =SUMIF('Monthly CFs'!$G$5:$EI$5,'Annual CFs'!J$6,'Monthly CFs'!$G71:$EI71) -> 0 | K42: =SUMIF('Monthly CFs'!$G$5:$EI$5,'Annual CFs'!K$6,'Monthly CFs'!$G71:$EI71) -> 0 | L42: =SUMIF('Monthly CFs'!$G$5:$EI$5,'Annual CFs'!L$6,'Monthly CFs'!$G71:$EI71) -> 65810.199 | M42: =SUMIF('Monthly CFs'!$G$5:$EI$5,'Annual CFs'!M$6,'Monthly CFs'!$G71:$EI71) -> 163355.32 | N42: =SUMIF('Monthly CFs'!$G$5:$EI$5,'Annual CFs'!N$6,'Monthly CFs'!$G71:$EI71) -> 168255.98 | O42: =SUMIF('Monthly CFs'!$G$5:$EI$5,'Annual CFs'!O$6,'Monthly CFs'!$G71:$EI71) -> 173303.66 | P42: =SUMIF('Monthly CFs'!$G$5:$EI$5,'Annual CFs'!P$6,'Monthly CFs'!$G71:$EI71) -> 178502.77 | ... S42: =SUMIF('Monthly CFs'!$G$5:$EI$5,'Annual CFs'!S$6,'Monthly CFs'!$G71:$EI71) -> 195054.8
C43: Total Non-Controllable Expenses | G43: =SUM(G39:G42) -> 990232.03 | I43: =SUM(I39:I42) -> 352956.1 | J43: =SUM(J39:J42) -> 352956.1 | K43: =SUM(K39:K42) -> 352956.1 | L43: =SUM(L39:L42) -> 643035.25 | M43: =SUM(M39:M42) -> 1032154.1 | N43: =SUM(N39:N42) -> 1063118.8 | O43: =SUM(O39:O42) -> 1095012.3 | P43: =SUM(P39:P42) -> 1127862.7 | ... S43: =SUM(S39:S42) -> 1232446
C44: Total Operating Expenses | G44: =G43+G36 -> 1370332 | I44: =I43+I36 -> 352956.1 | J44: =J43+J36 -> 352956.1 | K44: =K43+K36 -> 352956.1 | L44: =L43+L36 -> 796131.08 | M44: =M43+M36 -> 1423657.1 | N44: =N43+N36 -> 1466366.9 | O44: =O43+O36 -> 1510357.9 | P44: =P43+P36 -> 1555668.6 | ... S44: =S43+S36 -> 1699921.1 | V44: =G44/G28 -> 0.28015888
C46: Net Operating Income | G46: =G28-G44 -> 3520935.5 | I46: =I28-I44 -> -352956.1 | J46: =J28-J44 -> -352956.1 | K46: =K28-K44 -> -352956.1 | L46: =L28-L44 -> 1397542.2 | M46: =M28-M44 -> 4021520.3 | N46: =N28-N44 -> 4142166 | O46: =O28-O44 -> 4266430.9 | P46: =P28-P44 -> 4394423.9 | ... S46: =S28-S44 -> 4801905.6
C48: Capital Reserves | E48: ='Growth Rates'!P10 -> 150 | G48: =$E48*'Summary & Assumptions'!$D$34 -> 21600 | I48: =SUMIF('Monthly CFs'!$G$5:$EI$5,'Annual CFs'!I$6,'Monthly CFs'!$G77:$EI77) -> 0 | J48: =SUMIF('Monthly CFs'!$G$5:$EI$5,'Annual CFs'!J$6,'Monthly CFs'!$G77:$EI77) -> 0 | K48: =SUMIF('Monthly CFs'!$G$5:$EI$5,'Annual CFs'!K$6,'Monthly CFs'!$G77:$EI77) -> 0 | L48: =SUMIF('Monthly CFs'!$G$5:$EI$5,'Annual CFs'!L$6,'Monthly CFs'!$G77:$EI77) -> 8700 | M48: =SUMIF('Monthly CFs'!$G$5:$EI$5,'Annual CFs'!M$6,'Monthly CFs'!$G77:$EI77) -> 21600 | N48: =SUMIF('Monthly CFs'!$G$5:$EI$5,'Annual CFs'!N$6,'Monthly CFs'!$G77:$EI77) -> 21600 | O48: =SUMIF('Monthly CFs'!$G$5:$EI$5,'Annual CFs'!O$6,'Monthly CFs'!$G77:$EI77) -> 21600 | P48: =SUMIF('Monthly CFs'!$G$5:$EI$5,'Annual CFs'!P$6,'Monthly CFs'!$G77:$EI77) -> 21600 | ... S48: =SUMIF('Monthly CFs'!$G$5:$EI$5,'Annual CFs'!S$6,'Monthly CFs'!$G77:$EI77) -> 21600
C49: Cash Flows From Operations | G49: =G46-G48 -> 3499335.5 | I49: =I46-I48 -> -352956.1 | J49: =J46-J48 -> -352956.1 | K49: =K46-K48 -> -352956.1 | L49: =L46-L48 -> 1388842.2 | M49: =M46-M48 -> 3999920.3 | N49: =N46-N48 -> 4120566 | O49: =O46-O48 -> 4244830.9 | P49: =P46-P48 -> 4372823.9 | ... S49: =S46-S48 -> 4780305.6 | V49: =SUM(I49:S49)-SUM('Monthly CFs'!G78:EI78) -> 0
C51: Stabilized ROC / NOI (Untrended) | E51: ='Summary & Assumptions'!K41 -> 0.059773244 | G51: =G46 -> 3520935.5
C52: Required ROC / NOI (Untrended) | E52: 0.06 | G52: =E52*'Summary & Assumptions'!M19 -> 3534292.5
C53: (Discount)/Premium to Stab. Untrended NOI | G53: =G52-G46 -> 13357.03

Sheet Monthly CFs
C4: Monthly CFs | F4: Year | G4: =YEAR(G7) -> 2022 | H4: =YEAR(H7) -> 2022 | I4: =YEAR(I7) -> 2022 | J4: =YEAR(J7) -> 2022 | K4: =YEAR(K7) -> 2022 | L4: =YEAR(L7) -> 2022 | M4: =YEAR(M7) -> 2022 | N4: =YEAR(N7) -> 2023 | ... EI4: =YEAR(EI7) -> 2033
F5: Year | G5: =ROUNDUP(G6/12,0) -> 0 | H5: =ROUNDUP(H6/12,0) -> 1 | I5: =ROUNDUP(I6/12,0) -> 1 | J5: =ROUNDUP(J6/12,0) -> 1 | K5: =ROUNDUP(K6/12,0) -> 1 | L5: =ROUNDUP(L6/12,0) -> 1 | M5: =ROUNDUP(M6/12,0) -> 1 | N5: =ROUNDUP(N6/12,0) -> 1 | ... EI5: =ROUNDUP(EI6/12,0) -> 11
F6: Month | G6: 0 | H6: =+G6+1 -> 1 | I6: =+H6+1 -> 2 | J6: =+I6+1 -> 3 | K6: =+J6+1 -> 4 | L6: =+K6+1 -> 5 | M6: =+L6+1 -> 6 | N6: =+M6+1 -> 7 | O6: =+N6+1 -> 8 | ... EI6: =+EH6+1 -> 132
F7: Date | G7: ='Summary & Assumptions'!H38 -> 44713 | H7: =+EOMONTH(G7,1) -> 44773 | I7: =+EOMONTH(H7,1) -> 44804 | J7: =+EOMONTH(I7,1) -> 44834 | K7: =+EOMONTH(J7,1) -> 44865 | L7: =+EOMONTH(K7,1) -> 44895 | M7: =+EOMONTH(L7,1) -> 44926 | N7: =+EOMONTH(M7,1) -> 44957 | O7: =+EOMONTH(N7,1) -> 44985 | ... EI7: =+EOMONTH(EH7,1) -> 48760
C9: Assumptions
C11: Unit Assumptions
C12: Rent/SF | H12: {=INDEX('Growth Rates'!$F$10:$F$20,MATCH(H5,'Growth Rates'!$C$10:$C$20,0))} -> 3.7181122 | I12: {=INDEX('Growth Rates'!$F$10:$F$20,MATCH(I5,'Growth Rates'!$C$10:$C$20,0))} -> 3.7181122 | J12: {=INDEX('Growth Rates'!$F$10:$F$20,MATCH(J5,'Growth Rates'!$C$10:$C$20,0))} -> 3.7181122 | K12: {=INDEX('Growth Rates'!$F$10:$F$20,MATCH(K5,'Growth Rates'!$C$10:$C$20,0))} -> 3.7181122 | L12: {=INDEX('Growth Rates'!$F$10:$F$20,MATCH(L5,'Growth Rates'!$C$10:$C$20,0))} -> 3.7181122 | M12: {=INDEX('Growth Rates'!$F$10:$F$20,MATCH(M5,'Growth Rates'!$C$10:$C$20,0))} -> 3.7181122 | N12: {=INDEX('Growth Rates'!$F$10:$F$20,MATCH(N5,'Growth Rates'!$C$10:$C$20,0))} -> 3.7181122 | O12: {=INDEX('Growth Rates'!$F$10:$F$20,MATCH(O5,'Growth Rates'!$C$10:$C$20,0))} -> 3.7181122 | ... EI12: {=INDEX('Growth Rates'!$F$10:$F$20,MATCH(EI5,'Growth Rates'!$C$10:$C$20,0))} -> 4.9968319
C13: Effective Annual Rent | H13: =H17*H12*'Summary & Assumptions'!$E$34 -> 0 | I13: =I17*I12*'Summary & Assumptions'!$E$34 -> 0 | J13: =J17*J12*'Summary & Assumptions'!$E$34 -> 0 | K13: =K17*K12*'Summary & Assumptions'!$E$34 -> 0 | L13: =L17*L12*'Summary & Assumptions'!$E$34 -> 0 | M13: =M17*M12*'Summary & Assumptions'!$E$34 -> 0 | N13: =N17*N12*'Summary & Assumptions'!$E$34 -> 0 | O13: =O17*O12*'Summary & Assumptions'!$E$34 -> 0 | ... EI13: =EI17*EI12*'Summary & Assumptions'!$E$34 -> 509277.11
C15: Units Delivered In Month | G15: =IF(F16='Summary & Assumptions'!$D$34,0,IF(F16+'Summary & Assumptions'!$H$47>'Summary & Assumptions'!$D$34,'Summary & Assumptions'!$D$34-F16,IF(G7=EOMONTH('Summary & Assumptions'!$H$44,0),'Summary & Assumptions'!$H$46,IF(AND(G7>EOMONTH('Summary & Assumptions'!$H$44,0),G7<='Summary & Assumptions'!$H$48),'Summary & Assumptions'!$H$47,0)))) -> 0 | H15: =IF(G16='Summary & Assumptions'!$D$34,0,IF(G16+'Summary & Assumptions'!$H$47>'Summary & Assumptions'!$D$34,'Summary & Assumptions'!$D$34-G16,IF(H7=EOMONTH('Summary & Assumptions'!$H$44,0),'Summary & Assumptions'!$H$46,IF(AND(H7>EOMONTH('Summary & Assumptions'!$H$44,0),H7<='Summary & Assumptions'!$H$48),'Summary & Assumptions'!$H$47,0)))) -> 0 | I15: =IF(H16='Summary & Assumptions'!$D$34,0,IF(H16+'Summary & Assumptions'!$H$47>'Summary & Assumptions'!$D$34,'Summary & Assumptions'!$D$34-H16,IF(I7=EOMONTH('Summary & Assumptions'!$H$44,0),'Summary & Assumptions'!$H$46,IF(AND(I7>EOMONTH('Summary & Assumptions'!$H$44,0),I7<='Summary & Assumptions'!$H$48),'Summary & Assumptions'!$H$47,0)))) -> 0 | J15: =IF(I16='Summary & Assumptions'!$D$34,0,IF(I16+'Summary & Assumptions'!$H$47>'Summary & Assumptions'!$D$34,'Summary & Assumptions'!$D$34-I16,IF(J7=EOMONTH('Summary & Assumptions'!$H$44,0),'Summary & Assumptions'!$H$46,IF(AND(J7>EOMONTH('Summary & Assumptions'!$H$44,0),J7<='Summary & Assumptions'!$H$48),'Summary & Assumptions'!$H$47,0)))) -> 0 | K15: =IF(J16='Summary & Assumptions'!$D$34,0,IF(J16+'Summary & Assumptions'!$H$47>'Summary & Assumptions'!$D$34,'Summary & Assumptions'!$D$34-J16,IF(K7=EOMONTH('Summary & Assumptions'!$H$44,0),'Summary & Assumptions'!$H$46,IF(AND(K7>EOMONTH('Summary & Assumptions'!$H$44,0),K7<='Summary & Assumptions'!$H$48),'Summary & Assumptions'!$H$47,0)))) -> 0 | L15: =IF(K16='Summary & Assumptions'!$D$34,0,IF(K16+'Summary & Assumptions'!$H$47>'Summary & Assumptions'!$D$34,'Summary & Assumptions'!$D$34-K16,IF(L7=EOMONTH('Summary & Assumptions'!$H$44,0),'Summary & Assumptions'!$H$46,IF(AND(L7>EOMONTH('Summary & Assumptions'!$H$44,0),L7<='Summary & Assumptions'!$H$48),'Summary & Assumptions'!$H$47,0)))) -> 0 | M15: =IF(L16='Summary & Assumptions'!$D$34,0,IF(L16+'Summary & Assumptions'!$H$47>'Summary & Assumptions'!$D$34,'Summary & Assumptions'!$D$34-L16,IF(M7=EOMONTH('Summary & Assumptions'!$H$44,0),'Summary & Assumptions'!$H$46,IF(AND(M7>EOMONTH('Summary & Assumptions'!$H$44,0),M7<='Summary & Assumptions'!$H$48),'Summary & Assumptions'!$H$47,0)))) -> 0 | N15: =IF(M16='Summary & Assumptions'!$D$34,0,IF(M16+'Summary & Assumptions'!$H$47>'Summary & Assumptions'!$D$34,'Summary & Assumptions'!$D$34-M16,IF(N7=EOMONTH('Summary & Assumptions'!$H$44,0),'Summary & Assumptions'!$H$46,IF(AND(N7>EOMONTH('Summary & Assumptions'!$H$44,0),N7<='Summary & Assumptions'!$H$48),'Summary & Assumptions'!$H$47,0)))) -> 0 | ... EI15: =IF(EH16='Summary & Assumptions'!$D$34,0,IF(EH16+'Summary & Assumptions'!$H$47>'Summary & Assumptions'!$D$34,'Summary & Assumptions'!$D$34-EH16,IF(EI7=EOMONTH('Summary & Assumptions'!$H$44,0),'Summary & Assumptions'!$H$46,IF(AND(EI7>EOMONTH('Summary & Assumptions'!$H$44,0),EI7<='Summary & Assumptions'!$H$48),'Summary & Assumptions'!$H$47,0)))) -> 0
C16: Cumulative Units Delivered | G16: =SUM($F$15:G15) -> 0 | H16: =SUM($F$15:H15) -> 0 | I16: =SUM($F$15:I15) -> 0 | J16: =SUM($F$15:J15) -> 0 | K16: =SUM($F$15:K15) -> 0 | L16: =SUM($F$15:L15) -> 0 | M16: =SUM($F$15:M15) -> 0 | N16: =SUM($F$15:N15) -> 0 | ... EI16: =SUM($F$15:EI15) -> 144
C17: % Occupied | G17: =G16/'Summary & Assumptions'!$D$34 -> 0 | H17: =H16/'Summary & Assumptions'!$D$34 -> 0 | I17: =I16/'Summary & Assumptions'!$D$34 -> 0 | J17: =J16/'Summary & Assumptions'!$D$34 -> 0 | K17: =K16/'Summary & Assumptions'!$D$34 -> 0 | L17: =L16/'Summary & Assumptions'!$D$34 -> 0 | M17: =M16/'Summary & Assumptions'!$D$34 -> 0 | N17: =N16/'Summary & Assumptions'!$D$34 -> 0 | ... EI17: =EI16/'Summary & Assumptions'!$D$34 -> 1
C19: Market Vacancy | G19: {=IFERROR(INDEX('Growth Rates'!$G$10:$G$20,MATCH(G$5,'Growth Rates'!$C$10:$C$20,0)),0)} -> 0 | H19: {=IFERROR(INDEX('Growth Rates'!$G$10:$G$20,MATCH(H$5,'Growth Rates'!$C$10:$C$20,0)),0)} -> 0.05 | I19: {=IFERROR(INDEX('Growth Rates'!$G$10:$G$20,MATCH(I$5,'Growth Rates'!$C$10:$C$20,0)),0)} -> 0.05 | J19: {=IFERROR(INDEX('Growth Rates'!$G$10:$G$20,MATCH(J$5,'Growth Rates'!$C$10:$C$20,0)),0)} -> 0.05 | K19: {=IFERROR(INDEX('Growth Rates'!$G$10:$G$20,MATCH(K$5,'Growth Rates'!$C$10:$C$20,0)),0)} -> 0.05 | L19: {=IFERROR(INDEX('Growth Rates'!$G$10:$G$20,MATCH(L$5,'Growth Rates'!$C$10:$C$20,0)),0)} -> 0.05 | M19: {=IFERROR(INDEX('Growth Rates'!$G$10:$G$20,MATCH(M$5,'Growth Rates'!$C$10:$C$20,0)),0)} -> 0.05 | N19: {=IFERROR(INDEX('Growth Rates'!$G$10:$G$20,MATCH(N$5,'Growth Rates'!$C$10:$C$20,0)),0)} -> 0.05 | ... EI19: {=IFERROR(INDEX('Growth Rates'!$G$10:$G$20,MATCH(EI$5,'Growth Rates'!$C$10:$C$20,0)),0)} -> 0.05
C20: Retail Vacancy | G20: {=IFERROR(INDEX('Growth Rates'!$H$10:$H$20,MATCH(G$5,'Growth Rates'!$C$10:$C$20,0)),0)} -> 0 | H20: {=IFERROR(INDEX('Growth Rates'!$H$10:$H$20,MATCH(H$5,'Growth Rates'!$C$10:$C$20,0)),0)} -> 0.1 | I20: {=IFERROR(INDEX('Growth Rates'!$H$10:$H$20,MATCH(I$5,'Growth Rates'!$C$10:$C$20,0)),0)} -> 0.1 | J20: {=IFERROR(INDEX('Growth Rates'!$H$10:$H$20,MATCH(J$5,'Growth Rates'!$C$10:$C$20,0)),0)} -> 0.1 | K20: {=IFERROR(INDEX('Growth Rates'!$H$10:$H$20,MATCH(K$5,'Growth Rates'!$C$10:$C$20,0)),0)} -> 0.1 | L20: {=IFERROR(INDEX('Growth Rates'!$H$10:$H$20,MATCH(L$5,'Growth Rates'!$C$10:$C$20,0)),0)} -> 0.1 | M20: {=IFERROR(INDEX('Growth Rates'!$H$10:$H$20,MATCH(M$5,'Growth Rates'!$C$10:$C$20,0)),0)} -> 0.1 | N20: {=IFERROR(INDEX('Growth Rates'!$H$10:$H$20,MATCH(N$5,'Growth Rates'!$C$10:$C$20,0)),0)} -> 0.1 | ... EI20: {=IFERROR(INDEX('Growth Rates'!$H$10:$H$20,MATCH(EI$5,'Growth Rates'!$C$10:$C$20,0)),0)} -> 0.1
C22: Losses to GPR
C23: Non-Rev Beds | G23: {=IFERROR(INDEX('Growth Rates'!$I$10:$I$20,MATCH(G$5,'Growth Rates'!$C$10:$C$20,0)),0)} -> 0 | H23: {=IFERROR(INDEX('Growth Rates'!$I$10:$I$20,MATCH(H$5,'Growth Rates'!$C$10:$C$20,0)),0)} -> 0.0025 | I23: {=IFERROR(INDEX('Growth Rates'!$I$10:$I$20,MATCH(I$5,'Growth Rates'!$C$10:$C$20,0)),0)} -> 0.0025 | J23: {=IFERROR(INDEX('Growth Rates'!$I$10:$I$20,MATCH(J$5,'Growth Rates'!$C$10:$C$20,0)),0)} -> 0.0025 | K23: {=IFERROR(INDEX('Growth Rates'!$I$10:$I$20,MATCH(K$5,'Growth Rates'!$C$10:$C$20,0)),0)} -> 0.0025 | L23: {=IFERROR(INDEX('Growth Rates'!$I$10:$I$20,MATCH(L$5,'Growth Rates'!$C$10:$C$20,0)),0)} -> 0.0025 | M23: {=IFERROR(INDEX('Growth Rates'!$I$10:$I$20,MATCH(M$5,'Growth Rates'!$C$10:$C$20,0)),0)} -> 0.0025 | N23: {=IFERROR(INDEX('Growth Rates'!$I$10:$I$20,MATCH(N$5,'Growth Rates'!$C$10:$C$20,0)),0)} -> 0.0025 | ... EI23: {=IFERROR(INDEX('Growth Rates'!$I$10:$I$20,MATCH(EI$5,'Growth Rates'!$C$10:$C$20,0)),0)} -> 0.0025
C24: Bad Debt | G24: {=IFERROR(INDEX('Growth Rates'!$J$10:$J$20,MATCH(G$5,'Growth Rates'!$C$10:$C$20,0)),0)} -> 0 | H24: {=IFERROR(INDEX('Growth Rates'!$J$10:$J$20,MATCH(H$5,'Growth Rates'!$C$10:$C$20,0)),0)} -> 0.0075 | I24: {=IFERROR(INDEX('Growth Rates'!$J$10:$J$20,MATCH(I$5,'Growth Rates'!$C$10:$C$20,0)),0)} -> 0.0075 | J24: {=IFERROR(INDEX('Growth Rates'!$J$10:$J$20,MATCH(J$5,'Growth Rates'!$C$10:$C$20,0)),0)} -> 0.0075 | K24: {=IFERROR(INDEX('Growth Rates'!$J$10:$J$20,MATCH(K$5,'Growth Rates'!$C$10:$C$20,0)),0)} -> 0.0075 | L24: {=IFERROR(INDEX('Growth Rates'!$J$10:$J$20,MATCH(L$5,'Growth Rates'!$C$10:$C$20,0)),0)} -> 0.0075 | M24: {=IFERROR(INDEX('Growth Rates'!$J$10:$J$20,MATCH(M$5,'Growth Rates'!$C$10:$C$20,0)),0)} -> 0.0075 | N24: {=IFERROR(INDEX('Growth Rates'!$J$10:$J$20,MATCH(N$5,'Growth Rates'!$C$10:$C$20,0)),0)} -> 0.0075 | ... EI24: {=IFERROR(INDEX('Growth Rates'!$J$10:$J$20,MATCH(EI$5,'Growth Rates'!$C$10:$C$20,0)),0)} -> 0.0075
C25: Concessions | G25: {=IFERROR(INDEX('Growth Rates'!$K$10:$K$20,MATCH(G$5,'Growth Rates'!$C$10:$C$20,0)),0)} -> 0 | H25: {=IFERROR(INDEX('Growth Rates'!$K$10:$K$20,MATCH(H$5,'Growth Rates'!$C$10:$C$20,0)),0)} -> 0.01 | I25: {=IFERROR(INDEX('Growth Rates'!$K$10:$K$20,MATCH(I$5,'Growth Rates'!$C$10:$C$20,0)),0)} -> 0.01 | J25: {=IFERROR(INDEX('Growth Rates'!$K$10:$K$20,MATCH(J$5,'Growth Rates'!$C$10:$C$20,0)),0)} -> 0.01 | K25: {=IFERROR(INDEX('Growth Rates'!$K$10:$K$20,MATCH(K$5,'Growth Rates'!$C$10:$C$20,0)),0)} -> 0.01 | L25: {=IFERROR(INDEX('Growth Rates'!$K$10:$K$20,MATCH(L$5,'Growth Rates'!$C$10:$C$20,0)),0)} -> 0.01 | M25: {=IFERROR(INDEX('Growth Rates'!$K$10:$K$20,MATCH(M$5,'Growth Rates'!$C$10:$C$20,0)),0)} -> 0.01 | N25: {=IFERROR(INDEX('Growth Rates'!$K$10:$K$20,MATCH(N$5,'Growth Rates'!$C$10:$C$20,0)),0)} -> 0.01 | ... EI25: {=IFERROR(INDEX('Growth Rates'!$K$10:$K$20,MATCH(EI$5,'Growth Rates'!$C$10:$C$20,0)),0)} -> 0.0025
C27: Other Income
C28: Other Income Growth | G28: {=IFERROR(INDEX('Growth Rates'!$L$10:$L$20,MATCH(G$5,'Growth Rates'!$C$10:$C$20,0)),0)} -> 0 | H28: {=IFERROR(INDEX('Growth Rates'!$L$10:$L$20,MATCH(H$5,'Growth Rates'!$C$10:$C$20,0)),0)} -> 0 | I28: {=IFERROR(INDEX('Growth Rates'!$L$10:$L$20,MATCH(I$5,'Growth Rates'!$C$10:$C$20,0)),0)} -> 0 | J28: {=IFERROR(INDEX('Growth Rates'!$L$10:$L$20,MATCH(J$5,'Growth Rates'!$C$10:$C$20,0)),0)} -> 0 | K28: {=IFERROR(INDEX('Growth Rates'!$L$10:$L$20,MATCH(K$5,'Growth Rates'!$C$10:$C$20,0)),0)} -> 0 | L28: {=IFERROR(INDEX('Growth Rates'!$L$10:$L$20,MATCH(L$5,'Growth Rates'!$C$10:$C$20,0)),0)} -> 0 | M28: {=IFERROR(INDEX('Growth Rates'!$L$10:$L$20,MATCH(M$5,'Growth Rates'!$C$10:$C$20,0)),0)} -> 0 | N28: {=IFERROR(INDEX('Growth Rates'!$L$10:$L$20,MATCH(N$5,'Growth Rates'!$C$10:$C$20,0)),0)} -> 0 | ... EI28: {=IFERROR(INDEX('Growth Rates'!$L$10:$L$20,MATCH(EI$5,'Growth Rates'!$C$10:$C$20,0)),0)} -> 0.03
C30: Expenses
C31: Controllable Expense Growth | G31: {=IFERROR(INDEX('Growth Rates'!$M$10:$M$20,MATCH(G$5,'Growth Rates'!$C$10:$C$20,0)),0)} -> 0 | H31: {=IFERROR(INDEX('Growth Rates'!$M$10:$M$20,MATCH(H$5,'Growth Rates'!$C$10:$C$20,0)),0)} -> 0 | I31: {=IFERROR(INDEX('Growth Rates'!$M$10:$M$20,MATCH(I$5,'Growth Rates'!$C$10:$C$20,0)),0)} -> 0 | J31: {=IFERROR(INDEX('Growth Rates'!$M$10:$M$20,MATCH(J$5,'Growth Rates'!$C$10:$C$20,0)),0)} -> 0 | K31: {=IFERROR(INDEX('Growth Rates'!$M$10:$M$20,MATCH(K$5,'Growth Rates'!$C$10:$C$20,0)),0)} -> 0 | L31: {=IFERROR(INDEX('Growth Rates'!$M$10:$M$20,MATCH(L$5,'Growth Rates'!$C$10:$C$20,0)),0)} -> 0 | M31: {=IFERROR(INDEX('Growth Rates'!$M$10:$M$20,MATCH(M$5,'Growth Rates'!$C$10:$C$20,0)),0)} -> 0 | N31: {=IFERROR(INDEX('Growth Rates'!$M$10:$M$20,MATCH(N$5,'Growth Rates'!$C$10:$C$20,0)),0)} -> 0 | ... EI31: {=IFERROR(INDEX('Growth Rates'!$M$10:$M$20,MATCH(EI$5,'Growth Rates'!$C$10:$C$20,0)),0)} -> 0.03
C32: Non-Controllable Expense Growth | G32: {=IFERROR(INDEX('Growth Rates'!$N$10:$N$20,MATCH(G$5,'Growth Rates'!$C$10:$C$20,0)),0)} -> 0 | H32: {=IFERROR(INDEX('Growth Rates'!$N$10:$N$20,MATCH(H$5,'Growth Rates'!$C$10:$C$20,0)),0)} -> 0 | I32: {=IFERROR(INDEX('Growth Rates'!$N$10:$N$20,MATCH(I$5,'Growth Rates'!$C$10:$C$20,0)),0)} -> 0 | J32: {=IFERROR(INDEX('Growth Rates'!$N$10:$N$20,MATCH(J$5,'Growth Rates'!$C$10:$C$20,0)),0)} -> 0 | K32: {=IFERROR(INDEX('Growth Rates'!$N$10:$N$20,MATCH(K$5,'Growth Rates'!$C$10:$C$20,0)),0)} -> 0 | L32: {=IFERROR(INDEX('Growth Rates'!$N$10:$N$20,MATCH(L$5,'Growth Rates'!$C$10:$C$20,0)),0)} -> 0 | M32: {=IFERROR(INDEX('Growth Rates'!$N$10:$N$20,MATCH(M$5,'Growth Rates'!$C$10:$C$20,0)),0)} -> 0 | N32: {=IFERROR(INDEX('Growth Rates'!$N$10:$N$20,MATCH(N$5,'Growth Rates'!$C$10:$C$20,0)),0)} -> 0 | ... EI32: {=IFERROR(INDEX('Growth Rates'!$N$10:$N$20,MATCH(EI$5,'Growth Rates'!$C$10:$C$20,0)),0)} -> 0.03
C33: Management Fee Growth | G33: {=IFERROR(INDEX('Growth Rates'!$O$10:$O$20,MATCH(G$5,'Growth Rates'!$C$10:$C$20,0)),0)} -> 0 | H33: {=IFERROR(INDEX('Growth Rates'!$O$10:$O$20,MATCH(H$5,'Growth Rates'!$C$10:$C$20,0)),0)} -> 0.03 | I33: {=IFERROR(INDEX('Growth Rates'!$O$10:$O$20,MATCH(I$5,'Growth Rates'!$C$10:$C$20,0)),0)} -> 0.03 | J33: {=IFERROR(INDEX('Growth Rates'!$O$10:$O$20,MATCH(J$5,'Growth Rates'!$C$10:$C$20,0)),0)} -> 0.03 | K33: {=IFERROR(INDEX('Growth Rates'!$O$10:$O$20,MATCH(K$5,'Growth Rates'!$C$10:$C$20,0)),0)} -> 0.03 | L33: {=IFERROR(INDEX('Growth Rates'!$O$10:$O$20,MATCH(L$5,'Growth Rates'!$C$10:$C$20,0)),0)} -> 0.03 | M33: {=IFERROR(INDEX('Growth Rates'!$O$10:$O$20,MATCH(M$5,'Growth Rates'!$C$10:$C$20,0)),0)} -> 0.03 | N33: {=IFERROR(INDEX('Growth Rates'!$O$10:$O$20,MATCH(N$5,'Growth Rates'!$C$10:$C$20,0)),0)} -> 0.03 | ... EI33: {=IFERROR(INDEX('Growth Rates'!$O$10:$O$20,MATCH(EI$5,'Growth Rates'!$C$10:$C$20,0)),0)} -> 0.03
C35: Income & Expenses
C37: Income
C38: Rental Income | G38: =G13 -> 0 | H38: =H13 -> 0 | I38: =I13 -> 0 | J38: =J13 -> 0 | K38: =K13 -> 0 | L38: =L13 -> 0 | M38: =M13 -> 0 | N38: =N13 -> 0 | ... EI38: =EI13 -> 509277.11
C39: Gross Potential Rent | G39: =SUM(G38) -> 0 | H39: =SUM(H38) -> 0 | I39: =SUM(I38) -> 0 | J39: =SUM(J38) -> 0 | K39: =SUM(K38) -> 0 | L39: =SUM(L38) -> 0 | M39: =SUM(M38) -> 0 | N39: =SUM(N38) -> 0 | ... EI39: =SUM(EI38) -> 509277.11
C41: Losses to GPR
C42: Market Vacancy | G42: =IF(G17>(1-G19),-G39*G19,0) -> 0 | H42: =IF(H17>(1-H19),-H39*H19,0) -> 0 | I42: =IF(I17>(1-I19),-I39*I19,0) -> 0 | J42: =IF(J17>(1-J19),-J39*J19,0) -> 0 | K42: =IF(K17>(1-K19),-K39*K19,0) -> 0 | L42: =IF(L17>(1-L19),-L39*L19,0) -> 0 | M42: =IF(M17>(1-M19),-M39*M19,0) -> 0 | N42: =IF(N17>(1-N19),-N39*N19,0) -> 0 | ... EI42: =IF(EI17>(1-EI19),-EI39*EI19,0) -> -25463.856
C43: Non-Rev Beds | G43: =G$39*-G23 -> 0 | H43: =H$39*-H23 -> 0 | I43: =I$39*-I23 -> 0 | J43: =J$39*-J23 -> 0 | K43: =K$39*-K23 -> 0 | L43: =L$39*-L23 -> 0 | M43: =M$39*-M23 -> 0 | N43: =N$39*-N23 -> 0 | ... EI43: =EI$39*-EI23 -> -1273.1928
C44: Bad Debt | G44: =G$39*-G24 -> 0 | H44: =H$39*-H24 -> 0 | I44: =I$39*-I24 -> 0 | J44: =J$39*-J24 -> 0 | K44: =K$39*-K24 -> 0 | L44: =L$39*-L24 -> 0 | M44: =M$39*-M24 -> 0 | N44: =N$39*-N24 -> 0 | ... EI44: =EI$39*-EI24 -> -3819.5783
C45: Concessions | G45: =G$39*-G25 -> 0 | H45: =H$39*-H25 -> 0 | I45: =I$39*-I25 -> 0 | J45: =J$39*-J25 -> 0 | K45: =K$39*-K25 -> 0 | L45: =L$39*-L25 -> 0 | M45: =M$39*-M25 -> 0 | N45: =N$39*-N25 -> 0 | ... EI45: =EI$39*-EI25 -> -1273.1928
C46: Total Losses to GPR | G46: =SUM(G42:G45) -> 0 | H46: =SUM(H42:H45) -> 0 | I46: =SUM(I42:I45) -> 0 | J46: =SUM(J42:J45) -> 0 | K46: =SUM(K42:K45) -> 0 | L46: =SUM(L42:L45) -> 0 | M46: =SUM(M42:M45) -> 0 | N46: =SUM(N42:N45) -> 0 | ... EI46: =SUM(EI42:EI45) -> -31829.819
C48: Effective Rental Income | G48: =+G39+G46 -> 0 | H48: =+H39+H46 -> 0 | I48: =+I39+I46 -> 0 | J48: =+J39+J46 -> 0 | K48: =+K39+K46 -> 0 | L48: =+L39+L46 -> 0 | M48: =+M39+M46 -> 0 | N48: =+N39+N46 -> 0 | ... EI48: =+EI39+EI46 -> 477447.29
C50: Other Income
C51: Parking Permit Fees | G51: {=IFERROR(INDEX('OI & Expense Growth'!$F7:$P7,MATCH('Monthly CFs'!G$5,'OI & Expense Growth'!$F$4:$P$4,0))*G$17/12,0)} -> 0 | H51: {=IFERROR(INDEX('OI & Expense Growth'!$F7:$P7,MATCH('Monthly CFs'!H$5,'OI & Expense Growth'!$F$4:$P$4,0))*H$17/12,0)} -> 0 | I51: {=IFERROR(INDEX('OI & Expense Growth'!$F7:$P7,MATCH('Monthly CFs'!I$5,'OI & Expense Growth'!$F$4:$P$4,0))*I$17/12,0)} -> 0 | J51: {=IFERROR(INDEX('OI & Expense Growth'!$F7:$P7,MATCH('Monthly CFs'!J$5,'OI & Expense Growth'!$F$4:$P$4,0))*J$17/12,0)} -> 0 | K51: {=IFERROR(INDEX('OI & Expense Growth'!$F7:$P7,MATCH('Monthly CFs'!K$5,'OI & Expense Growth'!$F$4:$P$4,0))*K$17/12,0)} -> 0 | L51: {=IFERROR(INDEX('OI & Expense Growth'!$F7:$P7,MATCH('Monthly CFs'!L$5,'OI & Expense Growth'!$F$4:$P$4,0))*L$17/12,0)} -> 0 | M51: {=IFERROR(INDEX('OI & Expense Growth'!$F7:$P7,MATCH('Monthly CFs'!M$5,'OI & Expense Growth'!$F$4:$P$4,0))*M$17/12,0)} -> 0 | N51: {=IFERROR(INDEX('OI & Expense Growth'!$F7:$P7,MATCH('Monthly CFs'!N$5,'OI & Expense Growth'!$F$4:$P$4,0))*N$17/12,0)} -> 0 | ... EI51: {=IFERROR(INDEX('OI & Expense Growth'!$F7:$P7,MATCH('Monthly CFs'!EI$5,'OI & Expense Growth'!$F$4:$P$4,0))*EI$17/12,0)} -> 44890.396
C52: Utility Charge | G52: {=IFERROR(INDEX('OI & Expense Growth'!$F8:$P8,MATCH('Monthly CFs'!G$5,'OI & Expense Growth'!$F$4:$P$4,0))*G$17/12,0)} -> 0 | H52: {=IFERROR(INDEX('OI & Expense Growth'!$F8:$P8,MATCH('Monthly CFs'!H$5,'OI & Expense Growth'!$F$4:$P$4,0))*H$17/12,0)} -> 0 | I52: {=IFERROR(INDEX('OI & Expense Growth'!$F8:$P8,MATCH('Monthly CFs'!I$5,'OI & Expense Growth'!$F$4:$P$4,0))*I$17/12,0)} -> 0 | J52: {=IFERROR(INDEX('OI & Expense Growth'!$F8:$P8,MATCH('Monthly CFs'!J$5,'OI & Expense Growth'!$F$4:$P$4,0))*J$17/12,0)} -> 0 | K52: {=IFERROR(INDEX('OI & Expense Growth'!$F8:$P8,MATCH('Monthly CFs'!K$5,'OI & Expense Growth'!$F$4:$P$4,0))*K$17/12,0)} -> 0 | L52: {=IFERROR(INDEX('OI & Expense Growth'!$F8:$P8,MATCH('Monthly CFs'!L$5,'OI & Expense Growth'!$F$4:$P$4,0))*L$17/12,0)} -> 0 | M52: {=IFERROR(INDEX('OI & Expense Growth'!$F8:$P8,MATCH('Monthly CFs'!M$5,'OI & Expense Growth'!$F$4:$P$4,0))*M$17/12,0)} -> 0 | N52: {=IFERROR(INDEX('OI & Expense Growth'!$F8:$P8,MATCH('Monthly CFs'!N$5,'OI & Expense Growth'!$F$4:$P$4,0))*N$17/12,0)} -> 0 | ... EI52: {=IFERROR(INDEX('OI & Expense Growth'!$F8:$P8,MATCH('Monthly CFs'!EI$5,'OI & Expense Growth'!$F$4:$P$4,0))*EI$17/12,0)} -> 13282.638
