Workbook
Name ________EXP1: #REF!
Name ________EXP1: #REF!
Name ________LTL1: #REF!
Name ________LTL2: #REF!
Name ________LTL3: #REF!
Name ________LTL4: #REF!
Name ________LTL5: #REF!
Name ________LTL6: #REF!
Name _______EXP1: #REF!
Name _______EXP1: #REF!
Name _______LTL1: #REF!
Name _______LTL2: #REF!
Name _______LTL3: #REF!
Name _______LTL4: #REF!
Name _______LTL5: #REF!
Name _______LTL6: #REF!
Name ______EXP1: #REF!
Name ______EXP1: #REF!
Name ____GPR1: #REF!
Name ____GPR2: #REF!
Name ____GPR3: #REF!
Name ____GPR4: #REF!
Name ____GPR5: #REF!
Name ____GPR6: #REF!
Name ____LA1: #REF!
Name ____REF1: #N/A
Name ____REF2: #N/A
Name ___ASS1: #N/A
Name ___ASS2: #N/A
Name ___ass3: #N/A
Name ___AVI1: #N/A
Name ___CAM96: #REF!
Name ___CAM96: #REF!
Name ___CAM97: #REF!
Name ___CAM9710: #REF!
Name ___CAM9710: #REF!
Name ___GPR1: #REF!
Name ___GPR2: #REF!
Name ___GPR3: #REF!
Name ___GPR4: #REF!
Name ___GPR5: #REF!
Name ___GPR6: #REF!
Name ___GSF2: #N/A
Name ___INF1: #N/A
Name ___INF2: #N/A
Name ___INS97: #REF!
Name ___LA1: #REF!
Name ___LC1: #N/A
Name ___LC2: #N/A
Name ___LC3: #N/A
Name ___LTL1: #REF!
Name ___LTL2: #REF!
Name ___LTL3: #REF!
Name ___LTL4: #REF!
Name ___LTL5: #REF!
Name ___LTL6: #REF!
Name ___MGT2: #N/A
Name ___MGT3: #N/A
Name ___PER1: #REF!
Name ___PER1: #REF!

Sheet Disclaimer
B3: =+Assumptions!B2 -> Westview Austin
B4: =TODAY() -> 46199
B6: DISCLAIMER
B7: This confidential summary contains forward-looking statements that are not historical facts. These forward-looking statements include statements, express or implied, regarding the current expectations, estimates, projections, opinions and beliefs of the Arc Capital Partners LLC ("Company"), as well as certain assumptions on which those statements are based. Such forward-looking statements are subject to risks, uncertainties and other factors that may cause actual events to differ materially from any anticipated development and no assurance can be given that the Company, or any investment vehicle that may be formed or managed by the Company in the future, will achieve the projected returns. The pro forma information set forth in this confidential summary is shown for illustration purposes only and should not be relied upon. No representation or assurance is made that any potential investor will or is likely to achieve results comparable to those shown or will make any profit or will be able to avoid incurring substantial losses. The information contained herein is confidential and intended solely for use by the Company and persons to whom the Company has delivered this document. This confidential summary is not to be reproduced or distributed to any third party. The recipient, by accepting this document, agrees to this restriction and to return the document to the Company upon request. The pro forma information reflects the Company’s judgment, based on current circumstances, of the most likely set of conditions and its most likely course of action. The assumptions disclosed herein are those that the Company believes are significant to the pro forma information or are key factors upon which the financial results of the Company and any potential real estate investment opportunity depend. Some assumptions inevitably will not materialize and unanticipated events and circumstances may occur subsequent to the date of this information. Therefore, the actual results achieved during the forecast period will vary from the forecast, and the variations may be material. None of the Company, its managers, officers, directors, employees or affiliates assume any responsibility to notify recipients of any updates to this pro forma information if there are changes to the assumptions or results. Recipients are encouraged to consult with their own professional advisors concerning this pro forma information, including the assumptions used. The Company will make available additional information upon request concerning the pro forma information to the extent it is readily available to the Company at no additional cost and the Company is not otherwise restricted from providing such information.

Sheet Lease Audit Report
A1: Lease Audit Report
A2: Ten-O-Five St. Elmo - Arc Model 9.28.2021 (Amounts in USD, Measures in SF)
A3: Oct, 2021 through Sep, 2032
A4: 10/2/2021 2:33:18 PM
D5: 1 | E5: 1 | F5: 1 | G5: 1 | H5: 1 | I5: 1 | J5: 1 | K5: 1 | L5: 1 | M5: 1 | N5: 1 | O5: 1 | P5: =D5+1 -> 2 | Q5: =E5+1 -> 2 | R5: =F5+1 -> 2 | S5: =G5+1 -> 2 | T5: =H5+1 -> 2 | U5: =I5+1 -> 2 | V5: =J5+1 -> 2 | W5: =K5+1 -> 2 | ... ED5: =DR5+1 -> 11
C6: Month 1 | D6: Month 2 | E6: Month 3 | F6: Month 4 | G6: Month 5 | H6: Month 6 | I6: Month 7 | J6: Month 8 | K6: Month 9 | L6: Month 10 | M6: Month 11 | N6: Month 12 | O6: Month 13 | P6: Month 14 | Q6: Month 15 | R6: Month 16 | S6: Month 17 | T6: Month 18 | U6: Month 19 | V6: Month 20 | W6: Month 21 | X6: Month 22 | Y6: Month 23 | Z6: Month 24 | AA6: Month 25 | AB6: Month 26 | AC6: Month 27 | AD6: Month 28 | AE6: Month 29 | AF6: Month 30 | AG6: Month 31 | AH6: Month 32 | AI6: Month 33 | AJ6: Month 34 | AK6: Month 35 | AL6: Month 36 | AM6: Month 37 | AN6: Month 38 | AO6: Month 39 | AP6: Month 40 | AQ6: Month 41 | AR6: Month 42 | AS6: Month 43 | AT6: Month 44 | AU6: Month 45 | AV6: Month 46 | AW6: Month 47 | AX6: Month 48 | AY6: Month 49 | AZ6: Month 50 | BA6: Month 51 | BB6: Month 52 | BC6: Month 53 | BD6: Month 54 | BE6: Month 55 | BF6: Month 56 | BG6: Month 57 | BH6: Month 58 | BI6: Month 59 | BJ6: Month 60 | BK6: Month 61 | BL6: Month 62 | BM6: Month 63 | BN6: Month 64 | BO6: Month 65 | BP6: Month 66 | BQ6: Month 67 | BR6: Month 68 | BS6: Month 69 | BT6: Month 70 | BU6: Month 71 | BV6: Month 72 | BW6: Month 73 | BX6: Month 74 | BY6: Month 75 | BZ6: Month 76 | CA6: Month 77 | CB6: Month 78 | CC6: Month 79 | CD6: Month 80 | CE6: Month 81 | CF6: Month 82 | CG6: Month 83 | CH6: Month 84 | CI6: Month 85 | CJ6: Month 86 | CK6: Month 87 | CL6: Month 88 | CM6: Month 89 | CN6: Month 90 | CO6: Month 91 | CP6: Month 92 | CQ6: Month 93 | CR6: Month 94 | CS6: Month 95 | CT6: Month 96 | CU6: Month 97 | CV6: Month 98 | CW6: Month 99 | CX6: Month 100 | CY6: Month 101 | CZ6: Month 102 | DA6: Month 103 | DB6: Month 104 | DC6: Month 105 | DD6: Month 106 | DE6: Month 107 | DF6: Month 108 | DG6: Month 109 | DH6: Month 110 | DI6: Month 111 | DJ6: Month 112 | DK6: Month 113 | DL6: Month 114 | DM6: Month 115 | DN6: Month 116 | DO6: Month 117 | DP6: Month 118 | DQ6: Month 119 | DR6: Month 120 | DS6: Month 121 | DT6: Month 122 | DU6: Month 123 | DV6: Month 124 | DW6: Month 125 | DX6: Month 126 | DY6: Month 127 | DZ6: Month 128 | EA6: Month 129 | EB6: Month 130 | EC6: Month 131 | ED6: Month 132
A7: For the Months | B7: Suite | C7: Oct-2021 | D7: Nov-2021 | E7: Dec-2021 | F7: Jan-2022 | G7: Feb-2022 | H7: Mar-2022 | I7: Apr-2022 | J7: May-2022 | K7: Jun-2022 | L7: Jul-2022 | M7: Aug-2022 | N7: Sep-2022 | O7: Oct-2022 | P7: Nov-2022 | Q7: Dec-2022 | R7: Jan-2023 | S7: Feb-2023 | T7: Mar-2023 | U7: Apr-2023 | V7: May-2023 | W7: Jun-2023 | X7: Jul-2023 | Y7: Aug-2023 | Z7: Sep-2023 | AA7: Oct-2023 | AB7: Nov-2023 | AC7: Dec-2023 | AD7: Jan-2024 | AE7: Feb-2024 | AF7: Mar-2024 | AG7: Apr-2024 | AH7: May-2024 | AI7: Jun-2024 | AJ7: Jul-2024 | AK7: Aug-2024 | AL7: Sep-2024 | AM7: Oct-2024 | AN7: Nov-2024 | AO7: Dec-2024 | AP7: Jan-2025 | AQ7: Feb-2025 | AR7: Mar-2025 | AS7: Apr-2025 | AT7: May-2025 | AU7: Jun-2025 | AV7: Jul-2025 | AW7: Aug-2025 | AX7: Sep-2025 | AY7: Oct-2025 | AZ7: Nov-2025 | BA7: Dec-2025 | BB7: Jan-2026 | BC7: Feb-2026 | BD7: Mar-2026 | BE7: Apr-2026 | BF7: May-2026 | BG7: Jun-2026 | BH7: Jul-2026 | BI7: Aug-2026 | BJ7: Sep-2026 | BK7: Oct-2026 | BL7: Nov-2026 | BM7: Dec-2026 | BN7: Jan-2027 | BO7: Feb-2027 | BP7: Mar-2027 | BQ7: Apr-2027 | BR7: May-2027 | BS7: Jun-2027 | BT7: Jul-2027 | BU7: Aug-2027 | BV7: Sep-2027 | BW7: Oct-2027 | BX7: Nov-2027 | BY7: Dec-2027 | BZ7: Jan-2028 | CA7: Feb-2028 | CB7: Mar-2028 | CC7: Apr-2028 | CD7: May-2028 | CE7: Jun-2028 | CF7: Jul-2028 | CG7: Aug-2028 | CH7: Sep-2028 | CI7: Oct-2028 | CJ7: Nov-2028 | CK7: Dec-2028 | CL7: Jan-2029 | CM7: Feb-2029 | CN7: Mar-2029 | CO7: Apr-2029 | CP7: May-2029 | CQ7: Jun-2029 | CR7: Jul-2029 | CS7: Aug-2029 | CT7: Sep-2029 | CU7: Oct-2029 | CV7: Nov-2029 | CW7: Dec-2029 | CX7: Jan-2030 | CY7: Feb-2030 | CZ7: Mar-2030 | DA7: Apr-2030 | DB7: May-2030 | DC7: Jun-2030 | DD7: Jul-2030 | DE7: Aug-2030 | DF7: Sep-2030 | DG7: Oct-2030 | DH7: Nov-2030 | DI7: Dec-2030 | DJ7: Jan-2031 | DK7: Feb-2031 | DL7: Mar-2031 | DM7: Apr-2031 | DN7: May-2031 | DO7: Jun-2031 | DP7: Jul-2031 | DQ7: Aug-2031 | DR7: Sep-2031 | DS7: Oct-2031 | DT7: Nov-2031 | DU7: Dec-2031 | DV7: Jan-2032 | DW7: Feb-2032 | DX7: Mar-2032 | DY7: Apr-2032 | DZ7: May-2032 | EA7: Jun-2032 | EB7: Jul-2032 | EC7: Aug-2032 | ED7: Sep-2032 | EE7: Total
A8: Area
A9: 1. Kitu Life, Inc. | B9: 1 | C9: 8085 | D9: 8085 | E9: 8085 | F9: 8085 | G9: 8085 | H9: 8085 | I9: 8085 | J9: 8085 | K9: 8085 | L9: 8085 | M9: 8085 | N9: 8085 | O9: 8085 | P9: 8085 | Q9: 8085 | R9: 8085 | S9: 8085 | T9: 8085 | U9: 8085 | V9: 8085 | W9: 8085 | X9: 8085 | Y9: 8085 | Z9: 8085 | AA9: 8085 | AB9: 8085 | AC9: 8085 | AD9: 8085 | AE9: 8085 | AF9: 8085 | AG9: 8085 | AH9: 8085 | AI9: 8085 | AJ9: 8085 | AK9: 8085 | AL9: 8085 | AM9: 8085 | AN9: 8085 | AO9: 8085 | AP9: 8085 | AQ9: 8085 | AR9: 8085 | AS9: 8085 | AT9: 8085 | AU9: 8085 | AV9: 8085 | AW9: 8085 | AX9: 8085 | AY9: 8085 | AZ9: 8085 | BA9: 8085 | BB9: 8085 | BC9: 8085 | BD9: 8085 | BE9: 8085 | BF9: 8085 | BG9: 8085 | BH9: 8085 | BI9: 8085 | BJ9: 8085 | BK9: 0 | BL9: 0 | BM9: 8085 | BN9: 8085 | BO9: 8085 | BP9: 8085 | BQ9: 8085 | BR9: 8085 | BS9: 8085 | BT9: 8085 | BU9: 8085 | BV9: 8085 | BW9: 8085 | BX9: 8085 | BY9: 8085 | BZ9: 8085 | CA9: 8085 | CB9: 8085 | CC9: 8085 | CD9: 8085 | CE9: 8085 | CF9: 8085 | CG9: 8085 | CH9: 8085 | CI9: 8085 | CJ9: 8085 | CK9: 8085 | CL9: 8085 | CM9: 8085 | CN9: 8085 | CO9: 8085 | CP9: 8085 | CQ9: 8085 | CR9: 8085 | CS9: 8085 | CT9: 8085 | CU9: 8085 | CV9: 8085 | CW9: 8085 | CX9: 8085 | CY9: 8085 | CZ9: 8085 | DA9: 8085 | DB9: 8085 | DC9: 8085 | DD9: 8085 | DE9: 8085 | DF9: 8085 | DG9: 8085 | DH9: 8085 | DI9: 8085 | DJ9: 8085 | DK9: 8085 | DL9: 8085 | DM9: 8085 | DN9: 8085 | DO9: 8085 | DP9: 8085 | DQ9: 8085 | DR9: 8085 | DS9: 8085 | DT9: 8085 | DU9: 8085 | DV9: 8085 | DW9: 8085 | DX9: 0 | DY9: 0 | DZ9: 8085 | EA9: 8085 | EB9: 8085 | EC9: 8085 | ED9: 8085
A10: 2. VACANT | B10: 2 | C10: 0 | D10: 0 | E10: 0 | F10: 0 | G10: 0 | H10: 0 | I10: 0 | J10: 8956 | K10: 8956 | L10: 8956 | M10: 8956 | N10: 8956 | O10: 8956 | P10: 8956 | Q10: 8956 | R10: 8956 | S10: 8956 | T10: 8956 | U10: 8956 | V10: 8956 | W10: 8956 | X10: 8956 | Y10: 8956 | Z10: 8956 | AA10: 8956 | AB10: 8956 | AC10: 8956 | AD10: 8956 | AE10: 8956 | AF10: 8956 | AG10: 8956 | AH10: 8956 | AI10: 8956 | AJ10: 8956 | AK10: 8956 | AL10: 8956 | AM10: 8956 | AN10: 8956 | AO10: 8956 | AP10: 8956 | AQ10: 8956 | AR10: 8956 | AS10: 8956 | AT10: 8956 | AU10: 8956 | AV10: 8956 | AW10: 8956 | AX10: 8956 | AY10: 8956 | AZ10: 8956 | BA10: 8956 | BB10: 8956 | BC10: 8956 | BD10: 8956 | BE10: 8956 | BF10: 8956 | BG10: 8956 | BH10: 8956 | BI10: 8956 | BJ10: 8956 | BK10: 8956 | BL10: 8956 | BM10: 8956 | BN10: 8956 | BO10: 8956 | BP10: 8956 | BQ10: 8956 | BR10: 8956 | BS10: 8956 | BT10: 8956 | BU10: 0 | BV10: 0 | BW10: 8956 | BX10: 8956 | BY10: 8956 | BZ10: 8956 | CA10: 8956 | CB10: 8956 | CC10: 8956 | CD10: 8956 | CE10: 8956 | CF10: 8956 | CG10: 8956 | CH10: 8956 | CI10: 8956 | CJ10: 8956 | CK10: 8956 | CL10: 8956 | CM10: 8956 | CN10: 8956 | CO10: 8956 | CP10: 8956 | CQ10: 8956 | CR10: 8956 | CS10: 8956 | CT10: 8956 | CU10: 8956 | CV10: 8956 | CW10: 8956 | CX10: 8956 | CY10: 8956 | CZ10: 8956 | DA10: 8956 | DB10: 8956 | DC10: 8956 | DD10: 8956 | DE10: 8956 | DF10: 8956 | DG10: 8956 | DH10: 8956 | DI10: 8956 | DJ10: 8956 | DK10: 8956 | DL10: 8956 | DM10: 8956 | DN10: 8956 | DO10: 8956 | DP10: 8956 | DQ10: 8956 | DR10: 8956 | DS10: 8956 | DT10: 8956 | DU10: 8956 | DV10: 8956 | DW10: 8956 | DX10: 8956 | DY10: 8956 | DZ10: 8956 | EA10: 8956 | EB10: 8956 | EC10: 8956 | ED10: 8956
A11: 3. Saatva | B11: 3 | C11: 6000 | D11: 6000 | E11: 6000 | F11: 6000 | G11: 6000 | H11: 6000 | I11: 6000 | J11: 6000 | K11: 6000 | L11: 6000 | M11: 6000 | N11: 6000 | O11: 6000 | P11: 6000 | Q11: 6000 | R11: 6000 | S11: 6000 | T11: 6000 | U11: 6000 | V11: 6000 | W11: 6000 | X11: 6000 | Y11: 6000 | Z11: 6000 | AA11: 6000 | AB11: 6000 | AC11: 6000 | AD11: 0 | AE11: 0 | AF11: 6009 | AG11: 6009 | AH11: 6009 | AI11: 6009 | AJ11: 6009 | AK11: 6009 | AL11: 6009 | AM11: 6009 | AN11: 6009 | AO11: 6009 | AP11: 6009 | AQ11: 6009 | AR11: 6009 | AS11: 6009 | AT11: 6009 | AU11: 6009 | AV11: 6009 | AW11: 6009 | AX11: 6009 | AY11: 6009 | AZ11: 6009 | BA11: 6009 | BB11: 6009 | BC11: 6009 | BD11: 6009 | BE11: 6009 | BF11: 6009 | BG11: 6009 | BH11: 6009 | BI11: 6009 | BJ11: 6009 | BK11: 6009 | BL11: 6009 | BM11: 6009 | BN11: 6009 | BO11: 6009 | BP11: 6009 | BQ11: 6009 | BR11: 6009 | BS11: 6009 | BT11: 6009 | BU11: 6009 | BV11: 6009 | BW11: 6009 | BX11: 6009 | BY11: 6009 | BZ11: 6009 | CA11: 6009 | CB11: 6009 | CC11: 6009 | CD11: 6009 | CE11: 6009 | CF11: 6009 | CG11: 6009 | CH11: 6009 | CI11: 6009 | CJ11: 6009 | CK11: 6009 | CL11: 6009 | CM11: 6009 | CN11: 6009 | CO11: 6009 | CP11: 6009 | CQ11: 0 | CR11: 0 | CS11: 6009 | CT11: 6009 | CU11: 6009 | CV11: 6009 | CW11: 6009 | CX11: 6009 | CY11: 6009 | CZ11: 6009 | DA11: 6009 | DB11: 6009 | DC11: 6009 | DD11: 6009 | DE11: 6009 | DF11: 6009 | DG11: 6009 | DH11: 6009 | DI11: 6009 | DJ11: 6009 | DK11: 6009 | DL11: 6009 | DM11: 6009 | DN11: 6009 | DO11: 6009 | DP11: 6009 | DQ11: 6009 | DR11: 6009 | DS11: 6009 | DT11: 6009 | DU11: 6009 | DV11: 6009 | DW11: 6009 | DX11: 6009 | DY11: 6009 | DZ11: 6009 | EA11: 6009 | EB11: 6009 | EC11: 6009 | ED11: 6009
A12: 4. Fuse Architecture Studio | B12: 4 | C12: 3000 | D12: 3000 | E12: 3000 | F12: 3000 | G12: 3000 | H12: 3000 | I12: 3000 | J12: 3000 | K12: 3000 | L12: 3000 | M12: 3000 | N12: 3000 | O12: 3000 | P12: 3000 | Q12: 3000 | R12: 3000 | S12: 3000 | T12: 3000 | U12: 3000 | V12: 0 | W12: 0 | X12: 3143 | Y12: 3143 | Z12: 3143 | AA12: 3143 | AB12: 3143 | AC12: 3143 | AD12: 3143 | AE12: 3143 | AF12: 3143 | AG12: 3143 | AH12: 3143 | AI12: 3143 | AJ12: 3143 | AK12: 3143 | AL12: 3143 | AM12: 3143 | AN12: 3143 | AO12: 3143 | AP12: 3143 | AQ12: 3143 | AR12: 3143 | AS12: 3143 | AT12: 3143 | AU12: 3143 | AV12: 3143 | AW12: 3143 | AX12: 3143 | AY12: 3143 | AZ12: 3143 | BA12: 3143 | BB12: 3143 | BC12: 3143 | BD12: 3143 | BE12: 3143 | BF12: 3143 | BG12: 3143 | BH12: 3143 | BI12: 3143 | BJ12: 3143 | BK12: 3143 | BL12: 3143 | BM12: 3143 | BN12: 3143 | BO12: 3143 | BP12: 3143 | BQ12: 3143 | BR12: 3143 | BS12: 3143 | BT12: 3143 | BU12: 3143 | BV12: 3143 | BW12: 3143 | BX12: 3143 | BY12: 3143 | BZ12: 3143 | CA12: 3143 | CB12: 3143 | CC12: 3143 | CD12: 3143 | CE12: 3143 | CF12: 3143 | CG12: 3143 | CH12: 3143 | CI12: 0 | CJ12: 0 | CK12: 3143 | CL12: 3143 | CM12: 3143 | CN12: 3143 | CO12: 3143 | CP12: 3143 | CQ12: 3143 | CR12: 3143 | CS12: 3143 | CT12: 3143 | CU12: 3143 | CV12: 3143 | CW12: 3143 | CX12: 3143 | CY12: 3143 | CZ12: 3143 | DA12: 3143 | DB12: 3143 | DC12: 3143 | DD12: 3143 | DE12: 3143 | DF12: 3143 | DG12: 3143 | DH12: 3143 | DI12: 3143 | DJ12: 3143 | DK12: 3143 | DL12: 3143 | DM12: 3143 | DN12: 3143 | DO12: 3143 | DP12: 3143 | DQ12: 3143 | DR12: 3143 | DS12: 3143 | DT12: 3143 | DU12: 3143 | DV12: 3143 | DW12: 3143 | DX12: 3143 | DY12: 3143 | DZ12: 3143 | EA12: 3143 | EB12: 3143 | EC12: 3143 | ED12: 3143
A13: 5. Made In (sublessee to Geek Powered Studios) | B13: 5 | C13: 6000 | D13: 6000 | E13: 6000 | F13: 6000 | G13: 6000 | H13: 6000 | I13: 6000 | J13: 0 | K13: 0 | L13: 0 | M13: 0 | N13: 0 | O13: 0 | P13: 6057 | Q13: 6057 | R13: 6057 | S13: 6057 | T13: 6057 | U13: 6057 | V13: 6057 | W13: 6057 | X13: 6057 | Y13: 6057 | Z13: 6057 | AA13: 6057 | AB13: 6057 | AC13: 6057 | AD13: 6057 | AE13: 6057 | AF13: 6057 | AG13: 6057 | AH13: 6057 | AI13: 6057 | AJ13: 6057 | AK13: 6057 | AL13: 6057 | AM13: 6057 | AN13: 6057 | AO13: 6057 | AP13: 6057 | AQ13: 6057 | AR13: 6057 | AS13: 6057 | AT13: 6057 | AU13: 6057 | AV13: 6057 | AW13: 6057 | AX13: 6057 | AY13: 6057 | AZ13: 6057 | BA13: 6057 | BB13: 6057 | BC13: 6057 | BD13: 6057 | BE13: 6057 | BF13: 6057 | BG13: 6057 | BH13: 6057 | BI13: 6057 | BJ13: 6057 | BK13: 6057 | BL13: 6057 | BM13: 6057 | BN13: 6057 | BO13: 6057 | BP13: 6057 | BQ13: 6057 | BR13: 6057 | BS13: 6057 | BT13: 6057 | BU13: 6057 | BV13: 6057 | BW13: 6057 | BX13: 6057 | BY13: 6057 | BZ13: 6057 | CA13: 0 | CB13: 0 | CC13: 6057 | CD13: 6057 | CE13: 6057 | CF13: 6057 | CG13: 6057 | CH13: 6057 | CI13: 6057 | CJ13: 6057 | CK13: 6057 | CL13: 6057 | CM13: 6057 | CN13: 6057 | CO13: 6057 | CP13: 6057 | CQ13: 6057 | CR13: 6057 | CS13: 6057 | CT13: 6057 | CU13: 6057 | CV13: 6057 | CW13: 6057 | CX13: 6057 | CY13: 6057 | CZ13: 6057 | DA13: 6057 | DB13: 6057 | DC13: 6057 | DD13: 6057 | DE13: 6057 | DF13: 6057 | DG13: 6057 | DH13: 6057 | DI13: 6057 | DJ13: 6057 | DK13: 6057 | DL13: 6057 | DM13: 6057 | DN13: 6057 | DO13: 6057 | DP13: 6057 | DQ13: 6057 | DR13: 6057 | DS13: 6057 | DT13: 6057 | DU13: 6057 | DV13: 6057 | DW13: 6057 | DX13: 6057 | DY13: 6057 | DZ13: 6057 | EA13: 6057 | EB13: 6057 | EC13: 6057 | ED13: 6057
A14: 6. Elmo 35, LLC | B14: 6 | C14: 6569 | D14: 6569 | E14: 6569 | F14: 6569 | G14: 6569 | H14: 6569 | I14: 6569 | J14: 6569 | K14: 6569 | L14: 6569 | M14: 6569 | N14: 6569 | O14: 6569 | P14: 6569 | Q14: 6569 | R14: 6569 | S14: 6569 | T14: 6569 | U14: 6569 | V14: 6569 | W14: 6569 | X14: 6569 | Y14: 6569 | Z14: 6569 | AA14: 6569 | AB14: 6569 | AC14: 6569 | AD14: 6569 | AE14: 6569 | AF14: 6569 | AG14: 6569 | AH14: 6569 | AI14: 6569 | AJ14: 6569 | AK14: 6569 | AL14: 6569 | AM14: 6569 | AN14: 6569 | AO14: 6569 | AP14: 6569 | AQ14: 6569 | AR14: 6569 | AS14: 6569 | AT14: 6569 | AU14: 6569 | AV14: 6569 | AW14: 6569 | AX14: 6569 | AY14: 6569 | AZ14: 6569 | BA14: 6569 | BB14: 6569 | BC14: 6569 | BD14: 6569 | BE14: 6569 | BF14: 6569 | BG14: 6569 | BH14: 6569 | BI14: 6569 | BJ14: 6569 | BK14: 6569 | BL14: 6569 | BM14: 6569 | BN14: 6569 | BO14: 6569 | BP14: 6569 | BQ14: 6569 | BR14: 6569 | BS14: 6569 | BT14: 6569 | BU14: 6569 | BV14: 6569 | BW14: 6569 | BX14: 6569 | BY14: 6569 | BZ14: 6569 | CA14: 6569 | CB14: 6569 | CC14: 6569 | CD14: 6569 | CE14: 6569 | CF14: 6569 | CG14: 6569 | CH14: 6569 | CI14: 0 | CJ14: 0 | CK14: 6569 | CL14: 6569 | CM14: 6569 | CN14: 6569 | CO14: 6569 | CP14: 6569 | CQ14: 6569 | CR14: 6569 | CS14: 6569 | CT14: 6569 | CU14: 6569 | CV14: 6569 | CW14: 6569 | CX14: 6569 | CY14: 6569 | CZ14: 6569 | DA14: 6569 | DB14: 6569 | DC14: 6569 | DD14: 6569 | DE14: 6569 | DF14: 6569 | DG14: 6569 | DH14: 6569 | DI14: 6569 | DJ14: 6569 | DK14: 6569 | DL14: 6569 | DM14: 6569 | DN14: 6569 | DO14: 6569 | DP14: 6569 | DQ14: 6569 | DR14: 6569 | DS14: 6569 | DT14: 6569 | DU14: 6569 | DV14: 6569 | DW14: 6569 | DX14: 6569 | DY14: 6569 | DZ14: 6569 | EA14: 6569 | EB14: 6569 | EC14: 6569 | ED14: 6569
A15: 7. Trihydro Corporation | B15: 7 | C15: 3000 | D15: 3000 | E15: 3000 | F15: 3000 | G15: 3000 | H15: 3000 | I15: 3000 | J15: 3000 | K15: 3000 | L15: 3000 | M15: 3000 | N15: 3000 | O15: 3000 | P15: 3000 | Q15: 3000 | R15: 3000 | S15: 3000 | T15: 3000 | U15: 0 | V15: 0 | W15: 0 | X15: 0 | Y15: 0 | Z15: 0 | AA15: 3019 | AB15: 3019 | AC15: 3019 | AD15: 3019 | AE15: 3019 | AF15: 3019 | AG15: 3019 | AH15: 3019 | AI15: 3019 | AJ15: 3019 | AK15: 3019 | AL15: 3019 | AM15: 3019 | AN15: 3019 | AO15: 3019 | AP15: 3019 | AQ15: 3019 | AR15: 3019 | AS15: 3019 | AT15: 3019 | AU15: 3019 | AV15: 3019 | AW15: 3019 | AX15: 3019 | AY15: 3019 | AZ15: 3019 | BA15: 3019 | BB15: 3019 | BC15: 3019 | BD15: 3019 | BE15: 3019 | BF15: 3019 | BG15: 3019 | BH15: 3019 | BI15: 3019 | BJ15: 3019 | BK15: 3019 | BL15: 3019 | BM15: 3019 | BN15: 3019 | BO15: 3019 | BP15: 3019 | BQ15: 3019 | BR15: 3019 | BS15: 3019 | BT15: 3019 | BU15: 3019 | BV15: 3019 | BW15: 3019 | BX15: 3019 | BY15: 3019 | BZ15: 3019 | CA15: 3019 | CB15: 3019 | CC15: 3019 | CD15: 3019 | CE15: 3019 | CF15: 3019 | CG15: 3019 | CH15: 3019 | CI15: 3019 | CJ15: 3019 | CK15: 3019 | CL15: 0 | CM15: 0 | CN15: 3019 | CO15: 3019 | CP15: 3019 | CQ15: 3019 | CR15: 3019 | CS15: 3019 | CT15: 3019 | CU15: 3019 | CV15: 3019 | CW15: 3019 | CX15: 3019 | CY15: 3019 | CZ15: 3019 | DA15: 3019 | DB15: 3019 | DC15: 3019 | DD15: 3019 | DE15: 3019 | DF15: 3019 | DG15: 3019 | DH15: 3019 | DI15: 3019 | DJ15: 3019 | DK15: 3019 | DL15: 3019 | DM15: 3019 | DN15: 3019 | DO15: 3019 | DP15: 3019 | DQ15: 3019 | DR15: 3019 | DS15: 3019 | DT15: 3019 | DU15: 3019 | DV15: 3019 | DW15: 3019 | DX15: 3019 | DY15: 3019 | DZ15: 3019 | EA15: 3019 | EB15: 3019 | EC15: 3019 | ED15: 3019
A16: 8. Urban ATX | B16: 07A | C16: 1500 | D16: 1500 | E16: 1500 | F16: 1500 | G16: 1500 | H16: 1500 | I16: 1500 | J16: 1500 | K16: 1500 | L16: 1500 | M16: 1500 | N16: 1500 | O16: 1500 | P16: 1500 | Q16: 1500 | R16: 1500 | S16: 1500 | T16: 1500 | U16: 1500 | V16: 1500 | W16: 1500 | X16: 1500 | Y16: 1500 | Z16: 1500 | AA16: 1500 | AB16: 1500 | AC16: 1500 | AD16: 1500 | AE16: 1500 | AF16: 1500 | AG16: 1500 | AH16: 1500 | AI16: 1500 | AJ16: 1500 | AK16: 1500 | AL16: 1500 | AM16: 1500 | AN16: 1500 | AO16: 1500 | AP16: 1500 | AQ16: 1500 | AR16: 1500 | AS16: 1500 | AT16: 1500 | AU16: 1500 | AV16: 1500 | AW16: 1500 | AX16: 1500 | AY16: 1500 | AZ16: 1500 | BA16: 1500 | BB16: 1500 | BC16: 1500 | BD16: 1500 | BE16: 1500 | BF16: 1500 | BG16: 1500 | BH16: 0 | BI16: 0 | BJ16: 1514 | BK16: 1514 | BL16: 1514 | BM16: 1514 | BN16: 1514 | BO16: 1514 | BP16: 1514 | BQ16: 1514 | BR16: 1514 | BS16: 1514 | BT16: 1514 | BU16: 1514 | BV16: 1514 | BW16: 1514 | BX16: 1514 | BY16: 1514 | BZ16: 1514 | CA16: 1514 | CB16: 1514 | CC16: 1514 | CD16: 1514 | CE16: 1514 | CF16: 1514 | CG16: 1514 | CH16: 1514 | CI16: 1514 | CJ16: 1514 | CK16: 1514 | CL16: 1514 | CM16: 1514 | CN16: 1514 | CO16: 1514 | CP16: 1514 | CQ16: 1514 | CR16: 1514 | CS16: 1514 | CT16: 1514 | CU16: 1514 | CV16: 1514 | CW16: 1514 | CX16: 1514 | CY16: 1514 | CZ16: 1514 | DA16: 1514 | DB16: 1514 | DC16: 1514 | DD16: 1514 | DE16: 1514 | DF16: 1514 | DG16: 1514 | DH16: 1514 | DI16: 1514 | DJ16: 1514 | DK16: 1514 | DL16: 1514 | DM16: 1514 | DN16: 1514 | DO16: 1514 | DP16: 1514 | DQ16: 1514 | DR16: 1514 | DS16: 1514 | DT16: 1514 | DU16: 0 | DV16: 0 | DW16: 1514 | DX16: 1514 | DY16: 1514 | DZ16: 1514 | EA16: 1514 | EB16: 1514 | EC16: 1514 | ED16: 1514
A17: 9. Brinkley Sargent Winginton Architects | B17: 8 | C17: 3000 | D17: 3000 | E17: 3000 | F17: 3000 | G17: 3000 | H17: 3000 | I17: 3000 | J17: 3000 | K17: 3000 | L17: 3000 | M17: 3000 | N17: 3000 | O17: 3000 | P17: 3029 | Q17: 3029 | R17: 3029 | S17: 3029 | T17: 3029 | U17: 3029 | V17: 3029 | W17: 3029 | X17: 3029 | Y17: 3029 | Z17: 3029 | AA17: 3029 | AB17: 3029 | AC17: 3029 | AD17: 3029 | AE17: 3029 | AF17: 3029 | AG17: 3029 | AH17: 3029 | AI17: 3029 | AJ17: 3029 | AK17: 3029 | AL17: 3029 | AM17: 3029 | AN17: 3029 | AO17: 3029 | AP17: 3029 | AQ17: 3029 | AR17: 3029 | AS17: 3029 | AT17: 3029 | AU17: 3029 | AV17: 3029 | AW17: 3029 | AX17: 3029 | AY17: 3029 | AZ17: 3029 | BA17: 3029 | BB17: 3029 | BC17: 3029 | BD17: 3029 | BE17: 3029 | BF17: 3029 | BG17: 3029 | BH17: 3029 | BI17: 3029 | BJ17: 3029 | BK17: 3029 | BL17: 3029 | BM17: 3029 | BN17: 3029 | BO17: 3029 | BP17: 3029 | BQ17: 3029 | BR17: 3029 | BS17: 3029 | BT17: 3029 | BU17: 3029 | BV17: 3029 | BW17: 3029 | BX17: 3029 | BY17: 3029 | BZ17: 3029 | CA17: 3029 | CB17: 3029 | CC17: 3029 | CD17: 3029 | CE17: 3029 | CF17: 3029 | CG17: 3029 | CH17: 3029 | CI17: 3029 | CJ17: 3029 | CK17: 3029 | CL17: 3029 | CM17: 3029 | CN17: 3029 | CO17: 3029 | CP17: 3029 | CQ17: 3029 | CR17: 3029 | CS17: 3029 | CT17: 3029 | CU17: 3029 | CV17: 3029 | CW17: 3029 | CX17: 3029 | CY17: 3029 | CZ17: 3029 | DA17: 3029 | DB17: 3029 | DC17: 3029 | DD17: 3029 | DE17: 3029 | DF17: 3029 | DG17: 3029 | DH17: 3029 | DI17: 3029 | DJ17: 3029 | DK17: 3029 | DL17: 3029 | DM17: 3029 | DN17: 3029 | DO17: 3029 | DP17: 3029 | DQ17: 3029 | DR17: 3029 | DS17: 3029 | DT17: 3029 | DU17: 3029 | DV17: 3029 | DW17: 3029 | DX17: 3029 | DY17: 3029 | DZ17: 3029 | EA17: 3029 | EB17: 3029 | EC17: 3029 | ED17: 3029
A18: 10. Austin Prosthetics Center | B18: 9 | C18: 4000 | D18: 4000 | E18: 4000 | F18: 4000 | G18: 4000 | H18: 4000 | I18: 4000 | J18: 4000 | K18: 4000 | L18: 4000 | M18: 4000 | N18: 4000 | O18: 4000 | P18: 4000 | Q18: 4000 | R18: 4000 | S18: 4000 | T18: 4000 | U18: 4000 | V18: 4000 | W18: 4000 | X18: 4000 | Y18: 4000 | Z18: 4000 | AA18: 4000 | AB18: 4000 | AC18: 4000 | AD18: 4000 | AE18: 4000 | AF18: 4000 | AG18: 4000 | AH18: 4000 | AI18: 4000 | AJ18: 4000 | AK18: 4000 | AL18: 4000 | AM18: 4000 | AN18: 4000 | AO18: 4000 | AP18: 4000 | AQ18: 4000 | AR18: 4000 | AS18: 4000 | AT18: 4000 | AU18: 4000 | AV18: 4000 | AW18: 4000 | AX18: 4000 | AY18: 4000 | AZ18: 4000 | BA18: 4000 | BB18: 4000 | BC18: 4000 | BD18: 4000 | BE18: 4000 | BF18: 4000 | BG18: 4000 | BH18: 4000 | BI18: 4000 | BJ18: 4000 | BK18: 4000 | BL18: 4000 | BM18: 4000 | BN18: 4000 | BO18: 4000 | BP18: 4000 | BQ18: 4000 | BR18: 4000 | BS18: 0 | BT18: 0 | BU18: 4205 | BV18: 4205 | BW18: 4205 | BX18: 4205 | BY18: 4205 | BZ18: 4205 | CA18: 4205 | CB18: 4205 | CC18: 4205 | CD18: 4205 | CE18: 4205 | CF18: 4205 | CG18: 4205 | CH18: 4205 | CI18: 4205 | CJ18: 4205 | CK18: 4205 | CL18: 4205 | CM18: 4205 | CN18: 4205 | CO18: 4205 | CP18: 4205 | CQ18: 4205 | CR18: 4205 | CS18: 4205 | CT18: 4205 | CU18: 4205 | CV18: 4205 | CW18: 4205 | CX18: 4205 | CY18: 4205 | CZ18: 4205 | DA18: 4205 | DB18: 4205 | DC18: 4205 | DD18: 4205 | DE18: 4205 | DF18: 4205 | DG18: 4205 | DH18: 4205 | DI18: 4205 | DJ18: 4205 | DK18: 4205 | DL18: 4205 | DM18: 4205 | DN18: 4205 | DO18: 4205 | DP18: 4205 | DQ18: 4205 | DR18: 4205 | DS18: 4205 | DT18: 4205 | DU18: 4205 | DV18: 4205 | DW18: 4205 | DX18: 4205 | DY18: 4205 | DZ18: 4205 | EA18: 4205 | EB18: 4205 | EC18: 4205 | ED18: 4205
A19: 11. Ignite Fitnez | B19: 10 | C19: 11815 | D19: 11815 | E19: 11815 | F19: 0 | G19: 0 | H19: 0 | I19: 0 | J19: 0 | K19: 0 | L19: 0 | M19: 0 | N19: 0 | O19: 0 | P19: 0 | Q19: 0 | R19: 11815 | S19: 11815 | T19: 11815 | U19: 11815 | V19: 11815 | W19: 11815 | X19: 11815 | Y19: 11815 | Z19: 11815 | AA19: 11815 | AB19: 11815 | AC19: 11815 | AD19: 11815 | AE19: 11815 | AF19: 11815 | AG19: 11815 | AH19: 11815 | AI19: 11815 | AJ19: 11815 | AK19: 11815 | AL19: 11815 | AM19: 11815 | AN19: 11815 | AO19: 11815 | AP19: 11815 | AQ19: 11815 | AR19: 11815 | AS19: 11815 | AT19: 11815 | AU19: 11815 | AV19: 11815 | AW19: 11815 | AX19: 11815 | AY19: 11815 | AZ19: 11815 | BA19: 11815 | BB19: 11815 | BC19: 11815 | BD19: 11815 | BE19: 11815 | BF19: 11815 | BG19: 11815 | BH19: 11815 | BI19: 11815 | BJ19: 11815 | BK19: 11815 | BL19: 11815 | BM19: 11815 | BN19: 11815 | BO19: 11815 | BP19: 11815 | BQ19: 11815 | BR19: 11815 | BS19: 11815 | BT19: 11815 | BU19: 11815 | BV19: 11815 | BW19: 11815 | BX19: 11815 | BY19: 11815 | BZ19: 11815 | CA19: 11815 | CB19: 11815 | CC19: 11815 | CD19: 11815 | CE19: 11815 | CF19: 11815 | CG19: 11815 | CH19: 11815 | CI19: 11815 | CJ19: 11815 | CK19: 11815 | CL19: 11815 | CM19: 11815 | CN19: 11815 | CO19: 11815 | CP19: 11815 | CQ19: 11815 | CR19: 11815 | CS19: 11815 | CT19: 11815 | CU19: 11815 | CV19: 11815 | CW19: 11815 | CX19: 11815 | CY19: 11815 | CZ19: 11815 | DA19: 11815 | DB19: 11815 | DC19: 0 | DD19: 0 | DE19: 0 | DF19: 0 | DG19: 11815 | DH19: 11815 | DI19: 11815 | DJ19: 11815 | DK19: 11815 | DL19: 11815 | DM19: 11815 | DN19: 11815 | DO19: 11815 | DP19: 11815 | DQ19: 11815 | DR19: 11815 | DS19: 11815 | DT19: 11815 | DU19: 11815 | DV19: 11815 | DW19: 11815 | DX19: 11815 | DY19: 11815 | DZ19: 11815 | EA19: 11815 | EB19: 11815 | EC19: 11815 | ED19: 11815
A20: Total Area | C20: 52969 | D20: 52969 | E20: 52969 | F20: 41154 | G20: 41154 | H20: 41154 | I20: 41154 | J20: 44110 | K20: 44110 | L20: 44110 | M20: 44110 | N20: 44110 | O20: 44110 | P20: 50196 | Q20: 50196 | R20: 62011 | S20: 62011 | T20: 62011 | U20: 59011 | V20: 56011 | W20: 56011 | X20: 59154 | Y20: 59154 | Z20: 59154 | AA20: 62173 | AB20: 62173 | AC20: 62173 | AD20: 56173 | AE20: 56173 | AF20: 62182 | AG20: 62182 | AH20: 62182 | AI20: 62182 | AJ20: 62182 | AK20: 62182 | AL20: 62182 | AM20: 62182 | AN20: 62182 | AO20: 62182 | AP20: 62182 | AQ20: 62182 | AR20: 62182 | AS20: 62182 | AT20: 62182 | AU20: 62182 | AV20: 62182 | AW20: 62182 | AX20: 62182 | AY20: 62182 | AZ20: 62182 | BA20: 62182 | BB20: 62182 | BC20: 62182 | BD20: 62182 | BE20: 62182 | BF20: 62182 | BG20: 62182 | BH20: 60682 | BI20: 60682 | BJ20: 62196 | BK20: 54111 | BL20: 54111 | BM20: 62196 | BN20: 62196 | BO20: 62196 | BP20: 62196 | BQ20: 62196 | BR20: 62196 | BS20: 58196 | BT20: 58196 | BU20: 53445 | BV20: 53445 | BW20: 62401 | BX20: 62401 | BY20: 62401 | BZ20: 62401 | CA20: 56344 | CB20: 56344 | CC20: 62401 | CD20: 62401 | CE20: 62401 | CF20: 62401 | CG20: 62401 | CH20: 62401 | CI20: 52689 | CJ20: 52689 | CK20: 62401 | CL20: 59382 | CM20: 59382 | CN20: 62401 | CO20: 62401 | CP20: 62401 | CQ20: 56392 | CR20: 56392 | CS20: 62401 | CT20: 62401 | CU20: 62401 | CV20: 62401 | CW20: 62401 | CX20: 62401 | CY20: 62401 | CZ20: 62401 | DA20: 62401 | DB20: 62401 | DC20: 50586 | DD20: 50586 | DE20: 50586 | DF20: 50586 | DG20: 62401 | DH20: 62401 | DI20: 62401 | DJ20: 62401 | DK20: 62401 | DL20: 62401 | DM20: 62401 | DN20: 62401 | DO20: 62401 | DP20: 62401 | DQ20: 62401 | DR20: 62401 | DS20: 62401 | DT20: 62401 | DU20: 60887 | DV20: 60887 | DW20: 62401 | DX20: 54316 | DY20: 54316 | DZ20: 62401 | EA20: 62401 | EB20: 62401 | EC20: 62401 | ED20: 62401
A22: Total Occupancy % | C22: 0.85537344 | D22: 0.85537344 | E22: 0.85537344 | F22: 0.66457812 | G22: 0.66457812 | H22: 0.66457812 | I22: 0.66457812 | J22: 0.71165822 | K22: 0.71165822 | L22: 0.71165822 | M22: 0.71165822 | N22: 0.71165822 | O22: 0.71165822 | P22: 0.80946929 | Q22: 0.80946929 | R22: 1 | S22: 1 | T22: 1 | U22: 0.95133 | V22: 0.90088945 | W22: 0.90088945 | X22: 0.95144194 | Y22: 0.95144194 | Z22: 0.95144194 | AA22: 1 | AB22: 1 | AC22: 1 | AD22: 0.90336432 | AE22: 0.90336432 | AF22: 1 | AG22: 1 | AH22: 1 | AI22: 1 | AJ22: 1 | AK22: 1 | AL22: 1 | AM22: 1 | AN22: 1 | AO22: 1 | AP22: 1 | AQ22: 1 | AR22: 1 | AS22: 1 | AT22: 1 | AU22: 1 | AV22: 1 | AW22: 1 | AX22: 1 | AY22: 1 | AZ22: 1 | BA22: 1 | BB22: 1 | BC22: 1 | BD22: 1 | BE22: 1 | BF22: 1 | BG22: 1 | BH22: 0.9756576 | BI22: 0.9756576 | BJ22: 1 | BK22: 0.87000772 | BL22: 0.87000772 | BM22: 1 | BN22: 1 | BO22: 1 | BP22: 1 | BQ22: 1 | BR22: 1 | BS22: 0.93261326 | BT22: 0.93261326 | BU22: 0.85647666 | BV22: 0.85647666 | BW22: 1 | BX22: 1 | BY22: 1 | BZ22: 1 | CA22: 0.90293425 | CB22: 0.90293425 | CC22: 1 | CD22: 1 | CE22: 1 | CF22: 1 | CG22: 1 | CH22: 1 | CI22: 0.84436147 | CJ22: 0.84436147 | CK22: 1 | CL22: 0.95161937 | CM22: 0.95161937 | CN22: 1 | CO22: 1 | CP22: 1 | CQ22: 0.90370347 | CR22: 0.90370347 | CS22: 1 | CT22: 1 | CU22: 1 | CV22: 1 | CW22: 1 | CX22: 1 | CY22: 1 | CZ22: 1 | DA22: 1 | DB22: 1 | DC22: 0.81066009 | DD22: 0.81066009 | DE22: 0.81066009 | DF22: 0.81066009 | DG22: 1 | DH22: 1 | DI22: 1 | DJ22: 1 | DK22: 1 | DL22: 1 | DM22: 1 | DN22: 1 | DO22: 1 | DP22: 1 | DQ22: 1 | DR22: 1 | DS22: 1 | DT22: 1 | DU22: 0.97573757 | DV22: 0.97573757 | DW22: 1 | DX22: 0.87043477 | DY22: 0.87043477 | DZ22: 1 | EA22: 1 | EB22: 1 | EC22: 1 | ED22: 1
A24: Potential Base Rent
A25: 1. Kitu Life, Inc. | B25: 1 | C25: 18191 | D25: 18191 | E25: 18191 | F25: 18191 | G25: 18191 | H25: 18191 | I25: 18191 | J25: 18191 | K25: 18692 | L25: 18692 | M25: 18692 | N25: 18692 | O25: 18692 | P25: 18692 | Q25: 18692 | R25: 18692 | S25: 18692 | T25: 18692 | U25: 18692 | V25: 18692 | W25: 19206 | X25: 19206 | Y25: 19206 | Z25: 19206 | AA25: 19206 | AB25: 19206 | AC25: 19206 | AD25: 19206 | AE25: 19206 | AF25: 19206 | AG25: 19206 | AH25: 19206 | AI25: 19734 | AJ25: 19734 | AK25: 19734 | AL25: 19734 | AM25: 19734 | AN25: 19734 | AO25: 19734 | AP25: 19734 | AQ25: 19734 | AR25: 19734 | AS25: 19734 | AT25: 19734 | AU25: 20276 | AV25: 20276 | AW25: 20276 | AX25: 20276 | AY25: 20276 | AZ25: 20276 | BA25: 20276 | BB25: 20276 | BC25: 20276 | BD25: 20276 | BE25: 20276 | BF25: 20276 | BG25: 20834 | BH25: 20834 | BI25: 20834 | BJ25: 20834 | BK25: 22651 | BL25: 22651 | BM25: 22651 | BN25: 22651 | BO25: 22651 | BP25: 22651 | BQ25: 22651 | BR25: 22651 | BS25: 22651 | BT25: 22651 | BU25: 22651 | BV25: 22651 | BW25: 22651 | BX25: 22651 | BY25: 23330 | BZ25: 23330 | CA25: 23330 | CB25: 23330 | CC25: 23330 | CD25: 23330 | CE25: 23330 | CF25: 23330 | CG25: 23330 | CH25: 23330 | CI25: 23330 | CJ25: 23330 | CK25: 24030 | CL25: 24030 | CM25: 24030 | CN25: 24030 | CO25: 24030 | CP25: 24030 | CQ25: 24030 | CR25: 24030 | CS25: 24030 | CT25: 24030 | CU25: 24030 | CV25: 24030 | CW25: 24751 | CX25: 24751 | CY25: 24751 | CZ25: 24751 | DA25: 24751 | DB25: 24751 | DC25: 24751 | DD25: 24751 | DE25: 24751 | DF25: 24751 | DG25: 24751 | DH25: 24751 | DI25: 25494 | DJ25: 25494 | DK25: 25494 | DL25: 25494 | DM25: 25494 | DN25: 25494 | DO25: 25494 | DP25: 25494 | DQ25: 25494 | DR25: 25494 | DS25: 25494 | DT25: 25494 | DU25: 26258 | DV25: 26258 | DW25: 26258 | DX25: 26258 | DY25: 26258 | DZ25: 26258 | EA25: 26258 | EB25: 26258 | EC25: 26258 | ED25: 26258 | EE25: 2914709
A26: 2. VACANT | B26: 2 | C26: 21644 | D26: 21644 | E26: 21644 | F26: 21644 | G26: 21644 | H26: 21644 | I26: 21644 | J26: 21644 | K26: 21644 | L26: 21644 | M26: 21644 | N26: 21644 | O26: 21644 | P26: 21644 | Q26: 21644 | R26: 21644 | S26: 21644 | T26: 21644 | U26: 21644 | V26: 22293 | W26: 22293 | X26: 22293 | Y26: 22293 | Z26: 22293 | AA26: 22293 | AB26: 22293 | AC26: 22293 | AD26: 22293 | AE26: 22293 | AF26: 22293 | AG26: 22293 | AH26: 22962 | AI26: 22962 | AJ26: 22962 | AK26: 22962 | AL26: 22962 | AM26: 22962 | AN26: 22962 | AO26: 22962 | AP26: 22962 | AQ26: 22962 | AR26: 22962 | AS26: 22962 | AT26: 23651 | AU26: 23651 | AV26: 23651 | AW26: 23651 | AX26: 23651 | AY26: 23651 | AZ26: 23651 | BA26: 23651 | BB26: 23651 | BC26: 23651 | BD26: 23651 | BE26: 23651 | BF26: 24360 | BG26: 24360 | BH26: 24360 | BI26: 24360 | BJ26: 24360 | BK26: 24360 | BL26: 24360 | BM26: 24360 | BN26: 24360 | BO26: 24360 | BP26: 24360 | BQ26: 24360 | BR26: 25091 | BS26: 25091 | BT26: 25091 | BU26: 25091 | BV26: 25091 | BW26: 25844 | BX26: 25844 | BY26: 25844 | BZ26: 25844 | CA26: 25844 | CB26: 25844 | CC26: 25844 | CD26: 25844 | CE26: 25844 | CF26: 25844 | CG26: 25844 | CH26: 25844 | CI26: 26619 | CJ26: 26619 | CK26: 26619 | CL26: 26619 | CM26: 26619 | CN26: 26619 | CO26: 26619 | CP26: 26619 | CQ26: 26619 | CR26: 26619 | CS26: 26619 | CT26: 26619 | CU26: 27418 | CV26: 27418 | CW26: 27418 | CX26: 27418 | CY26: 27418 | CZ26: 27418 | DA26: 27418 | DB26: 27418 | DC26: 27418 | DD26: 27418 | DE26: 27418 | DF26: 27418 | DG26: 28240 | DH26: 28240 | DI26: 28240 | DJ26: 28240 | DK26: 28240 | DL26: 28240 | DM26: 28240 | DN26: 28240 | DO26: 28240 | DP26: 28240 | DQ26: 28240 | DR26: 28240 | DS26: 29087 | DT26: 29087 | DU26: 29087 | DV26: 29087 | DW26: 29087 | DX26: 29087 | DY26: 29087 | DZ26: 29087 | EA26: 29087 | EB26: 29087 | EC26: 29087 | ED26: 29087 | EE26: 3302361
A27: 3. Saatva | B27: 3 | C27: 12208 | D27: 12208 | E27: 12208 | F27: 10750 | G27: 10750 | H27: 10750 | I27: 10750 | J27: 10750 | K27: 10750 | L27: 10750 | M27: 10750 | N27: 10750 | O27: 10750 | P27: 10750 | Q27: 10750 | R27: 13500 | S27: 13500 | T27: 13500 | U27: 13500 | V27: 13500 | W27: 13500 | X27: 13500 | Y27: 13500 | Z27: 13500 | AA27: 13500 | AB27: 13500 | AC27: 13500 | AD27: 15406 | AE27: 15406 | AF27: 15406 | AG27: 15406 | AH27: 15406 | AI27: 15406 | AJ27: 15406 | AK27: 15406 | AL27: 15406 | AM27: 15406 | AN27: 15406 | AO27: 15406 | AP27: 15406 | AQ27: 15406 | AR27: 15868 | AS27: 15868 | AT27: 15868 | AU27: 15868 | AV27: 15868 | AW27: 15868 | AX27: 15868 | AY27: 15868 | AZ27: 15868 | BA27: 15868 | BB27: 15868 | BC27: 15868 | BD27: 16344 | BE27: 16344 | BF27: 16344 | BG27: 16344 | BH27: 16344 | BI27: 16344 | BJ27: 16344 | BK27: 16344 | BL27: 16344 | BM27: 16344 | BN27: 16344 | BO27: 16344 | BP27: 16835 | BQ27: 16835 | BR27: 16835 | BS27: 16835 | BT27: 16835 | BU27: 16835 | BV27: 16835 | BW27: 16835 | BX27: 16835 | BY27: 16835 | BZ27: 16835 | CA27: 16835 | CB27: 17340 | CC27: 17340 | CD27: 17340 | CE27: 17340 | CF27: 17340 | CG27: 17340 | CH27: 17340 | CI27: 17340 | CJ27: 17340 | CK27: 17340 | CL27: 17340 | CM27: 17340 | CN27: 17860 | CO27: 17860 | CP27: 17860 | CQ27: 17860 | CR27: 17860 | CS27: 17860 | CT27: 17860 | CU27: 17860 | CV27: 17860 | CW27: 17860 | CX27: 17860 | CY27: 17860 | CZ27: 17860 | DA27: 17860 | DB27: 17860 | DC27: 17860 | DD27: 17860 | DE27: 18396 | DF27: 18396 | DG27: 18396 | DH27: 18396 | DI27: 18396 | DJ27: 18396 | DK27: 18396 | DL27: 18396 | DM27: 18396 | DN27: 18396 | DO27: 18396 | DP27: 18396 | DQ27: 18948 | DR27: 18948 | DS27: 18948 | DT27: 18948 | DU27: 18948 | DV27: 18948 | DW27: 18948 | DX27: 18948 | DY27: 18948 | DZ27: 18948 | EA27: 18948 | EB27: 18948 | EC27: 19516 | ED27: 19516 | EE27: 2130726
A28: 4. Fuse Architecture Studio | B28: 4 | C28: 6010 | D28: 6010 | E28: 6010 | F28: 6010 | G28: 6010 | H28: 6010 | I28: 6010 | J28: 6190 | K28: 6190 | L28: 6190 | M28: 6190 | N28: 6190 | O28: 6190 | P28: 6190 | Q28: 6190 | R28: 6190 | S28: 6190 | T28: 6190 | U28: 6190 | V28: 7823 | W28: 7823 | X28: 7823 | Y28: 7823 | Z28: 7823 | AA28: 7823 | AB28: 7823 | AC28: 7823 | AD28: 7823 | AE28: 7823 | AF28: 7823 | AG28: 7823 | AH28: 7823 | AI28: 7823 | AJ28: 8058 | AK28: 8058 | AL28: 8058 | AM28: 8058 | AN28: 8058 | AO28: 8058 | AP28: 8058 | AQ28: 8058 | AR28: 8058 | AS28: 8058 | AT28: 8058 | AU28: 8058 | AV28: 8300 | AW28: 8300 | AX28: 8300 | AY28: 8300 | AZ28: 8300 | BA28: 8300 | BB28: 8300 | BC28: 8300 | BD28: 8300 | BE28: 8300 | BF28: 8300 | BG28: 8300 | BH28: 8549 | BI28: 8549 | BJ28: 8549 | BK28: 8549 | BL28: 8549 | BM28: 8549 | BN28: 8549 | BO28: 8549 | BP28: 8549 | BQ28: 8549 | BR28: 8549 | BS28: 8549 | BT28: 8805 | BU28: 8805 | BV28: 8805 | BW28: 8805 | BX28: 8805 | BY28: 8805 | BZ28: 8805 | CA28: 8805 | CB28: 8805 | CC28: 8805 | CD28: 8805 | CE28: 8805 | CF28: 9070 | CG28: 9070 | CH28: 9070 | CI28: 9342 | CJ28: 9342 | CK28: 9342 | CL28: 9342 | CM28: 9342 | CN28: 9342 | CO28: 9342 | CP28: 9342 | CQ28: 9342 | CR28: 9342 | CS28: 9342 | CT28: 9342 | CU28: 9342 | CV28: 9342 | CW28: 9622 | CX28: 9622 | CY28: 9622 | CZ28: 9622 | DA28: 9622 | DB28: 9622 | DC28: 9622 | DD28: 9622 | DE28: 9622 | DF28: 9622 | DG28: 9622 | DH28: 9622 | DI28: 9911 | DJ28: 9911 | DK28: 9911 | DL28: 9911 | DM28: 9911 | DN28: 9911 | DO28: 9911 | DP28: 9911 | DQ28: 9911 | DR28: 9911 | DS28: 9911 | DT28: 9911 | DU28: 10208 | DV28: 10208 | DW28: 10208 | DX28: 10208 | DY28: 10208 | DZ28: 10208 | EA28: 10208 | EB28: 10208 | EC28: 10208 | ED28: 10208 | EE28: 1124884
A29: 5. Made In (sublessee to Geek Powered Studios) | B29: 5 | C29: 9850 | D29: 9850 | E29: 9850 | F29: 9850 | G29: 9850 | H29: 9850 | I29: 9850 | J29: 14638 | K29: 14638 | L29: 14638 | M29: 14638 | N29: 14638 | O29: 15077 | P29: 15077 | Q29: 15077 | R29: 15077 | S29: 15077 | T29: 15077 | U29: 15077 | V29: 15077 | W29: 15077 | X29: 15077 | Y29: 15077 | Z29: 15077 | AA29: 15077 | AB29: 15529 | AC29: 15529 | AD29: 15529 | AE29: 15529 | AF29: 15529 | AG29: 15529 | AH29: 15529 | AI29: 15529 | AJ29: 15529 | AK29: 15529 | AL29: 15529 | AM29: 15529 | AN29: 15995 | AO29: 15995 | AP29: 15995 | AQ29: 15995 | AR29: 15995 | AS29: 15995 | AT29: 15995 | AU29: 15995 | AV29: 15995 | AW29: 15995 | AX29: 15995 | AY29: 15995 | AZ29: 16475 | BA29: 16475 | BB29: 16475 | BC29: 16475 | BD29: 16475 | BE29: 16475 | BF29: 16475 | BG29: 16475 | BH29: 16475 | BI29: 16475 | BJ29: 16475 | BK29: 16475 | BL29: 16969 | BM29: 16969 | BN29: 16969 | BO29: 16969 | BP29: 16969 | BQ29: 16969 | BR29: 16969 | BS29: 16969 | BT29: 16969 | BU29: 16969 | BV29: 16969 | BW29: 16969 | BX29: 17478 | BY29: 17478 | BZ29: 17478 | CA29: 17478 | CB29: 17478 | CC29: 17478 | CD29: 17478 | CE29: 17478 | CF29: 17478 | CG29: 17478 | CH29: 17478 | CI29: 17478 | CJ29: 17478 | CK29: 17478 | CL29: 17478 | CM29: 17478 | CN29: 17478 | CO29: 18003 | CP29: 18003 | CQ29: 18003 | CR29: 18003 | CS29: 18003 | CT29: 18003 | CU29: 18003 | CV29: 18003 | CW29: 18003 | CX29: 18003 | CY29: 18003 | CZ29: 18003 | DA29: 18543 | DB29: 18543 | DC29: 18543 | DD29: 18543 | DE29: 18543 | DF29: 18543 | DG29: 18543 | DH29: 18543 | DI29: 18543 | DJ29: 18543 | DK29: 18543 | DL29: 18543 | DM29: 19099 | DN29: 19099 | DO29: 19099 | DP29: 19099 | DQ29: 19099 | DR29: 19099 | DS29: 19099 | DT29: 19099 | DU29: 19099 | DV29: 19099 | DW29: 19099 | DX29: 19099 | DY29: 19672 | DZ29: 19672 | EA29: 19672 | EB29: 19672 | EC29: 19672 | ED29: 19672 | EE29: 2200650
A30: 6. Elmo 35, LLC | B30: 6 | C30: 15875 | D30: 15875 | E30: 15875 | F30: 15875 | G30: 15875 | H30: 15875 | I30: 15875 | J30: 15875 | K30: 15875 | L30: 15875 | M30: 15875 | N30: 15875 | O30: 16351 | P30: 16351 | Q30: 16351 | R30: 16351 | S30: 16351 | T30: 16351 | U30: 16351 | V30: 16351 | W30: 16351 | X30: 16351 | Y30: 16351 | Z30: 16351 | AA30: 16842 | AB30: 16842 | AC30: 16842 | AD30: 16842 | AE30: 16842 | AF30: 16842 | AG30: 16842 | AH30: 16842 | AI30: 16842 | AJ30: 16842 | AK30: 16842 | AL30: 16842 | AM30: 17347 | AN30: 17347 | AO30: 17347 | AP30: 17347 | AQ30: 17347 | AR30: 17347 | AS30: 17347 | AT30: 17347 | AU30: 17347 | AV30: 17347 | AW30: 17347 | AX30: 17347 | AY30: 17868 | AZ30: 17868 | BA30: 17868 | BB30: 17868 | BC30: 17868 | BD30: 17868 | BE30: 17868 | BF30: 17868 | BG30: 17868 | BH30: 17868 | BI30: 17868 | BJ30: 17868 | BK30: 18404 | BL30: 18404 | BM30: 18404 | BN30: 18404 | BO30: 18404 | BP30: 18404 | BQ30: 18404 | BR30: 18404 | BS30: 18404 | BT30: 18404 | BU30: 18404 | BV30: 18404 | BW30: 18956 | BX30: 18956 | BY30: 18956 | BZ30: 18956 | CA30: 18956 | CB30: 18956 | CC30: 18956 | CD30: 18956 | CE30: 18956 | CF30: 18956 | CG30: 18956 | CH30: 18956 | CI30: 19524 | CJ30: 19524 | CK30: 19524 | CL30: 19524 | CM30: 19524 | CN30: 19524 | CO30: 19524 | CP30: 19524 | CQ30: 19524 | CR30: 19524 | CS30: 19524 | CT30: 19524 | CU30: 19524 | CV30: 19524 | CW30: 20110 | CX30: 20110 | CY30: 20110 | CZ30: 20110 | DA30: 20110 | DB30: 20110 | DC30: 20110 | DD30: 20110 | DE30: 20110 | DF30: 20110 | DG30: 20110 | DH30: 20110 | DI30: 20713 | DJ30: 20713 | DK30: 20713 | DL30: 20713 | DM30: 20713 | DN30: 20713 | DO30: 20713 | DP30: 20713 | DQ30: 20713 | DR30: 20713 | DS30: 20713 | DT30: 20713 | DU30: 21335 | DV30: 21335 | DW30: 21335 | DX30: 21335 | DY30: 21335 | DZ30: 21335 | EA30: 21335 | EB30: 21335 | EC30: 21335 | ED30: 21335 | EE30: 2436277
A31: 7. Trihydro Corporation | B31: 7 | C31: 6010 | D31: 6010 | E31: 6010 | F31: 6010 | G31: 6010 | H31: 6010 | I31: 6190 | J31: 6190 | K31: 6190 | L31: 6190 | M31: 6190 | N31: 6190 | O31: 6190 | P31: 6190 | Q31: 6190 | R31: 6190 | S31: 6190 | T31: 6190 | U31: 7515 | V31: 7515 | W31: 7515 | X31: 7515 | Y31: 7515 | Z31: 7515 | AA31: 7740 | AB31: 7740 | AC31: 7740 | AD31: 7740 | AE31: 7740 | AF31: 7740 | AG31: 7740 | AH31: 7740 | AI31: 7740 | AJ31: 7740 | AK31: 7740 | AL31: 7740 | AM31: 7972 | AN31: 7972 | AO31: 7972 | AP31: 7972 | AQ31: 7972 | AR31: 7972 | AS31: 7972 | AT31: 7972 | AU31: 7972 | AV31: 7972 | AW31: 7972 | AX31: 7972 | AY31: 8212 | AZ31: 8212 | BA31: 8212 | BB31: 8212 | BC31: 8212 | BD31: 8212 | BE31: 8212 | BF31: 8212 | BG31: 8212 | BH31: 8212 | BI31: 8212 | BJ31: 8212 | BK31: 8458 | BL31: 8458 | BM31: 8458 | BN31: 8458 | BO31: 8458 | BP31: 8458 | BQ31: 8458 | BR31: 8458 | BS31: 8458 | BT31: 8458 | BU31: 8458 | BV31: 8458 | BW31: 8712 | BX31: 8712 | BY31: 8712 | BZ31: 8712 | CA31: 8712 | CB31: 8712 | CC31: 8712 | CD31: 8712 | CE31: 8712 | CF31: 8712 | CG31: 8712 | CH31: 8712 | CI31: 8973 | CJ31: 8973 | CK31: 8973 | CL31: 8973 | CM31: 8973 | CN31: 8973 | CO31: 8973 | CP31: 8973 | CQ31: 8973 | CR31: 8973 | CS31: 8973 | CT31: 8973 | CU31: 8973 | CV31: 8973 | CW31: 8973 | CX31: 8973 | CY31: 8973 | CZ31: 9242 | DA31: 9242 | DB31: 9242 | DC31: 9242 | DD31: 9242 | DE31: 9242 | DF31: 9242 | DG31: 9242 | DH31: 9242 | DI31: 9242 | DJ31: 9242 | DK31: 9242 | DL31: 9520 | DM31: 9520 | DN31: 9520 | DO31: 9520 | DP31: 9520 | DQ31: 9520 | DR31: 9520 | DS31: 9520 | DT31: 9520 | DU31: 9520 | DV31: 9520 | DW31: 9520 | DX31: 9805 | DY31: 9805 | DZ31: 9805 | EA31: 9805 | EB31: 9805 | EC31: 9805 | ED31: 9805 | EE31: 1094879
A32: 8. Urban ATX | B32: 07A | C32: 3252 | D32: 3252 | E32: 3252 | F32: 3252 | G32: 3252 | H32: 3252 | I32: 3252 | J32: 3350 | K32: 3350 | L32: 3350 | M32: 3350 | N32: 3350 | O32: 3350 | P32: 3350 | Q32: 3350 | R32: 3350 | S32: 3350 | T32: 3350 | U32: 3350 | V32: 3450 | W32: 3450 | X32: 3450 | Y32: 3450 | Z32: 3450 | AA32: 3450 | AB32: 3450 | AC32: 3450 | AD32: 3450 | AE32: 3450 | AF32: 3450 | AG32: 3450 | AH32: 3554 | AI32: 3554 | AJ32: 3554 | AK32: 3554 | AL32: 3554 | AM32: 3554 | AN32: 3554 | AO32: 3554 | AP32: 3554 | AQ32: 3554 | AR32: 3554 | AS32: 3554 | AT32: 3660 | AU32: 3660 | AV32: 3660 | AW32: 3660 | AX32: 3660 | AY32: 3660 | AZ32: 3660 | BA32: 3660 | BB32: 3660 | BC32: 3660 | BD32: 3660 | BE32: 3660 | BF32: 3660 | BG32: 3660 | BH32: 4118 | BI32: 4118 | BJ32: 4118 | BK32: 4118 | BL32: 4118 | BM32: 4118 | BN32: 4118 | BO32: 4118 | BP32: 4118 | BQ32: 4118 | BR32: 4118 | BS32: 4118 | BT32: 4118 | BU32: 4118 | BV32: 4242 | BW32: 4242 | BX32: 4242 | BY32: 4242 | BZ32: 4242 | CA32: 4242 | CB32: 4242 | CC32: 4242 | CD32: 4242 | CE32: 4242 | CF32: 4242 | CG32: 4242 | CH32: 4369 | CI32: 4369 | CJ32: 4369 | CK32: 4369 | CL32: 4369 | CM32: 4369 | CN32: 4369 | CO32: 4369 | CP32: 4369 | CQ32: 4369 | CR32: 4369 | CS32: 4369 | CT32: 4500 | CU32: 4500 | CV32: 4500 | CW32: 4500 | CX32: 4500 | CY32: 4500 | CZ32: 4500 | DA32: 4500 | DB32: 4500 | DC32: 4500 | DD32: 4500 | DE32: 4500 | DF32: 4635 | DG32: 4635 | DH32: 4635 | DI32: 4635 | DJ32: 4635 | DK32: 4635 | DL32: 4635 | DM32: 4635 | DN32: 4635 | DO32: 4635 | DP32: 4635 | DQ32: 4635 | DR32: 4774 | DS32: 4774 | DT32: 4774 | DU32: 4917 | DV32: 4917 | DW32: 4917 | DX32: 4917 | DY32: 4917 | DZ32: 4917 | EA32: 4917 | EB32: 4917 | EC32: 4917 | ED32: 4917 | EE32: 532343
A33: 9. Brinkley Sargent Winginton Architects | B33: 8 | C33: 5375 | D33: 5500 | E33: 5500 | F33: 5500 | G33: 5500 | H33: 5500 | I33: 5500 | J33: 5500 | K33: 5500 | L33: 5500 | M33: 5500 | N33: 5500 | O33: 5500 | P33: 6563 | Q33: 6563 | R33: 6563 | S33: 6563 | T33: 6563 | U33: 6563 | V33: 6563 | W33: 6563 | X33: 6563 | Y33: 6563 | Z33: 6563 | AA33: 6563 | AB33: 6760 | AC33: 6760 | AD33: 6760 | AE33: 6760 | AF33: 6760 | AG33: 6760 | AH33: 6760 | AI33: 6760 | AJ33: 6760 | AK33: 6760 | AL33: 6760 | AM33: 6760 | AN33: 6963 | AO33: 6963 | AP33: 6963 | AQ33: 6963 | AR33: 6963 | AS33: 6963 | AT33: 6963 | AU33: 6963 | AV33: 6963 | AW33: 6963 | AX33: 6963 | AY33: 6963 | AZ33: 7171 | BA33: 7171 | BB33: 7171 | BC33: 7171 | BD33: 7171 | BE33: 7171 | BF33: 7171 | BG33: 7171 | BH33: 7171 | BI33: 7171 | BJ33: 7171 | BK33: 7171 | BL33: 7387 | BM33: 7387 | BN33: 7387 | BO33: 7387 | BP33: 7387 | BQ33: 7387 | BR33: 7387 | BS33: 7387 | BT33: 7387 | BU33: 7387 | BV33: 7387 | BW33: 7387 | BX33: 7608 | BY33: 7608 | BZ33: 7608 | CA33: 7608 | CB33: 7608 | CC33: 7608 | CD33: 7608 | CE33: 7608 | CF33: 7608 | CG33: 7608 | CH33: 7608 | CI33: 7608 | CJ33: 7836 | CK33: 7836 | CL33: 7836 | CM33: 7836 | CN33: 7836 | CO33: 7836 | CP33: 7836 | CQ33: 7836 | CR33: 7836 | CS33: 7836 | CT33: 7836 | CU33: 7836 | CV33: 8071 | CW33: 8071 | CX33: 8071 | CY33: 8071 | CZ33: 8071 | DA33: 8071 | DB33: 8071 | DC33: 8071 | DD33: 8071 | DE33: 8071 | DF33: 8071 | DG33: 8071 | DH33: 8314 | DI33: 8314 | DJ33: 8314 | DK33: 8314 | DL33: 8314 | DM33: 8314 | DN33: 8314 | DO33: 8314 | DP33: 8314 | DQ33: 8314 | DR33: 8314 | DS33: 8314 | DT33: 8563 | DU33: 8563 | DV33: 8563 | DW33: 8563 | DX33: 8563 | DY33: 8563 | DZ33: 8563 | EA33: 8563 | EB33: 8563 | EC33: 8563 | ED33: 8563 | EE33: 965638
A34: 10. Austin Prosthetics Center | B34: 9 | C34: 7167 | D34: 7167 | E34: 7167 | F34: 7167 | G34: 7167 | H34: 7167 | I34: 7167 | J34: 7167 | K34: 7333 | L34: 7333 | M34: 7333 | N34: 7333 | O34: 7333 | P34: 7333 | Q34: 7333 | R34: 7333 | S34: 7333 | T34: 7333 | U34: 7333 | V34: 7333 | W34: 7500 | X34: 7500 | Y34: 7500 | Z34: 7500 | AA34: 7500 | AB34: 7500 | AC34: 7500 | AD34: 7500 | AE34: 7500 | AF34: 7500 | AG34: 7500 | AH34: 7500 | AI34: 7667 | AJ34: 7667 | AK34: 7667 | AL34: 7667 | AM34: 7667 | AN34: 7667 | AO34: 7667 | AP34: 7667 | AQ34: 7667 | AR34: 7667 | AS34: 7667 | AT34: 7667 | AU34: 7833 | AV34: 7833 | AW34: 7833 | AX34: 7833 | AY34: 7833 | AZ34: 7833 | BA34: 7833 | BB34: 7833 | BC34: 7833 | BD34: 7833 | BE34: 7833 | BF34: 7833 | BG34: 8000 | BH34: 8000 | BI34: 8000 | BJ34: 8000 | BK34: 8000 | BL34: 8000 | BM34: 8000 | BN34: 8000 | BO34: 8000 | BP34: 8000 | BQ34: 8000 | BR34: 8000 | BS34: 11781 | BT34: 11781 | BU34: 11781 | BV34: 11781 | BW34: 11781 | BX34: 11781 | BY34: 11781 | BZ34: 11781 | CA34: 11781 | CB34: 11781 | CC34: 11781 | CD34: 11781 | CE34: 11781 | CF34: 11781 | CG34: 12134 | CH34: 12134 | CI34: 12134 | CJ34: 12134 | CK34: 12134 | CL34: 12134 | CM34: 12134 | CN34: 12134 | CO34: 12134 | CP34: 12134 | CQ34: 12134 | CR34: 12134 | CS34: 12498 | CT34: 12498 | CU34: 12498 | CV34: 12498 | CW34: 12498 | CX34: 12498 | CY34: 12498 | CZ34: 12498 | DA34: 12498 | DB34: 12498 | DC34: 12498 | DD34: 12498 | DE34: 12873 | DF34: 12873 | DG34: 12873 | DH34: 12873 | DI34: 12873 | DJ34: 12873 | DK34: 12873 | DL34: 12873 | DM34: 12873 | DN34: 12873 | DO34: 12873 | DP34: 12873 | DQ34: 13259 | DR34: 13259 | DS34: 13259 | DT34: 13259 | DU34: 13259 | DV34: 13259 | DW34: 13259 | DX34: 13259 | DY34: 13259 | DZ34: 13259 | EA34: 13259 | EB34: 13259 | EC34: 13657 | ED34: 13657 | EE34: 1318749
A35: 11. Ignite Fitnez | B35: 10 | C35: 0 | D35: 0 | E35: 0 | F35: 28553 | G35: 28553 | H35: 28553 | I35: 28553 | J35: 28553 | K35: 28553 | L35: 28553 | M35: 28553 | N35: 28553 | O35: 29410 | P35: 29410 | Q35: 29410 | R35: 29410 | S35: 29410 | T35: 29410 | U35: 29410 | V35: 29410 | W35: 29410 | X35: 29410 | Y35: 29410 | Z35: 29410 | AA35: 29410 | AB35: 29410 | AC35: 29410 | AD35: 30292 | AE35: 30292 | AF35: 30292 | AG35: 30292 | AH35: 30292 | AI35: 30292 | AJ35: 30292 | AK35: 30292 | AL35: 30292 | AM35: 30292 | AN35: 30292 | AO35: 30292 | AP35: 31201 | AQ35: 31201 | AR35: 31201 | AS35: 31201 | AT35: 31201 | AU35: 31201 | AV35: 31201 | AW35: 31201 | AX35: 31201 | AY35: 31201 | AZ35: 31201 | BA35: 31201 | BB35: 32137 | BC35: 32137 | BD35: 32137 | BE35: 32137 | BF35: 32137 | BG35: 32137 | BH35: 32137 | BI35: 32137 | BJ35: 32137 | BK35: 32137 | BL35: 32137 | BM35: 32137 | BN35: 33101 | BO35: 33101 | BP35: 33101 | BQ35: 33101 | BR35: 33101 | BS35: 33101 | BT35: 33101 | BU35: 33101 | BV35: 33101 | BW35: 33101 | BX35: 33101 | BY35: 33101 | BZ35: 34094 | CA35: 34094 | CB35: 34094 | CC35: 34094 | CD35: 34094 | CE35: 34094 | CF35: 34094 | CG35: 34094 | CH35: 34094 | CI35: 34094 | CJ35: 34094 | CK35: 34094 | CL35: 35116 | CM35: 35116 | CN35: 35116 | CO35: 35116 | CP35: 35116 | CQ35: 35116 | CR35: 35116 | CS35: 35116 | CT35: 35116 | CU35: 35116 | CV35: 35116 | CW35: 35116 | CX35: 36170 | CY35: 36170 | CZ35: 36170 | DA35: 36170 | DB35: 36170 | DC35: 36170 | DD35: 36170 | DE35: 36170 | DF35: 36170 | DG35: 37255 | DH35: 37255 | DI35: 37255 | DJ35: 37255 | DK35: 37255 | DL35: 37255 | DM35: 37255 | DN35: 37255 | DO35: 37255 | DP35: 37255 | DQ35: 37255 | DR35: 37255 | DS35: 38373 | DT35: 38373 | DU35: 38373 | DV35: 38373 | DW35: 38373 | DX35: 38373 | DY35: 38373 | DZ35: 38373 | EA35: 38373 | EB35: 38373 | EC35: 38373 | ED35: 38373 | EE35: 4282459
A36: Total Potential Base Rent | C36: 105582 | D36: 105707 | E36: 105707 | F36: 132802 | G36: 132802 | H36: 132802 | I36: 132982 | J36: 138047 | K36: 138714 | L36: 138714 | M36: 138714 | N36: 138714 | O36: 140486 | P36: 141549 | Q36: 141549 | R36: 144299 | S36: 144299 | T36: 144299 | U36: 145624 | V36: 148007 | W36: 148688 | X36: 148688 | Y36: 148688 | Z36: 148688 | AA36: 149404 | AB36: 150053 | AC36: 150053 | AD36: 152841 | AE36: 152841 | AF36: 152841 | AG36: 152841 | AH36: 153613 | AI36: 154308 | AJ36: 154543 | AK36: 154543 | AL36: 154543 | AM36: 155280 | AN36: 155949 | AO36: 155949 | AP36: 156858 | AQ36: 156858 | AR36: 157320 | AS36: 157320 | AT36: 158115 | AU36: 158825 | AV36: 159067 | AW36: 159067 | AX36: 159067 | AY36: 159826 | AZ36: 160515 | BA36: 160515 | BB36: 161451 | BC36: 161451 | BD36: 161927 | BE36: 161927 | BF36: 162636 | BG36: 163361 | BH36: 164067 | BI36: 164067 | BJ36: 164067 | BK36: 166667 | BL36: 167376 | BM36: 167376 | BN36: 168340 | BO36: 168340 | BP36: 168830 | BQ36: 168830 | BR36: 169561 | BS36: 173342 | BT36: 173598 | BU36: 173598 | BV36: 173722 | BW36: 175280 | BX36: 176011 | BY36: 176691 | BZ36: 177684 | CA36: 177684 | CB36: 178189 | CC36: 178189 | CD36: 178189 | CE36: 178189 | CF36: 178453 | CG36: 178806 | CH36: 178934 | CI36: 180811 | CJ36: 181039 | CK36: 181739 | CL36: 182762 | CM36: 182762 | CN36: 183282 | CO36: 183806 | CP36: 183806 | CQ36: 183806 | CR36: 183806 | CS36: 184170 | CT36: 184302 | CU36: 185100 | CV36: 185335 | CW36: 186922 | CX36: 187976 | CY36: 187976 | CZ36: 188245 | DA36: 188785 | DB36: 188785 | DC36: 188785 | DD36: 188785 | DE36: 189696 | DF36: 189831 | DG36: 191738 | DH36: 191980 | DI36: 193615 | DJ36: 193615 | DK36: 193615 | DL36: 193892 | DM36: 194448 | DN36: 194448 | DO36: 194448 | DP36: 194448 | DQ36: 195386 | DR36: 195526 | DS36: 197490 | DT36: 197740 | DU36: 199567 | DV36: 199567 | DW36: 199567 | DX36: 199852 | DY36: 200425 | DZ36: 200425 | EA36: 200425 | EB36: 200425 | EC36: 201391 | ED36: 201391 | EE36: 22303675
A38: Lost Absorption / Turnover Rent
A39: 1. Kitu Life, Inc. | B39: 1 | C39: 0 | D39: 0 | E39: 0 | F39: 0 | G39: 0 | H39: 0 | I39: 0 | J39: 0 | K39: 0 | L39: 0 | M39: 0 | N39: 0 | O39: 0 | P39: 0 | Q39: 0 | R39: 0 | S39: 0 | T39: 0 | U39: 0 | V39: 0 | W39: 0 | X39: 0 | Y39: 0 | Z39: 0 | AA39: 0 | AB39: 0 | AC39: 0 | AD39: 0 | AE39: 0 | AF39: 0 | AG39: 0 | AH39: 0 | AI39: 0 | AJ39: 0 | AK39: 0 | AL39: 0 | AM39: 0 | AN39: 0 | AO39: 0 | AP39: 0 | AQ39: 0 | AR39: 0 | AS39: 0 | AT39: 0 | AU39: 0 | AV39: 0 | AW39: 0 | AX39: 0 | AY39: 0 | AZ39: 0 | BA39: 0 | BB39: 0 | BC39: 0 | BD39: 0 | BE39: 0 | BF39: 0 | BG39: 0 | BH39: 0 | BI39: 0 | BJ39: 0 | BK39: -22651 | BL39: -22651 | BM39: 0 | BN39: 0 | BO39: 0 | BP39: 0 | BQ39: 0 | BR39: 0 | BS39: 0 | BT39: 0 | BU39: 0 | BV39: 0 | BW39: 0 | BX39: 0 | BY39: 0 | BZ39: 0 | CA39: 0 | CB39: 0 | CC39: 0 | CD39: 0 | CE39: 0 | CF39: 0 | CG39: 0 | CH39: 0 | CI39: 0 | CJ39: 0 | CK39: 0 | CL39: 0 | CM39: 0 | CN39: 0 | CO39: 0 | CP39: 0 | CQ39: 0 | CR39: 0 | CS39: 0 | CT39: 0 | CU39: 0 | CV39: 0 | CW39: 0 | CX39: 0 | CY39: 0 | CZ39: 0 | DA39: 0 | DB39: 0 | DC39: 0 | DD39: 0 | DE39: 0 | DF39: 0 | DG39: 0 | DH39: 0 | DI39: 0 | DJ39: 0 | DK39: 0 | DL39: 0 | DM39: 0 | DN39: 0 | DO39: 0 | DP39: 0 | DQ39: 0 | DR39: 0 | DS39: 0 | DT39: 0 | DU39: 0 | DV39: 0 | DW39: 0 | DX39: -26258 | DY39: -26258 | DZ39: 0 | EA39: 0 | EB39: 0 | EC39: 0 | ED39: 0 | EE39: -97818
A40: 2. VACANT | B40: 2 | C40: -21644 | D40: -21644 | E40: -21644 | F40: -21644 | G40: -21644 | H40: -21644 | I40: -21644 | J40: 0 | K40: 0 | L40: 0 | M40: 0 | N40: 0 | O40: 0 | P40: 0 | Q40: 0 | R40: 0 | S40: 0 | T40: 0 | U40: 0 | V40: 0 | W40: 0 | X40: 0 | Y40: 0 | Z40: 0 | AA40: 0 | AB40: 0 | AC40: 0 | AD40: 0 | AE40: 0 | AF40: 0 | AG40: 0 | AH40: 0 | AI40: 0 | AJ40: 0 | AK40: 0 | AL40: 0 | AM40: 0 | AN40: 0 | AO40: 0 | AP40: 0 | AQ40: 0 | AR40: 0 | AS40: 0 | AT40: 0 | AU40: 0 | AV40: 0 | AW40: 0 | AX40: 0 | AY40: 0 | AZ40: 0 | BA40: 0 | BB40: 0 | BC40: 0 | BD40: 0 | BE40: 0 | BF40: 0 | BG40: 0 | BH40: 0 | BI40: 0 | BJ40: 0 | BK40: 0 | BL40: 0 | BM40: 0 | BN40: 0 | BO40: 0 | BP40: 0 | BQ40: 0 | BR40: 0 | BS40: 0 | BT40: 0 | BU40: -25091 | BV40: -25091 | BW40: 0 | BX40: 0 | BY40: 0 | BZ40: 0 | CA40: 0 | CB40: 0 | CC40: 0 | CD40: 0 | CE40: 0 | CF40: 0 | CG40: 0 | CH40: 0 | CI40: 0 | CJ40: 0 | CK40: 0 | CL40: 0 | CM40: 0 | CN40: 0 | CO40: 0 | CP40: 0 | CQ40: 0 | CR40: 0 | CS40: 0 | CT40: 0 | CU40: 0 | CV40: 0 | CW40: 0 | CX40: 0 | CY40: 0 | CZ40: 0 | DA40: 0 | DB40: 0 | DC40: 0 | DD40: 0 | DE40: 0 | DF40: 0 | DG40: 0 | DH40: 0 | DI40: 0 | DJ40: 0 | DK40: 0 | DL40: 0 | DM40: 0 | DN40: 0 | DO40: 0 | DP40: 0 | DQ40: 0 | DR40: 0 | DS40: 0 | DT40: 0 | DU40: 0 | DV40: 0 | DW40: 0 | DX40: 0 | DY40: 0 | DZ40: 0 | EA40: 0 | EB40: 0 | EC40: 0 | ED40: 0 | EE40: -201688
A41: 3. Saatva | B41: 3 | C41: 0 | D41: 0 | E41: 0 | F41: 0 | G41: 0 | H41: 0 | I41: 0 | J41: 0 | K41: 0 | L41: 0 | M41: 0 | N41: 0 | O41: 0 | P41: 0 | Q41: 0 | R41: 0 | S41: 0 | T41: 0 | U41: 0 | V41: 0 | W41: 0 | X41: 0 | Y41: 0 | Z41: 0 | AA41: 0 | AB41: 0 | AC41: 0 | AD41: -15406 | AE41: -15406 | AF41: 0 | AG41: 0 | AH41: 0 | AI41: 0 | AJ41: 0 | AK41: 0 | AL41: 0 | AM41: 0 | AN41: 0 | AO41: 0 | AP41: 0 | AQ41: 0 | AR41: 0 | AS41: 0 | AT41: 0 | AU41: 0 | AV41: 0 | AW41: 0 | AX41: 0 | AY41: 0 | AZ41: 0 | BA41: 0 | BB41: 0 | BC41: 0 | BD41: 0 | BE41: 0 | BF41: 0 | BG41: 0 | BH41: 0 | BI41: 0 | BJ41: 0 | BK41: 0 | BL41: 0 | BM41: 0 | BN41: 0 | BO41: 0 | BP41: 0 | BQ41: 0 | BR41: 0 | BS41: 0 | BT41: 0 | BU41: 0 | BV41: 0 | BW41: 0 | BX41: 0 | BY41: 0 | BZ41: 0 | CA41: 0 | CB41: 0 | CC41: 0 | CD41: 0 | CE41: 0 | CF41: 0 | CG41: 0 | CH41: 0 | CI41: 0 | CJ41: 0 | CK41: 0 | CL41: 0 | CM41: 0 | CN41: 0 | CO41: 0 | CP41: 0 | CQ41: -17860 | CR41: -17860 | CS41: 0 | CT41: 0 | CU41: 0 | CV41: 0 | CW41: 0 | CX41: 0 | CY41: 0 | CZ41: 0 | DA41: 0 | DB41: 0 | DC41: 0 | DD41: 0 | DE41: 0 | DF41: 0 | DG41: 0 | DH41: 0 | DI41: 0 | DJ41: 0 | DK41: 0 | DL41: 0 | DM41: 0 | DN41: 0 | DO41: 0 | DP41: 0 | DQ41: 0 | DR41: 0 | DS41: 0 | DT41: 0 | DU41: 0 | DV41: 0 | DW41: 0 | DX41: 0 | DY41: 0 | DZ41: 0 | EA41: 0 | EB41: 0 | EC41: 0 | ED41: 0 | EE41: -66532
A42: 4. Fuse Architecture Studio | B42: 4 | C42: 0 | D42: 0 | E42: 0 | F42: 0 | G42: 0 | H42: 0 | I42: 0 | J42: 0 | K42: 0 | L42: 0 | M42: 0 | N42: 0 | O42: 0 | P42: 0 | Q42: 0 | R42: 0 | S42: 0 | T42: 0 | U42: 0 | V42: -7823 | W42: -7823 | X42: 0 | Y42: 0 | Z42: 0 | AA42: 0 | AB42: 0 | AC42: 0 | AD42: 0 | AE42: 0 | AF42: 0 | AG42: 0 | AH42: 0 | AI42: 0 | AJ42: 0 | AK42: 0 | AL42: 0 | AM42: 0 | AN42: 0 | AO42: 0 | AP42: 0 | AQ42: 0 | AR42: 0 | AS42: 0 | AT42: 0 | AU42: 0 | AV42: 0 | AW42: 0 | AX42: 0 | AY42: 0 | AZ42: 0 | BA42: 0 | BB42: 0 | BC42: 0 | BD42: 0 | BE42: 0 | BF42: 0 | BG42: 0 | BH42: 0 | BI42: 0 | BJ42: 0 | BK42: 0 | BL42: 0 | BM42: 0 | BN42: 0 | BO42: 0 | BP42: 0 | BQ42: 0 | BR42: 0 | BS42: 0 | BT42: 0 | BU42: 0 | BV42: 0 | BW42: 0 | BX42: 0 | BY42: 0 | BZ42: 0 | CA42: 0 | CB42: 0 | CC42: 0 | CD42: 0 | CE42: 0 | CF42: 0 | CG42: 0 | CH42: 0 | CI42: -9342 | CJ42: -9342 | CK42: 0 | CL42: 0 | CM42: 0 | CN42: 0 | CO42: 0 | CP42: 0 | CQ42: 0 | CR42: 0 | CS42: 0 | CT42: 0 | CU42: 0 | CV42: 0 | CW42: 0 | CX42: 0 | CY42: 0 | CZ42: 0 | DA42: 0 | DB42: 0 | DC42: 0 | DD42: 0 | DE42: 0 | DF42: 0 | DG42: 0 | DH42: 0 | DI42: 0 | DJ42: 0 | DK42: 0 | DL42: 0 | DM42: 0 | DN42: 0 | DO42: 0 | DP42: 0 | DQ42: 0 | DR42: 0 | DS42: 0 | DT42: 0 | DU42: 0 | DV42: 0 | DW42: 0 | DX42: 0 | DY42: 0 | DZ42: 0 | EA42: 0 | EB42: 0 | EC42: 0 | ED42: 0 | EE42: -34330
