Workbook
Name _: #REF!
Name _______________: #REF!
Name ________EXP1: #REF!
Name __C: #REF!
Name _1_96100: #REF!
Name _1201T1: #REF!
Name _1202T1: #N/A
Name _1206T1: #REF!
Name _1207T1: #REF!
Name _1208T1: #REF!
Name _1210T1: #REF!
Name _1211T1: #REF!
Name _1216T1: #REF!
Name _1217T1: #REF!
Name _1218T1: #REF!
Name _1219T1: #REF!
Name _1220T1: #REF!
Name _1220T2: #REF!
Name _1221T1: #REF!
Name _1222T1: #REF!
Name _1223T1: #REF!
Name _1224T1: #REF!
Name _1226T2: #REF!
Name _1231T: #REF!
Name _1231T1: #REF!
Name _1233T1: #REF!
Name _1234T2: #REF!
Name _1235T1: #REF!
Name _1236T1: #REF!
Name _1238T1: #REF!
Name _1239T1: #REF!
Name _1239T3: #REF!
Name _1240T1: #REF!
Name _1248T3: #REF!
Name _1251T1: #REF!
Name _1251T2: #REF!
Name _1252T1: #REF!
Name _1252T2: #REF!
Name _1256T1: #REF!
Name _1257T1: #REF!
Name _1258T1: #REF!
Name _1260T1: #REF!
Name _1260T2: #REF!
Name _1261T1: #REF!
Name _1262T1: #REF!
Name _1264T1: #REF!
Name _1265T1: #REF!
Name _1268T2: #REF!
Name _1273T1: #REF!
Name _1276T1: #REF!
Name _1280T1: #REF!
Name _1281T1: #REF!
Name _1992: #REF!
Name _1993: #REF!
Name _1994: #REF!
Name _450: #REF!
Name _450.INT: #REF!
Name _451: #REF!
Name _451.INT: #REF!
Name _502: #REF!

Sheet Disclaimer
B3: =+Assumptions!B2 -> Chapman Plaza
B4: =TODAY() -> 46153
B6: DISCLAIMER
B7: This confidential summary contains forward-looking statements that are not historical facts. These forward-looking statements include statements, express or implied, regarding the current expectations, estimates, projections, opinions and beliefs of the Arc Capital Partners LLC ("Company"), as well as certain assumptions on which those statements are based. Such forward-looking statements are subject to risks, uncertainties and other factors that may cause actual events to differ materially from any anticipated development and no assurance can be given that the Company, or any investment vehicle that may be formed or managed by the Company in the future, will achieve the projected returns. The pro forma information set forth in this confidential summary is shown for illustration purposes only and should not be relied upon. No representation or assurance is made that any potential investor will or is likely to achieve results comparable to those shown or will make any profit or will be able to avoid incurring substantial losses. The information contained herein is confidential and intended solely for use by the Company and persons to whom the Company has delivered this document. This confidential summary is not to be reproduced or distributed to any third party. The recipient, by accepting this document, agrees to this restriction and to return the document to the Company upon request. The pro forma information reflects the Company’s judgment, based on current circumstances, of the most likely set of conditions and its most likely course of action. The assumptions disclosed herein are those that the Company believes are significant to the pro forma information or are key factors upon which the financial results of the Company and any potential real estate investment opportunity depend. Some assumptions inevitably will not materialize and unanticipated events and circumstances may occur subsequent to the date of this information. Therefore, the actual results achieved during the forecast period will vary from the forecast, and the variations may be material. None of the Company, its managers, officers, directors, employees or affiliates assume any responsibility to notify recipients of any updates to this pro forma information if there are changes to the assumptions or results. Recipients are encouraged to consult with their own professional advisors concerning this pro forma information, including the assumptions used. The Company will make available additional information upon request concerning the pro forma information to the extent it is readily available to the Company at no additional cost and the Company is not otherwise restricted from providing such information.

Sheet Major Changes 2023
B2: Lease Up Revisions (2020, 2021 and 2022)
E3: Base Rent Assumptions | I3: Lease up Assumption | L3: TIs PSF Assumption
D4: Term | E4: 2020 | F4: 2021 | G4: 2022 | H4: Delta | I4: 2020 | J4: 2021 | K4: 2022 | L4: 2020 | M4: 2021 | N4: 2022 | O4: Delta
B5: 200 | C5: VACANT | D5: 5 years | E5: 3.5 | F5: 2.5 | G5: 2.5 | H5: =F5-G5 -> 0 | I5: 44196 | J5: 44593 | K5: 44835 | L5: 80 | M5: 100 | N5: 100 | O5: =N5-M5 -> 0
B6: 300 | C6: VACANT | D6: 5 years | E6: 3.5 | F6: 2.5 | G6: 2.5 | H6: =F6-G6 -> 0 | I6: 44196 | J6: 44470 | K6: 44835 | L6: 25 | M6: 25 | N6: 45 | O6: =N6-M6 -> 20
B11: Current Rent Roll
E12: Base Rent (PSF) | J12: Rent Renewal | N12: Renewal TI Assumptions
B13: Suite # | C13: Tenant | D13: Lease Expiration | E13: 2020 | F13: 2021 | G13: 2022 | M13: Delta | N13: 2019 | O13: 2020 | P13: 2021 | Q13: Delta | R13: Comments
B14: 10/180 | C14: Shibuyala | D14: 44834 | E14: 5.75 | F14: 6 | M14: 0 | N14: 40 | O14: 40 | P14: 18.03 | Q14: =P14-O14 -> -21.97 | R14: Expansion space buildout completed
B15: 010, 020 | C15: Baekjeong | E15: 5.5 | F15: 5.75 | M15: 0 | N15: 0 | O15: 0 | P15: 17.5 | Q15: =P15-O15 -> 17.5 | R15: Current
B16: 40 | C16: Starbucks | D16: 46904 | E16: 5.5 | F16: 5.5 | M16: 0 | N16: 75 | O16: 75 | P16: 21.52 | Q16: =P16-O16 -> -53.48 | R16: Current
B17: 50 | C17: Kazunori (LOI) | D17: =EOMONTH(L17,15*12-1) -> 5479 | E17: 6 | F17: 5.25 | N17: 75 | O17: 50 | P17: 60 | Q17: =P17-O17 -> 10 | R17: Signed lease expected week of 12/7/2020
B18: 65 | C18: Project 11 11 (LOI) | D18: 46204 | E18: 4.6 | F18: 3.75 | M18: 0 | N18: 50 | O18: 50 | P18: 35 | Q18: =P18-O18 -> -15 | R18: Interested in the Gaam #300 space
B19: 70 | C19: Escala | D19: 45291 | E19: 5.75 | F19: 5.5 | M19: 0 | N19: 20 | O19: 20 | P19: 22.17 | Q19: =P19-O19 -> 2.17 | R19: Current
B20: 80 | C20: GER Bar | D20: 47422 | E20: 5.08 | F20: 4.5 | M20: 2 | N20: 50 | O20: 50 | P20: 22.17 | Q20: =P20-O20 -> -27.83 | R20: Payment plan has been accepted by tenant
B21: 150 | C21: Hikari | D21: 45107 | E21: 6 | F21: 5.5 | M21: 0 | N21: 0 | O21: 0 | P21: 18.57 | Q21: =P21-O21 -> 18.57 | R21: Current
B22: 110 | C22: Toe Bang | D22: 44985 | E22: 5.4207829 | F22: 5.5 | M22: 0 | N22: 0 | O22: 0 | P22: 18.57 | Q22: =P22-O22 -> 18.57 | R22: Payment plan in progress for $133k+ in A/R
B23: 120, 140 | C23: Tiger Sugar Boba | D23: 44681 | E23: 5.5 | F23: 6 | M23: 0 | N23: 40 | O23: 40 | P23: 19.7 | Q23: =P23-O23 -> -20.3 | R23: TI buildout approved, construction to commence Dec-2020
B24: 160 | C24: Silver Lake Ramen | D24: 47269 | E24: 6.14 | F24: 6 | M24: 2 | N24: 50 | O24: 50 | P24: 22.17 | Q24: =P24-O24 -> -27.83 | R24: Current
B25: 130 | C25: Quarters | D25: 45138 | E25: 5.25 | F25: 5.5 | M25: 0 | N25: 0 | O25: 0 | P25: 18.57 | Q25: =P25-O25 -> 18.57 | R25: Current
B26: 170 | C26: Uncle Tetsu | E26: 0 | F26: 0 | G26: 5.75
B28: Total/Weighted Average | E28: =AVERAGE(E3:E7) -> 675.66667 | F28: =AVERAGE(F3:F7) -> 675.33333 | H28: =AVERAGE(H3:H7) -> 0 | N28: =AVERAGE(N3:N7) -> 722.33333 | O28: =AVERAGE(O3:O7) -> 10 | P28: =AVERAGE(P4:P7) -> #DIV/0! | Q28: =AVERAGE(Q3:Q7) -> #DIV/0!
B30: Other Major Revisions (2022 vs 2021 Business Plan)
B31: Assumptions ($'s in 000's) | O31: 2021 | P31: 2022 | Q31: Delta | R31: Comments
B32: Exit Cap Rate | O32: 0.05 | Q32: 0 | R32: Current broker feedback is 4.50% - 5.25%
B33: Sale Date | O33: 45291 | Q33: 36 | R33: New stabilization period, optionality for early sale
B34: CapEx Budget (2021 Forecast) | O34: =Assumptions!M92 -> 0 | Q34: =O34-#REF! -> #REF! | R34: CapEx (with optionality) planned for 2021
B35: Net Parking Income (annual) | O35: =13*12 -> 156 | Q35: =O35-#REF! -> #REF! | R35: Signed license agreement with PCAM
B36: Event & Kiosk Income (annual) | O36: 60 | Q36: =O36-#REF! -> #REF! | R36: Revised $5k/mo event assumption & removed kiosk income
B37: Patio SF (BOMA) | Q37: 371.3 | R37: Includes Silver Lake Ramen patio
B39: Refinance (June 2021)
B40: Total Proceeds | O40: =Assumptions!F62 -> 22133.64 | Q40: =O40-#REF! -> #REF! | R40: Approx. proceeds expected
B41: TI/LC Reserve | O41: Incl. above | Q41: - | R41: Approx. proceeds expected
B42: CapEx Reserve | O42: Incl. above | Q42: - | R42: Approx. proceeds expected
B43: Pricing | O43: =Assumptions!D65 -> 490 | Q43: =O43-#REF! -> #REF! | R43: Change from UBS terms to new lender post-Covid
B44: Loan Origination/Broker Fee & Exit Fee | O44: 1.0% / 0.50% | R44: Proforma
B47: (1) Tenant Improvements for new leases are blended at $50/sf for new leases and $0/sf for renewals, with 65% renewal probability
C48: =PMT(4.5%/12,360,-1)*12 -> 0.060802237
B50: Projected Returns Summary
D51: 2020 | E51: 2021 | F51: 2022 | G51: 2023
...

Sheet Charts
B3: =+Assumptions!B2 -> Chapman Plaza
B4: Deal Snapshot
A6: x | B6: Property Overview
B7: Property Type | D7: Retail | F7: Year Built/Renovated | I7: 1928/2017
B8: NRA (SF) | D8: =Assumptions!$F$7 -> 41469 | F8: Market | I8: Los Angeles
B9: Current Occupancy | D9: 0.6 | F9: Submarket | I9: Koreatown
B10: Parking Stalls | D10: 102 | F10: Sponsor | I10: Arc Capital Partners
A12: x | B12: Sources & Uses
G13: At Close | H13: Lease Up | I13: Total | J13: $ PSF | K13: %
B14: Debt | G14: =+Assumptions!F46 -> 19541 | H14: =+Assumptions!F49 -> 2254.794 | I14: =+G14+H14 -> 21795.794 | J14: =+I14/$D$8*1000 -> 525.59247 | K14: =+I14/$I$17 -> 0.52847275
B15: Equity | G15: =(G$29-G$14-G16) -> 13708 | H15: =(H$29-H$14-H16) -> 5624.7811 | I15: =+G15+H15 -> 19332.781 | J15: =+I15/$D$8*1000 -> 466.19839 | K15: =+I15/$I$17 -> 0.46875319
B16: Project Cash Flow | G16: 0 | H16: =+Assumptions!J69 -> 114.41053 | I16: =+G16+H16 -> 114.41053 | J16: =+I16/$D$8*1000 -> 2.7589411 | K16: =+I16/$I$17 -> 0.0027740603
B17: Total Sources | G17: =SUM(G14:G16) -> 33249 | H17: =SUM(H14:H16) -> 7993.9856 | I17: =SUM(I14:I16) -> 41242.986 | J17: =SUM(J14:J16) -> 994.5498 | K17: =SUM(K14:K16) -> 1
B19: =+Assumptions!H53 -> Purchase Price | G19: =+Assumptions!C12 -> 30000 | H19: 0 | I19: =+G19+H19 -> 30000 | J19: =+I19/$D$8*1000 -> 723.43196 | K19: =+I19/$I$29 -> 0.72739642
B20: Reserves Funded at Close | G20: =-'Monthly Cash Flow'!$K$180 -> 2473 | H20: 0 | I20: =+G20+H20 -> 2473 | J20: =+I20/$D$8*1000 -> 59.634908 | K20: =+I20/$I$29 -> 0.059961711
B21: =+Assumptions!H54 -> Closing Costs | G21: =+Assumptions!C13 -> 206 | H21: 0 | I21: =+G21+H21 -> 206 | J21: =+I21/$D$8*1000 -> 4.9675661 | K21: =+I21/$I$29 -> 0.0049947887
B22: =+Assumptions!H56 -> Operating Losses | G22: 0 | H22: =+Assumptions!J56 -> 499.20616 | I22: =+G22+H22 -> 499.20616 | J22: =+I22/$D$8*1000 -> 12.038056 | K22: =+I22/$I$29 -> 0.012104026
B23: =+Assumptions!H57 -> CapEx | G23: 0 | H23: =+Assumptions!J57 -> 2314.3238 | I23: =+G23+H23 -> 2314.3238 | J23: =+I23/$D$8*1000 -> 55.808526 | K23: =+I23/$I$29 -> 0.05611436
B24: =+Assumptions!H58 -> Soft Costs | G24: 0 | H24: =+Assumptions!J58 -> 823.309 | I24: =+G24+H24 -> 823.309 | J24: =+I24/$D$8*1000 -> 19.853601 | K24: =+I24/$I$29 -> 0.019962401
B25: =+Assumptions!H59 -> Contingency | G25: 0 | H25: =+Assumptions!J59 -> 0 | I25: =+G25+H25 -> 0 | J25: =+I25/$D$8*1000 -> 0 | K25: =+I25/$I$29 -> 0
B26: =+Assumptions!H61 -> TIs | G26: 0 | H26: =+Assumptions!J61 -> 2716.711 | I26: =+G26+H26 -> 2716.711 | J26: =+I26/$D$8*1000 -> 65.511852 | K26: =+I26/$I$29 -> 0.065870862
B27: =+Assumptions!H62 -> LCs | G27: 0 | H27: =+Assumptions!J62 -> 976.22775 | I27: =+G27+H27 -> 976.22775 | J27: =+I27/$D$8*1000 -> 23.541145 | K27: =+I27/$I$29 -> 0.023670152
B28: =+Assumptions!H63 -> Loan Closing Costs & Fees | G28: =+Assumptions!C24 -> 570 | H28: =+'Monthly Cash Flow'!I110+'Monthly Cash Flow'!I108+'Monthly Cash Flow'!I107-'Monthly Cash Flow'!K107 -> 664.20794 | I28: =+G28+H28 -> 1234.2079 | J28: =+I28/$D$8*1000 -> 29.762182 | K28: =+I28/$I$29 -> 0.029925281
B29: Total Uses | G29: =SUM(G19:G28) -> 33249 | H29: =SUM(H19:H28) -> 7993.9856 | I29: =SUM(I19:I28) -> 41242.986 | J29: =SUM(J19:J28) -> 994.5498 | K29: =SUM(K19:K28) -> 1
A31: x | B31: Cash Flows
F32: Year 0 | G32: 1 | H32: 2 | I32: 3 | J32: 4 | K32: 5 | L32: 6 | M32: 7 | N32: 8 | O32: Total
B33: Revenues | F33: =+'Monthly Cash Flow'!HN62 -> 0 | G33: =+'Monthly Cash Flow'!HO62-G34 -> 2481.425 | H33: =+'Monthly Cash Flow'!HP62-H34 -> 2653.2109 | I33: =+'Monthly Cash Flow'!HQ62-I34 -> 2822.0617 | J33: =+'Monthly Cash Flow'!HR62-J34 -> 3141.6924 | K33: =+'Monthly Cash Flow'!HS62-K34 -> 2780.3238 | L33: =+'Monthly Cash Flow'!HT62-L34 -> 3082.3794 | M33: =+'Monthly Cash Flow'!HU62-M34 -> 3532.1282 | N33: =+'Monthly Cash Flow'!HV62-N34 -> 3797.647 | O33: =SUM(F33:N33) -> 24290.869
B34: Rental Abatement | F34: =+'Monthly Cash Flow'!HN56 -> 0 | G34: =+'Monthly Cash Flow'!HO56 -> -53.115 | H34: =+'Monthly Cash Flow'!HP56 -> -121.70247 | I34: =+'Monthly Cash Flow'!HQ56 -> -104.91229 | J34: =+'Monthly Cash Flow'!HR56 -> -114.87685 | K34: =+'Monthly Cash Flow'!HS56 -> -59.26107 | L34: =+'Monthly Cash Flow'!HT56 -> -27.20017 | M34: =+'Monthly Cash Flow'!HU56 -> -48.75893 | N34: =+'Monthly Cash Flow'!HV56 -> -6.775 | O34: =SUM(F34:N34) -> -536.60178
B35: Operating Expenses | F35: =+'Monthly Cash Flow'!HN74 -> 0 | G35: =-'Monthly Cash Flow'!HO74 -> -1588.5911 | H35: =-'Monthly Cash Flow'!HP74 -> -1562.0958 | I35: =-'Monthly Cash Flow'!HQ74 -> -1425.7339 | J35: =-'Monthly Cash Flow'!HR74 -> -1581.2866 | K35: =-'Monthly Cash Flow'!HS74 -> -1978.2159 | L35: =-'Monthly Cash Flow'!HT74 -> -1771.2262 | M35: =-'Monthly Cash Flow'!HU74 -> -1759.31 | N35: =-'Monthly Cash Flow'!HV74 -> -1828.583 | O35: =SUM(F35:N35) -> -13495.042
B36: Net Operating Income | F36: 0 | G36: =SUM(G33:G35) -> 839.71891 | H36: =SUM(H33:H35) -> 969.41268 | I36: =SUM(I33:I35) -> 1291.4156 | J36: =SUM(J33:J35) -> 1445.5289 | K36: =SUM(K33:K35) -> 742.84688 | L36: =SUM(L33:L35) -> 1283.953 | M36: =SUM(M33:M35) -> 1724.0593 | N36: =SUM(N33:N35) -> 1962.289 | O36: =SUM(F36:N36) -> 10259.224
B37: =Assumptions!B17 -> CapEx | F37: =-'Monthly Cash Flow'!HN26 -> 0 | G37: =-'Monthly Cash Flow'!HO26 -> -84.0285 | H37: =-'Monthly Cash Flow'!HP26 -> -1211.4883 | I37: =-'Monthly Cash Flow'!HQ26 -> -22.651 | J37: =-'Monthly Cash Flow'!HR26 -> -180.858 | K37: =-'Monthly Cash Flow'!HS26 -> -65.924 | L37: =-'Monthly Cash Flow'!HT26 -> -259.374 | M37: =-'Monthly Cash Flow'!HU26 -> -310.31746 | N37: =-'Monthly Cash Flow'!HV26 -> -179.68254 | O37: =SUM(F37:N37) -> -2314.3238
B38: TIs/LCs/Soft Costs/Other | F38: =-SUM('Monthly Cash Flow'!HN33:HN33,'Monthly Cash Flow'!HN36:HN36,'Monthly Cash Flow'!HN29:HN30,'Monthly Cash Flow'!HN39) -> 0 | G38: =-SUM('Monthly Cash Flow'!HO33:HO33,'Monthly Cash Flow'!HO36:HO36,'Monthly Cash Flow'!HO29:HO30,'Monthly Cash Flow'!HO39) -> -209.71683 | H38: =-SUM('Monthly Cash Flow'!HP33:HP33,'Monthly Cash Flow'!HP36:HP36,'Monthly Cash Flow'!HP29:HP30,'Monthly Cash Flow'!HP39) -> -758.88951 | I38: =-SUM('Monthly Cash Flow'!HQ33:HQ33,'Monthly Cash Flow'!HQ36:HQ36,'Monthly Cash Flow'!HQ29:HQ30,'Monthly Cash Flow'!HQ39) -> -429.41721 | J38: =-SUM('Monthly Cash Flow'!HR33:HR33,'Monthly Cash Flow'!HR36:HR36,'Monthly Cash Flow'!HR29:HR30,'Monthly Cash Flow'!HR39) -> -516.28246 | K38: =-SUM('Monthly Cash Flow'!HS33:HS33,'Monthly Cash Flow'!HS36:HS36,'Monthly Cash Flow'!HS29:HS30,'Monthly Cash Flow'!HS39) -> 0 | L38: =-SUM('Monthly Cash Flow'!HT33:HT33,'Monthly Cash Flow'!HT36:HT36,'Monthly Cash Flow'!HT29:HT30,'Monthly Cash Flow'!HT39) -> -248.5883 | M38: =-SUM('Monthly Cash Flow'!HU33:HU33,'Monthly Cash Flow'!HU36:HU36,'Monthly Cash Flow'!HU29:HU30,'Monthly Cash Flow'!HU39) -> -207.14543 | N38: =-SUM('Monthly Cash Flow'!HV33:HV33,'Monthly Cash Flow'!HV36:HV36,'Monthly Cash Flow'!HV29:HV30,'Monthly Cash Flow'!HV39) -> -2146.208 | O38: =SUM(F38:N38) -> -4516.2477
B39: Debt Service | F39: =+'Monthly Cash Flow'!HN182+'Monthly Cash Flow'!HN183 -> 0 | G39: =+'Monthly Cash Flow'!HO182+'Monthly Cash Flow'!HO183 -> -1191.4756 | H39: =+'Monthly Cash Flow'!HP182+'Monthly Cash Flow'!HP183 -> -1425.4419 | I39: =+'Monthly Cash Flow'!HQ182+'Monthly Cash Flow'!HQ183 -> -1730.8324 | J39: =+'Monthly Cash Flow'!HR182+'Monthly Cash Flow'!HR183 -> -1528.2517 | K39: =+'Monthly Cash Flow'!HS182+'Monthly Cash Flow'!HS183 -> -1273.8617 | L39: =+'Monthly Cash Flow'!HT182+'Monthly Cash Flow'!HT183 -> -1200.9664 | M39: =+'Monthly Cash Flow'!HU182+'Monthly Cash Flow'!HU183 -> -1473.2061 | N39: =+'Monthly Cash Flow'!HV182+'Monthly Cash Flow'!HV183 -> -1793.0433 | O39: =SUM(F39:N39) -> -11617.079
B40: Cash Flows after Debt Service | F40: =SUM(F36:F39) -> 0 | G40: =SUM(G36:G39) -> -645.50202 | H40: =SUM(H36:H39) -> -2426.4069 | I40: =SUM(I36:I39) -> -891.48502 | J40: =SUM(J36:J39) -> -779.86323 | K40: =SUM(K36:K39) -> -596.93878 | L40: =SUM(L36:L39) -> -424.97568 | M40: =SUM(M36:M39) -> -266.60966 | N40: =SUM(N36:N39) -> -2156.6448 | O40: =SUM(F40:N40) -> -8188.4261
B41: Acquisition and Disposition | F41: =+'Monthly Cash Flow'!HN174+'Monthly Cash Flow'!HN180 -> -32679 | G41: =+'Monthly Cash Flow'!HO174 -> 0 | H41: =+'Monthly Cash Flow'!HP174 -> 0 | I41: =+'Monthly Cash Flow'!HQ174 -> 0 | J41: =+'Monthly Cash Flow'!HR174 -> 0 | K41: =+'Monthly Cash Flow'!HS174 -> 0 | L41: =+'Monthly Cash Flow'!HT174 -> 0 | M41: =+'Monthly Cash Flow'!HU174 -> 0 | N41: =+'Monthly Cash Flow'!HV174 -> 0 | O41: =SUM(F41:N41) -> -32679
B42: New Debt, net | F42: =+'Monthly Cash Flow'!HN179+'Monthly Cash Flow'!HN181 -> 19541 | G42: =+'Monthly Cash Flow'!HO179+'Monthly Cash Flow'!HO181 -> 293.74533 | H42: =+'Monthly Cash Flow'!HP179+'Monthly Cash Flow'!HP181 -> 1961.0487 | I42: =+'Monthly Cash Flow'!HQ179+'Monthly Cash Flow'!HQ181 -> 1.4708235e-12 | J42: =+'Monthly Cash Flow'!HR179+'Monthly Cash Flow'!HR181 -> -4.938272e-13 | K42: =+'Monthly Cash Flow'!HS179+'Monthly Cash Flow'!HS181 -> 22133.64 | L42: =+'Monthly Cash Flow'!HT179+'Monthly Cash Flow'!HT181 -> 507.9623 | M42: =+'Monthly Cash Flow'!HU179+'Monthly Cash Flow'!HU181 -> 517.46289 | N42: =+'Monthly Cash Flow'!HV179+'Monthly Cash Flow'!HV181 -> 2325.8905 | O42: =SUM(F42:N42) -> 47280.75
B43: Financing Cost | F43: =+'Monthly Cash Flow'!HN184+'Monthly Cash Flow'!HN185 -> -570 | G43: =+'Monthly Cash Flow'!HO184+'Monthly Cash Flow'!HO185 -> 0 | H43: =+'Monthly Cash Flow'!HP184+'Monthly Cash Flow'!HP185 -> 0 | I43: =+'Monthly Cash Flow'!HQ184+'Monthly Cash Flow'!HQ185 -> 0 | J43: =+'Monthly Cash Flow'!HR184+'Monthly Cash Flow'!HR185 -> -108.97897 | K43: =+'Monthly Cash Flow'!HS184+'Monthly Cash Flow'!HS185 -> -920.11164 | L43: =+'Monthly Cash Flow'!HT184+'Monthly Cash Flow'!HT185 -> 0 | M43: =+'Monthly Cash Flow'!HU184+'Monthly Cash Flow'!HU185 -> 0 | N43: =+'Monthly Cash Flow'!HV184+'Monthly Cash Flow'!HV185 -> 0 | O43: =SUM(F43:N43) -> -1599.0906
B44: Loan Repayment | F44: =+'Monthly Cash Flow'!HN186 -> 0 | G44: =+'Monthly Cash Flow'!HO186 -> 0 | H44: =+'Monthly Cash Flow'!HP186 -> 0 | I44: =+'Monthly Cash Flow'!HQ186 -> 0 | J44: =+'Monthly Cash Flow'!HR186 -> 0 | K44: =+'Monthly Cash Flow'!HS186 -> -21795.794 | L44: =+'Monthly Cash Flow'!HT186 -> 0 | M44: =+'Monthly Cash Flow'!HU186 -> 0 | N44: =+'Monthly Cash Flow'!HV186 -> 0 | O44: =SUM(F44:N44) -> -21795.794
B45: Leveraged Cash Flows | F45: =SUM(F40:F44) -> -13708 | G45: =SUM(G40:G44) -> -351.75669 | H45: =SUM(H40:H44) -> -465.35827 | I45: =SUM(I40:I44) -> -891.48502 | J45: =SUM(J40:J44) -> -888.8422 | K45: =SUM(K40:K44) -> -1179.2045 | L45: =SUM(L40:L44) -> 82.98662 | M45: =SUM(M40:M44) -> 250.85323 | N45: =SUM(N40:N44) -> 169.24573 | O45: =SUM(F45:N45) -> -16981.561
B46: NOI Growth Rate | G46: n/a | H46: n/a | I46: n/a | J46: n/a | K46: n/a | L46: n/a | M46: n/a | N46: n/a
...

Sheet Assumptions
E1: 1 | F1: Circ Trigger
B2: Chapman Plaza | R2: =NOW() -> 46153.526
B3: ($ in thousands, except psf amounts)
B5: Land Summary | H5: Project Timing | J5: Start | K5: Duration | L5: End | N5: Joint Venture Terms | T5: Sensitivity Chart - Sales Date vs Cap Rate
B6: Land SF | E6: 1.57 | F6: =43560*E6 -> 68389.2 | H6: Purchase Date | I6: 42552 | N6: Investor Contribution | R6: 0.98
B7: Building FAR SF | F7: 41469 | H7: Acquisition | L7: =J7+K7 -> 0 | P7: Hurdle | Q7: Distribution % | T7: =O23 -> 0.071606448 | U7: 90 | V7: 96 | W7: 99 | X7: 102
B8: Implied FAR | F8: =F7/F6 -> 0.60636767 | H8: =+B17 -> CapEx | N8: Waterfall Structure (TBD) | P8: Rate | Q8: Investors | R8: Arc | T8: 0.0425 | U8: 0.089910141 | V8: 0.11410877 | W8: 0.11095428 | X8: 0.10869942
H9: Suite 300 | I9: =HLOOKUP(J9,'Monthly Cash Flow'!$K$13:$GT$15,3) -> 44592 | J9: 67 | K9: 1 | L9: =J9+K9 -> 68 | N9: Capital Contribution | Q9: 1 | R9: =1-Q9 -> 0 | T9: =T8+0.25% -> 0.045 | U9: 0.074231014 | V9: 0.10050105 | W9: 0.097788948 | X9: 0.096009633
B10: Acquisition Costs | H10: Suite 170 | I10: =HLOOKUP(J10,'Monthly Cash Flow'!$K$13:$GT$15,3) -> 44592 | J10: 67 | K10: 3 | L10: =J10+K10 -> 70 | N10: Tier 1 | P10: 0.09 | Q10: 1 | R10: =1-Q10 -> 0 | T10: =T9+0.25% -> 0.0475 | U10: 0.058861801 | V10: 0.08727015 | W10: 0.084982792 | X10: 0.083666947
C11: At Close | D11: PSF* | E11: At Stabilization | F11: PSF* | H11: Courtyard | I11: =HLOOKUP(J11,'Monthly Cash Flow'!$K$13:$GT$15,3) -> 44712 | J11: 71 | K11: 3 | L11: =J11+K11 -> 74 | N11: Tier 2 | P11: 0.09 | Q11: =1-R11 -> 1 | R11: 0 | T11: =T10+0.25% -> 0.05 | U11: 0.043713734 | V11: 0.074345776 | W11: 0.072468033 | X11: 0.071606448
B12: Purchase Price | C12: 30000 | D12: =C12/$F$7*1000 -> 723.43196 | E12: =C12 -> 30000 | F12: =E12/$F$7*1000 -> 723.43196 | H12: =+B18 -> Soft Costs | N12: Capital Events | T12: =T11+0.25% -> 0.0525 | U12: 0.028703257 | V12: 0.061664852 | W12: 0.060183766 | X12: 0.059769842
B13: =C13/C12 -> 0.0068666667 | C13: 206 | D13: =C13/$F$7*1000 -> 4.9675661 | E13: =C13 -> 206 | F13: =E13/$F$7*1000 -> 4.9675661 | H13: Suite 200 | I13: =HLOOKUP(J13,'Monthly Cash Flow'!$K$13:$GT$15,3) -> 44620 | J13: 68 | K13: 3 | L13: =J13+K13 -> 71 | N13: Tier 3 | P13: 0.09 | Q13: 1 | R13: =1-Q13 -> 0 | T13: =T12+0.25% -> 0.055 | U13: 0.013749281 | V13: 0.049169555 | W13: 0.048074076 | X13: 0.048103681
B14: Working Capital & Reserves | C14: 160 | D14: =C14/$F$7*1000 -> 3.8583038 | E14: =C14 -> 160 | F14: =E14/$F$7*1000 -> 3.8583038 | H14: Courtyard | I14: =HLOOKUP(J14,'Monthly Cash Flow'!$K$13:$GT$15,3) -> 44620 | J14: 68 | K14: 3 | L14: =J14+K14 -> 71 | N14: Return of Capital | Q14: 1 | R14: =1-Q14 -> 0 | T14: =T13+0.25% -> 0.0575 | U14: -0.0012294725 | V14: 0.036805722 | W14: 0.036086467 | X14: 0.036557886
B15: Total Acquisition Costs | C15: =SUM(C12:C14) -> 30366 | D15: =C15/F7*1000 -> 732.25783 | E15: =SUM(E12:E14) -> 30366 | F15: =E15/F7*1000 -> 732.25783 | N15: Tier 4 | P15: 0.12 | Q15: 0.9 | R15: =1-Q15 -> 0.1
B16: Operating Losses | C16: 0 | D16: =C16/F7*1000 -> 0 | E16: ='Monthly Cash Flow'!I111 -> 499.20616 | F16: =E16/$F$7*1000 -> 12.038056 | N16: Tier 5 | P16: 0.15 | Q16: 0.7 | R16: =1-Q16 -> 0.3
B17: CapEx | C17: 0 | D17: =C17/F7*1000 -> 0 | E17: =+'Monthly Cash Flow'!H26 -> 2314.3238 | F17: =E17/$F$7*1000 -> 55.808526 | H17: Project Sale | I17: =EOMONTH(I6,L17-1) -> 45657 | L17: =99+3 -> 102 | N17: Remainder | Q17: 0.6 | R17: =1-Q17 -> 0.4
B18: Soft Costs | C18: 0 | D18: =C18/F7*1000 -> 0 | E18: ='Monthly Cash Flow'!H29 -> 823.309 | F18: =E18/$F$7*1000 -> 19.853601 | T18: =$P$23 -> 1.7510529 | U18: =U7 -> 90 | V18: =V7 -> 96 | W18: =W7 -> 99 | X18: =X7 -> 102
B19: Contingency | C19: =0.1*(C17+C18) -> 0 | D19: =C19/F7*1000 -> 0 | E19: ='Monthly Cash Flow'!H30 -> 0 | F19: =E19/$F$7*1000 -> 0 | H19: Exit Assumptions | K19: $ per GLA | L19: % of Total | N19: Project Return Summary | T19: 0.0425 | U19: 1.8441502 | V19: 2.2783901 | W19: 2.2891963 | X19: 2.3119466
B20: Capital Reserves | C20: 0 | D20: =C20/F7*1000 -> 0 | E20: =+J41 -> 0 | F20: =+E20*1000/$F$7 -> 0 | H20: Year of Sale | L20: =L17 -> 102 | O20: Base Case | T20: =T19+0.25% -> 0.045 | U20: 1.662539 | V20: 2.0732009 | W20: 2.0827331 | X20: 2.1042082
B21: TIs | C21: 0 | D21: =C21/F7*1000 -> 0 | E21: =+J42 -> 2716.711 | F21: =+E21*1000/$F$7 -> 65.511852 | H21: Forward NOI (add back free rent) | L21: =SUM(OFFSET('Monthly Cash Flow'!K$76,0,Assumptions!$L$20+1,1,12))-SUM(OFFSET('Monthly Cash Flow'!K$56,0,Assumptions!$L$20+1,1,12)) -> 2690.476 | O21: IRR | P21: Multiple | Q21: Contribution | R21: Profit | T21: =T20+0.25% -> 0.0475 | U21: 1.5000447 | V21: 1.8896105 | W21: 1.8980029 | X21: 1.918337
B22: LCs | C22: 0 | D22: =C22/F7*1000 -> 0 | E22: =+J43 -> 976.22775 | F22: =+E22*1000/$F$7 -> 23.541145 | H22: Exit Cap Rate | L22: 0.05 | N22: Unleveraged Returns | O22: =+'Monthly Cash Flow'!I96 -> 0.057904282 | P22: =+'Monthly Cash Flow'!I95 -> 1.55 | Q22: =+'Monthly Cash Flow'!I94 -> 37647.066 | R22: ='Monthly Cash Flow'!I93 -> 20705.888 | T22: =T21+0.25% -> 0.05 | U22: 1.3537998 | V22: 1.7243791 | W22: 1.7317457 | X22: 1.7510529
B23: Total Unleveraged Basis | C23: =SUM(C15:C22) -> 30366 | D23: =C23/F7*1000 -> 732.25783 | E23: =SUM(E15:E22) -> 37695.778 | F23: =E23/F7*1000 -> 909.01101 | H23: Gross Exit Value | K23: =L23/F7*1000 -> 1369.9274 | L23: =(MAX(L21/L22))+3000 -> 56809.52 | N23: Leveraged Returns | O23: ='Monthly Cash Flow'!$I$200 -> 0.071606448 | P23: ='Monthly Cash Flow'!$I$199 -> 1.7510529 | Q23: ='Monthly Cash Flow'!$I$198 -> 15882.232 | R23: ='Monthly Cash Flow'!I197 -> 11928.396 | T23: =T22+0.25% -> 0.0525 | U23: 1.221483 | V23: 1.5748841 | W23: 1.5813225 | X23: 1.5997006
B24: Loan Closing Costs & Fees | C24: 570 | D24: =C24/F7*1000 -> 13.745207 | E24: =SUM('Monthly Cash Flow'!I107:I110) -> 1599.0906 | F24: =E24/F7*1000 -> 38.561109 | H24: Rental Abatement Credit | L24: =+SUM(OFFSET('Monthly Cash Flow'!K$56,0,Assumptions!$L$20+1,1,12)) -> 0 | N24: LP Equity | O24: =+Waterfall!G133 -> 0.071606448 | P24: =+Waterfall!G135 -> 1.7510529 | Q24: =-Waterfall!G123 -> 15564.587 | R24: =+Waterfall!G134 -> 11689.828 | T24: =T23+0.25% -> 0.055 | U24: 1.1011951 | V24: 1.4389795 | W24: 1.4445742 | X24: 1.4621076
B25: Capitalized Interest | C25: 0 | D25: =C25/F7*1000 -> 0 | E25: ='Monthly Cash Flow'!I150 -> 1715.5169 | F25: =E25/F7*1000 -> 41.368659 | H25: TI/LC Credit | L25: =-SUM(OFFSET('Monthly Cash Flow'!K$33,0,Assumptions!$L$20+1,1,12))-SUM(OFFSET('Monthly Cash Flow'!K$36,0,Assumptions!$L$20+1,1,12)) -> -59.47 | N25: GP Equity | O25: =+Waterfall!G164 -> 0.071606448 | P25: =+Waterfall!G163 -> 1.7510529 | Q25: =-Waterfall!G138 -> 317.64464 | R25: =+Waterfall!G161 -> 238.56792 | T25: =T24+0.25% -> 0.0575 | U25: 0.99136691 | V25: 1.3148927 | W25: 1.319717 | X25: 1.3364792
B26: Total Leveraged Basis | C26: =SUM(C23:C25) -> 30936 | D26: =C26/F7*1000 -> 746.00304 | E26: =SUM(E23:E25) -> 41010.385 | F26: =E26/F7*1000 -> 988.94078 | H26: ULA Tax | L26: =L23*-5% -> -2840.476
H27: Gross Exit Value (Post Abatement/TI/LC Credit, ULA) | K27: =L27/F7*1000 -> 1299.997 | L27: =+L23+SUM(L24:L26) -> 53909.574 | N27: Free Cash Flow Hold Back
B28: Financing Assumptions (Acquisition Loan) | O28: Start | P28: End
B29: Total Debt | F29: =+F50 -> 21795.794 | H29: Total Gross Exit Proceeds | K29: =L29/F7*1000 -> 1299.997 | L29: =L27 -> 53909.574 | N29: Holdback | O29: 1 | P29: 25 | T29: Sensitivity Chart - Sales Date vs Cap Rate
B30: Total Equity | F30: =+F51-F29 -> 16705.367 | H30: Sales Costs | K30: 0.0125 | L30: =-L29*K30 -> -673.86968 | U30: =EOMONTH($I$6,U7-1) -> 45291 | V30: =EOMONTH($I$6,V7-1) -> 45473 | W30: =EOMONTH($I$6,W7-1) -> 45565 | X30: =EOMONTH($I$6,X7-1) -> 45657
B31: Interest Rate | C31: Floating Rate | D31: 525 | E31: =LIBOR!M34 -> 0.0012929 | F31: =+D32 -> 0.09 | H31: Net Exit Proceeds | K31: =L31/F7*1000 -> 1283.747 | L31: =SUM(L29:L30) -> 53235.704 | T31: =T8 -> 0.0425 | U31: =TEXT(U8,"0.0%")&" / "&TEXT(U19,"0.0x") -> 9.0% / 1.8x | V31: =TEXT(V8,"0.0%")&" / "&TEXT(V19,"0.0x") -> 11.4% / 2.3x | W31: =TEXT(W8,"0.0%")&" / "&TEXT(W19,"0.0x") -> 11.1% / 2.3x | X31: =TEXT(X8,"0.0%")&" / "&TEXT(X19,"0.0x") -> 10.9% / 2.3x | AE31: TEXT(V8,"0.0%")&" / "&TEXT(V19,"0.0x")
B32: Loan Closing Month | C32: Fixed Rate | D32: 0.09 | F32: 0 | T32: =T9 -> 0.045 | U32: =TEXT(U9,"0.0%")&" / "&TEXT(U20,"0.0x") -> 7.4% / 1.7x | V32: =TEXT(V9,"0.0%")&" / "&TEXT(V20,"0.0x") -> 10.1% / 2.1x | W32: =TEXT(W9,"0.0%")&" / "&TEXT(W20,"0.0x") -> 9.8% / 2.1x | X32: =TEXT(X9,"0.0%")&" / "&TEXT(X20,"0.0x") -> 9.6% / 2.1x
B33: Libor Floor | C33: Floor | D33: 0.005 | H33: Unleveraged Sources and Uses | T33: =T10 -> 0.0475 | U33: =TEXT(U10,"0.0%")&" / "&TEXT(U21,"0.0x") -> 5.9% / 1.5x | V33: =TEXT(V10,"0.0%")&" / "&TEXT(V21,"0.0x") -> 8.7% / 1.9x | W33: =TEXT(W10,"0.0%")&" / "&TEXT(W21,"0.0x") -> 8.5% / 1.9x | X33: =TEXT(X10,"0.0%")&" / "&TEXT(X21,"0.0x") -> 8.4% / 1.9x
B34: Servicing Fee | F34: 0 | H34: Project Uses | J34: Amount | K34: % | L34: $ Per NRSF | T34: =T11 -> 0.05 | U34: =TEXT(U11,"0.0%")&" / "&TEXT(U22,"0.0x") -> 4.4% / 1.4x | V34: =TEXT(V11,"0.0%")&" / "&TEXT(V22,"0.0x") -> 7.4% / 1.7x | W34: =TEXT(W11,"0.0%")&" / "&TEXT(W22,"0.0x") -> 7.2% / 1.7x | X34: =TEXT(X11,"0.0%")&" / "&TEXT(X22,"0.0x") -> 7.2% / 1.8x
B35: Loan Fees (Bank And Broker) | E35: 0.01 | F35: =C24 -> 570 | H35: Purchase Price | J35: ='Monthly Cash Flow'!$I$18 -> 30000 | K35: =J35/$J$44 -> 0.79923747 | L35: =J35/F7*1000 -> 723.43196 | T35: =T12 -> 0.0525 | U35: =TEXT(U12,"0.0%")&" / "&TEXT(U23,"0.0x") -> 2.9% / 1.2x | V35: =TEXT(V12,"0.0%")&" / "&TEXT(V23,"0.0x") -> 6.2% / 1.6x | W35: =TEXT(W12,"0.0%")&" / "&TEXT(W23,"0.0x") -> 6.0% / 1.6x | X35: =TEXT(X12,"0.0%")&" / "&TEXT(X23,"0.0x") -> 6.0% / 1.6x
B36: Exit Fee | E36: 0.005 | F36: =+IF(E1=0,0,E36*F29) -> 108.97897 | H36: Closing Costs | J36: ='Monthly Cash Flow'!$I$19 -> 206 | K36: =J36/$J$44 -> 0.0054880973 | L36: =J36/F7*1000 -> 4.9675661 | T36: =T13 -> 0.055 | U36: =TEXT(U13,"0.0%")&" / "&TEXT(U24,"0.0x") -> 1.4% / 1.1x | V36: =TEXT(V13,"0.0%")&" / "&TEXT(V24,"0.0x") -> 4.9% / 1.4x | W36: =TEXT(W13,"0.0%")&" / "&TEXT(W24,"0.0x") -> 4.8% / 1.4x | X36: =TEXT(X13,"0.0%")&" / "&TEXT(X24,"0.0x") -> 4.8% / 1.5x
B37: Loan Closing Costs | E37: =+F37/F29 -> 0 | F37: 0 | H37: Operating Losses | J37: =+'Monthly Cash Flow'!I88 -> 499.20616 | K37: =J37/$J$44 -> 0.013299476 | L37: =J37/F7*1000 -> 12.038056 | T37: =T14 -> 0.0575 | U37: =TEXT(U14,"0.0%")&" / "&TEXT(U25,"0.0x") -> -0.1% / 1.0x | V37: =TEXT(V14,"0.0%")&" / "&TEXT(V25,"0.0x") -> 3.7% / 1.3x | W37: =TEXT(W14,"0.0%")&" / "&TEXT(W25,"0.0x") -> 3.6% / 1.3x | X37: =TEXT(X14,"0.0%")&" / "&TEXT(X25,"0.0x") -> 3.7% / 1.3x
B38: Loan Extension Fee | C38: 48 | D38: 999 | E38: 0.005 | F38: =+IF(E1=0,0,E38*F29) -> 108.97897 | H38: =+B17 -> CapEx | J38: ='Monthly Cash Flow'!$I26 -> 2314.3238 | K38: =J38/$J$44 -> 0.061656476 | L38: =J38/F7*1000 -> 55.808526
B39: I/O Period (Months) | C39: =EOMONTH(I6,C38) -> 44043 | F39: 60 | H39: =+B18 -> Soft Costs | J39: ='Monthly Cash Flow'!$I29 -> 823.309 | K39: =J39/$J$44 -> 0.02193398 | L39: =J39/F7*1000 -> 19.853601
B40: Amortization Period (Years) | E40: 30 | F40: =(E40*12) -> 360 | H40: =+B19 -> Contingency | J40: ='Monthly Cash Flow'!$I30 -> 0 | K40: =J40/$J$44 -> 0 | L40: =J40/F7*1000 -> 0
B41: TI/LC Force Funding | E41: =EOMONTH($I$6,F41-1) -> 43465 | F41: 30 | H41: =+B20 -> Capital Reserves | J41: =+'Monthly Cash Flow'!I39 -> 0 | K41: =J41/$J$44 -> 0 | L41: =J41/F7*1000 -> 0
...

Sheet Monthly Cash Flow
K2: 1 | L2: =K2*(1+$F2)^(1/12) -> 1 | M2: =L2*(1+$F2)^(1/12) -> 1 | N2: =M2*(1+$F2)^(1/12) -> 1 | O2: =N2*(1+$F2)^(1/12) -> 1 | P2: =O2*(1+$F2)^(1/12) -> 1 | Q2: =P2*(1+$F2)^(1/12) -> 1 | R2: =Q2*(1+$F2)^(1/12) -> 1 | S2: =R2*(1+$F2)^(1/12) -> 1 | ... BY2: =BX2*(1+$F2)^(1/12) -> 1 | CB2: =CA2*(1+$F2)^(1/12) -> 0 | CC2: =CB2*(1+$F2)^(1/12) -> 0 | CD2: =CC2*(1+$F2)^(1/12) -> 0 | CE2: =CD2*(1+$F2)^(1/12) -> 0 | CF2: =CE2*(1+$F2)^(1/12) -> 0 | CG2: =CF2*(1+$F2)^(1/12) -> 0 | CH2: =CG2*(1+$F2)^(1/12) -> 0 | CI2: =CH2*(1+$F2)^(1/12) -> 0 | ... CR2: =CQ2*(1+$F2)^(1/12) -> 0 | CU2: =CT2*(1+$F2)^(1/12) -> 0 | CV2: =CU2*(1+$F2)^(1/12) -> 0 | CW2: =CV2*(1+$F2)^(1/12) -> 0 | CX2: =CW2*(1+$F2)^(1/12) -> 0 | CY2: =CX2*(1+$F2)^(1/12) -> 0 | CZ2: =CY2*(1+$F2)^(1/12) -> 0 | DA2: =CZ2*(1+$F2)^(1/12) -> 0 | DB2: =DA2*(1+$F2)^(1/12) -> 0 | ... EL2: =EK2*(1+$F2)^(1/12) -> 0 | GS2: =EL2*(1+$F2)^(1/12) -> 0
K3: 1 | L3: =K3*(1+$F3)^(1/12) -> 1 | M3: =L3*(1+$F3)^(1/12) -> 1 | N3: =M3*(1+$F3)^(1/12) -> 1 | O3: =N3*(1+$F3)^(1/12) -> 1 | P3: =O3*(1+$F3)^(1/12) -> 1 | Q3: =P3*(1+$F3)^(1/12) -> 1 | R3: =Q3*(1+$F3)^(1/12) -> 1 | S3: =R3*(1+$F3)^(1/12) -> 1 | ... BY3: =BX3*(1+$F3)^(1/12) -> 1 | CB3: =CA3*(1+$F3)^(1/12) -> 0 | CC3: =CB3*(1+$F3)^(1/12) -> 0 | CD3: =CC3*(1+$F3)^(1/12) -> 0 | CE3: =CD3*(1+$F3)^(1/12) -> 0 | CF3: =CE3*(1+$F3)^(1/12) -> 0 | CG3: =CF3*(1+$F3)^(1/12) -> 0 | CH3: =CG3*(1+$F3)^(1/12) -> 0 | CI3: =CH3*(1+$F3)^(1/12) -> 0 | ... CR3: =CQ3*(1+$F3)^(1/12) -> 0 | CU3: =CT3*(1+$F3)^(1/12) -> 0 | CV3: =CU3*(1+$F3)^(1/12) -> 0 | CW3: =CV3*(1+$F3)^(1/12) -> 0 | CX3: =CW3*(1+$F3)^(1/12) -> 0 | CY3: =CX3*(1+$F3)^(1/12) -> 0 | CZ3: =CY3*(1+$F3)^(1/12) -> 0 | DA3: =CZ3*(1+$F3)^(1/12) -> 0 | DB3: =DA3*(1+$F3)^(1/12) -> 0 | ... EL3: =EK3*(1+$F3)^(1/12) -> 0 | GS3: =EL3*(1+$F3)^(1/12) -> 0
K4: 1 | L4: =K4*(1+$F4)^(1/12) -> 1 | M4: =L4*(1+$F4)^(1/12) -> 1 | N4: =M4*(1+$F4)^(1/12) -> 1 | O4: =N4*(1+$F4)^(1/12) -> 1 | P4: =O4*(1+$F4)^(1/12) -> 1 | Q4: =P4*(1+$F4)^(1/12) -> 1 | R4: =Q4*(1+$F4)^(1/12) -> 1 | S4: =R4*(1+$F4)^(1/12) -> 1 | ... BY4: =BX4*(1+$F4)^(1/12) -> 1 | CB4: =CA4*(1+$F4)^(1/12) -> 0 | CC4: =CB4*(1+$F4)^(1/12) -> 0 | CD4: =CC4*(1+$F4)^(1/12) -> 0 | CE4: =CD4*(1+$F4)^(1/12) -> 0 | CF4: =CE4*(1+$F4)^(1/12) -> 0 | CG4: =CF4*(1+$F4)^(1/12) -> 0 | CH4: =CG4*(1+$F4)^(1/12) -> 0 | CI4: =CH4*(1+$F4)^(1/12) -> 0 | ... CR4: =CQ4*(1+$F4)^(1/12) -> 0 | CU4: =CT4*(1+$F4)^(1/12) -> 0 | CV4: =CU4*(1+$F4)^(1/12) -> 0 | CW4: =CV4*(1+$F4)^(1/12) -> 0 | CX4: =CW4*(1+$F4)^(1/12) -> 0 | CY4: =CX4*(1+$F4)^(1/12) -> 0 | CZ4: =CY4*(1+$F4)^(1/12) -> 0 | DA4: =CZ4*(1+$F4)^(1/12) -> 0 | DB4: =DA4*(1+$F4)^(1/12) -> 0 | ... EL4: =EK4*(1+$F4)^(1/12) -> 0 | GS4: =EL4*(1+$F4)^(1/12) -> 0
K5: 1 | L5: =K5*(1+$F5)^(1/12) -> 1 | M5: =L5*(1+$F5)^(1/12) -> 1 | N5: =M5*(1+$F5)^(1/12) -> 1 | O5: =N5*(1+$F5)^(1/12) -> 1 | P5: =O5*(1+$F5)^(1/12) -> 1 | Q5: =P5*(1+$F5)^(1/12) -> 1 | R5: =Q5*(1+$F5)^(1/12) -> 1 | S5: =R5*(1+$F5)^(1/12) -> 1 | ... BY5: =BX5*(1+$F5)^(1/12) -> 1 | CB5: =CA5*(1+$F5)^(1/12) -> 0 | CC5: =CB5*(1+$F5)^(1/12) -> 0 | CD5: =CC5*(1+$F5)^(1/12) -> 0 | CE5: =CD5*(1+$F5)^(1/12) -> 0 | CF5: =CE5*(1+$F5)^(1/12) -> 0 | CG5: =CF5*(1+$F5)^(1/12) -> 0 | CH5: =CG5*(1+$F5)^(1/12) -> 0 | CI5: =CH5*(1+$F5)^(1/12) -> 0 | ... CR5: =CQ5*(1+$F5)^(1/12) -> 0 | CU5: =CT5*(1+$F5)^(1/12) -> 0 | CV5: =CU5*(1+$F5)^(1/12) -> 0 | CW5: =CV5*(1+$F5)^(1/12) -> 0 | CX5: =CW5*(1+$F5)^(1/12) -> 0 | CY5: =CX5*(1+$F5)^(1/12) -> 0 | CZ5: =CY5*(1+$F5)^(1/12) -> 0 | DA5: =CZ5*(1+$F5)^(1/12) -> 0 | DB5: =DA5*(1+$F5)^(1/12) -> 0 | ... EL5: =EK5*(1+$F5)^(1/12) -> 0 | GS5: =EL5*(1+$F5)^(1/12) -> 0
K6: 1 | L6: =$K6*(1+$F6)^(L$13/12) -> 1 | M6: =$K6*(1+$F6)^(M$13/12) -> 1 | N6: =$K6*(1+$F6)^(N$13/12) -> 1 | O6: =$K6*(1+$F6)^(O$13/12) -> 1 | P6: =$K6*(1+$F6)^(P$13/12) -> 1 | Q6: =$K6*(1+$F6)^(Q$13/12) -> 1 | R6: =$K6*(1+$F6)^(R$13/12) -> 1 | S6: =$K6*(1+$F6)^(S$13/12) -> 1 | ... BY6: =$K6*(1+$F6)^(BY$13/12) -> 1 | CB6: =$K6*(1+$F6)^(CB$13/12) -> 1 | CC6: =$K6*(1+$F6)^(CC$13/12) -> 1 | CD6: =$K6*(1+$F6)^(CD$13/12) -> 1 | CE6: =$K6*(1+$F6)^(CE$13/12) -> 1 | CF6: =$K6*(1+$F6)^(CF$13/12) -> 1 | CG6: =$K6*(1+$F6)^(CG$13/12) -> 1 | CH6: =$K6*(1+$F6)^(CH$13/12) -> 1 | CI6: =$K6*(1+$F6)^(CI$13/12) -> 1 | ... CR6: =$K6*(1+$F6)^(CR$13/12) -> 1 | CU6: =$K6*(1+$F6)^(CU$13/12) -> 1 | CV6: =$K6*(1+$F6)^(CV$13/12) -> 1 | CW6: =$K6*(1+$F6)^(CW$13/12) -> 1 | CX6: =$K6*(1+$F6)^(CX$13/12) -> 1 | CY6: =$K6*(1+$F6)^(CY$13/12) -> 1 | CZ6: =$K6*(1+$F6)^(CZ$13/12) -> 1 | DA6: =$K6*(1+$F6)^(DA$13/12) -> 1 | DB6: =$K6*(1+$F6)^(DB$13/12) -> 1 | ... EL6: =$K6*(1+$F6)^(EL$13/12) -> 1 | GS6: =$K6*(1+$F6)^(GT$13/12) -> 1
B7: LIBOR Curve | K7: =IFERROR(INDEX(LIBOR!$M$3:$M$122,MATCH('Monthly Cash Flow'!K$15,LIBOR!$N$3:$N$122,0)),J7) -> 0 | L7: =IFERROR(INDEX(LIBOR!$M$3:$M$122,MATCH('Monthly Cash Flow'!L$15,LIBOR!$N$3:$N$122,0)),K7) -> 0 | M7: =IFERROR(INDEX(LIBOR!$M$3:$M$122,MATCH('Monthly Cash Flow'!M$15,LIBOR!$N$3:$N$122,0)),L7) -> 0 | N7: =IFERROR(INDEX(LIBOR!$M$3:$M$122,MATCH('Monthly Cash Flow'!N$15,LIBOR!$N$3:$N$122,0)),M7) -> 0 | O7: =IFERROR(INDEX(LIBOR!$M$3:$M$122,MATCH('Monthly Cash Flow'!O$15,LIBOR!$N$3:$N$122,0)),N7) -> 0 | P7: =IFERROR(INDEX(LIBOR!$M$3:$M$122,MATCH('Monthly Cash Flow'!P$15,LIBOR!$N$3:$N$122,0)),O7) -> 0 | Q7: =IFERROR(INDEX(LIBOR!$M$3:$M$122,MATCH('Monthly Cash Flow'!Q$15,LIBOR!$N$3:$N$122,0)),P7) -> 0 | R7: =IFERROR(INDEX(LIBOR!$M$3:$M$122,MATCH('Monthly Cash Flow'!R$15,LIBOR!$N$3:$N$122,0)),Q7) -> 0 | ... BY7: =IFERROR(INDEX(LIBOR!$M$3:$M$122,MATCH('Monthly Cash Flow'!BY$15,LIBOR!$N$3:$N$122,0)),BX7) -> 0.0015071 | CB7: =IFERROR(INDEX(LIBOR!$M$3:$M$122,MATCH('Monthly Cash Flow'!CB$15,LIBOR!$N$3:$N$122,0)),CA7) -> 0.0015849 | CC7: =IFERROR(INDEX(LIBOR!$M$3:$M$122,MATCH('Monthly Cash Flow'!CC$15,LIBOR!$N$3:$N$122,0)),CB7) -> 0.0015552 | CD7: =IFERROR(INDEX(LIBOR!$M$3:$M$122,MATCH('Monthly Cash Flow'!CD$15,LIBOR!$N$3:$N$122,0)),CC7) -> 0.001517 | CE7: =IFERROR(INDEX(LIBOR!$M$3:$M$122,MATCH('Monthly Cash Flow'!CE$15,LIBOR!$N$3:$N$122,0)),CD7) -> 0.0014938 | CF7: =IFERROR(INDEX(LIBOR!$M$3:$M$122,MATCH('Monthly Cash Flow'!CF$15,LIBOR!$N$3:$N$122,0)),CE7) -> 0.0014702 | CG7: =IFERROR(INDEX(LIBOR!$M$3:$M$122,MATCH('Monthly Cash Flow'!CG$15,LIBOR!$N$3:$N$122,0)),CF7) -> 0.0014851 | CH7: =IFERROR(INDEX(LIBOR!$M$3:$M$122,MATCH('Monthly Cash Flow'!CH$15,LIBOR!$N$3:$N$122,0)),CG7) -> 0.0015347 | CI7: =IFERROR(INDEX(LIBOR!$M$3:$M$122,MATCH('Monthly Cash Flow'!CI$15,LIBOR!$N$3:$N$122,0)),CH7) -> 0.0015907 | ... CR7: =IFERROR(INDEX(LIBOR!$M$3:$M$122,MATCH('Monthly Cash Flow'!CR$15,LIBOR!$N$3:$N$122,0)),CQ7) -> 0.0495866 | CU7: =IFERROR(INDEX(LIBOR!$M$3:$M$122,MATCH('Monthly Cash Flow'!CU$15,LIBOR!$N$3:$N$122,0)),CT7) -> 0.0471558 | CV7: =IFERROR(INDEX(LIBOR!$M$3:$M$122,MATCH('Monthly Cash Flow'!CV$15,LIBOR!$N$3:$N$122,0)),CU7) -> 0.0461346 | CW7: =IFERROR(INDEX(LIBOR!$M$3:$M$122,MATCH('Monthly Cash Flow'!CW$15,LIBOR!$N$3:$N$122,0)),CV7) -> 0.0450652 | CX7: =IFERROR(INDEX(LIBOR!$M$3:$M$122,MATCH('Monthly Cash Flow'!CX$15,LIBOR!$N$3:$N$122,0)),CW7) -> 0.0440782 | CY7: =IFERROR(INDEX(LIBOR!$M$3:$M$122,MATCH('Monthly Cash Flow'!CY$15,LIBOR!$N$3:$N$122,0)),CX7) -> 0.0429112 | CZ7: =IFERROR(INDEX(LIBOR!$M$3:$M$122,MATCH('Monthly Cash Flow'!CZ$15,LIBOR!$N$3:$N$122,0)),CY7) -> 0.0416869 | DA7: =IFERROR(INDEX(LIBOR!$M$3:$M$122,MATCH('Monthly Cash Flow'!DA$15,LIBOR!$N$3:$N$122,0)),CZ7) -> 0.0405943 | DB7: =IFERROR(INDEX(LIBOR!$M$3:$M$122,MATCH('Monthly Cash Flow'!DB$15,LIBOR!$N$3:$N$122,0)),DA7) -> 0.0394062 | ... EL7: =IFERROR(INDEX(LIBOR!$M$3:$M$122,MATCH('Monthly Cash Flow'!EL$15,LIBOR!$N$3:$N$122,0)),EK7) -> 0.0325073 | GS7: =IFERROR(INDEX(LIBOR!$M$3:$M$122,MATCH('Monthly Cash Flow'!GT$15,LIBOR!$N$3:$N$122,0)),EL7) -> 0.0325073
CB9: =SUM(CB22:CD22)*1000 -> 0
B10: =+Assumptions!B2 -> Chapman Plaza | BN10: =BM13+120 -> 174
B11: Monthly Project Cash Flow | CL11: 1 | CM11: =CL11+1 -> 2 | CN11: =CM11+1 -> 3 | CO11: =CN11+1 -> 4 | CP11: =CO11+1 -> 5 | CQ11: =CP11+1 -> 6 | CR11: =CQ11+1 -> 7 | CS11: =CR11+1 -> 8 | CT11: =CS11+1 -> 9 | ... HA11: =GZ11+1 -> 120 | HG11: =HF11+1 -> 1
B12: ($ in thousands, except psf amounts) | L12: Actuals | M12: Actuals | N12: Actuals | O12: Actuals | P12: Actuals | Q12: Actuals | R12: Actuals | S12: Actuals | T12: Actuals | U12: Actuals | V12: Actuals | W12: Actuals | X12: Actuals | Y12: Actuals | Z12: Actuals | AA12: Actuals | AB12: Actuals | AC12: Actuals | AD12: Actuals | AE12: Actuals | AF12: Actuals | AG12: Actuals | AH12: Actuals | AI12: Actuals | AJ12: Actuals | AK12: Actuals | AL12: Actuals | AM12: Actuals | AN12: Actuals | AO12: Actuals | AP12: Actuals | AQ12: Actuals | AR12: Actuals | AS12: Actuals | AT12: Actuals | AU12: Actuals | AV12: Actuals | AW12: Actuals | AX12: Actuals | AY12: Actuals | AZ12: Actuals | BA12: Actuals | BB12: Actuals | BC12: Actuals | BD12: Actuals | BE12: Actuals | BF12: Actuals | BG12: Actuals | BH12: Actuals | BI12: Actuals | BJ12: Actuals | BK12: Actuals | BL12: Actuals | BM12: Actuals | BN12: Actuals | BO12: Actuals | BP12: Actuals | BQ12: Actuals | BR12: Actuals | BS12: Actuals | BT12: Actuals | BU12: Actuals | BV12: Actuals | BW12: Actuals | BX12: Actuals | BY12: Actuals | BZ12: Actuals | CA12: Actuals | CB12: Actuals | CC12: Actuals | CD12: Actuals | CE12: Actuals | CF12: Actuals | CG12: Actuals | CH12: Actuals | CI12: Proforma | CJ12: Proforma | CK12: Proforma | CL12: Proforma | CM12: Proforma | CN12: Proforma | CO12: Proforma | CP12: Proforma | CQ12: Proforma | CR12: Proforma | CS12: Proforma | CT12: Proforma | CU12: Proforma | CV12: Proforma | CW12: Proforma | CX12: Proforma | CY12: Proforma | CZ12: Proforma | DA12: Proforma | DB12: Proforma | DC12: Proforma | DD12: Proforma | DE12: Proforma | DF12: Proforma | DG12: Proforma | DH12: Proforma | DI12: Proforma | DJ12: Proforma | DK12: Proforma | DL12: Proforma | DM12: Proforma | DN12: Proforma | DO12: Proforma | DP12: Proforma | DQ12: Proforma | DR12: Proforma | DS12: Proforma | DT12: Proforma | DU12: Proforma | DV12: Proforma | DW12: Proforma | DX12: Proforma | DY12: Proforma | DZ12: Proforma | EA12: Proforma | EB12: Proforma | EC12: Proforma | ED12: Proforma | EE12: Proforma | EF12: Proforma | EG12: Proforma | EH12: Proforma | EI12: Proforma | EJ12: Proforma | EK12: Proforma | EL12: Proforma | EM12: Proforma | EN12: Proforma | EO12: Proforma | EP12: Proforma | EQ12: Proforma | ER12: Proforma | ES12: Proforma | ET12: Proforma | EU12: Proforma | EV12: Proforma | EW12: Proforma | EX12: Proforma | EY12: Proforma | EZ12: Proforma | FA12: Proforma | FB12: Proforma | FC12: Proforma | FD12: Proforma | FE12: Proforma | FF12: Proforma | FG12: Proforma | FH12: Proforma | FI12: Proforma | FJ12: Proforma | FK12: Proforma | FL12: Proforma | FM12: Proforma | FN12: Proforma | FO12: Proforma | FP12: Proforma | FQ12: Proforma | FR12: Proforma | FS12: Proforma | FT12: Proforma | FU12: Proforma | FV12: Proforma | FW12: Proforma | FX12: Proforma | FY12: Proforma | FZ12: Proforma | GA12: Proforma | GB12: Proforma | GC12: Proforma | GD12: Proforma | GE12: Proforma | GF12: Proforma | GG12: Proforma | GH12: Proforma | GI12: Proforma | GJ12: Proforma | GK12: Proforma | GL12: Proforma | GM12: Proforma | GN12: Proforma | GO12: Proforma | GP12: Proforma | GQ12: Proforma | GR12: Proforma | GS12: Proforma | GT12: Proforma | GU12: Proforma | GV12: Proforma | GW12: Proforma | GX12: Proforma | GY12: Proforma | GZ12: Proforma | HA12: Proforma | HF12: 1
B13: Current Month | C13: 79 | D13: =HLOOKUP(C13,$L$13:$GT$15,3) -> 44957 | K13: =Assumptions!J7 -> 0 | L13: =K13+1 -> 1 | M13: =L13+1 -> 2 | N13: =M13+1 -> 3 | O13: =N13+1 -> 4 | P13: =O13+1 -> 5 | Q13: =P13+1 -> 6 | R13: =Q13+1 -> 7 | S13: =R13+1 -> 8 | ... HA13: =GZ13+1 -> 198 | HH13: Annual Project Cash Flows
K14: =ROUNDUP(K13/12,0) -> 0 | L14: =ROUNDUP(L13/12,0) -> 1 | M14: =ROUNDUP(M13/12,0) -> 1 | N14: =ROUNDUP(N13/12,0) -> 1 | O14: =ROUNDUP(O13/12,0) -> 1 | P14: =ROUNDUP(P13/12,0) -> 1 | Q14: =ROUNDUP(Q13/12,0) -> 1 | R14: =ROUNDUP(R13/12,0) -> 1 | ... HA14: =ROUNDUP(HA13/12,0) -> 17 | HN14: 0 | HO14: =HN14+1 -> 1 | HP14: =HO14+1 -> 2 | HQ14: =HP14+1 -> 3 | HR14: =HQ14+1 -> 4 | HS14: =HR14+1 -> 5 | HT14: =HS14+1 -> 6 | HU14: =HT14+1 -> 7 | HV14: =HU14+1 -> 8
K15: =+Assumptions!I6 -> 42552 | L15: =EOMONTH(K15,0) -> 42582 | M15: =EOMONTH(L15,1) -> 42613 | N15: =EOMONTH(M15,1) -> 42643 | O15: =EOMONTH(N15,1) -> 42674 | P15: =EOMONTH(O15,1) -> 42704 | Q15: =EOMONTH(P15,1) -> 42735 | R15: =EOMONTH(Q15,1) -> 42766 | S15: =EOMONTH(R15,1) -> 42794 | T15: =EOMONTH(S15,1) -> 42825 | ... HA15: =EOMONTH(GZ15,1) -> 48579 | HG15: 1 | HL15: 12 Months Ending: | HN15: =IF(HN$14=0,EOMONTH($K$15,0),EOMONTH(HM$15,12)) -> 42582 | HO15: =IF(HO$14=0,EOMONTH($K$15,0),EOMONTH(HN$15,12)) -> 42947 | HP15: =IF(HP$14=0,EOMONTH($K$15,0),EOMONTH(HO$15,12)) -> 43312 | HQ15: =IF(HQ$14=0,EOMONTH($K$15,0),EOMONTH(HP$15,12)) -> 43677 | HR15: =IF(HR$14=0,EOMONTH($K$15,0),EOMONTH(HQ$15,12)) -> 44043 | HS15: =IF(HS$14=0,EOMONTH($K$15,0),EOMONTH(HR$15,12)) -> 44408 | HT15: =IF(HT$14=0,EOMONTH($K$15,0),EOMONTH(HS$15,12)) -> 44773 | HU15: =IF(HU$14=0,EOMONTH($K$15,0),EOMONTH(HT$15,12)) -> 45138 | HV15: =IF(HV$14=0,EOMONTH($K$15,0),EOMONTH(HU$15,12)) -> 45504
B16: Unleveraged Costs | I16: Total | HF16: x | HG16: =HG15+1 -> 2 | HH16: =B16 -> Unleveraged Costs | HL16: Total
B17: Acquisition Costs | HF17: x | HG17: =HG16+1 -> 3 | HH17: =B17 -> Acquisition Costs
B18: =Assumptions!B12 -> Purchase Price | I18: =SUM(K18:GT18) -> 30000 | K18: =Assumptions!C12 -> 30000 | L18: 0 | M18: 0 | N18: 0 | O18: 0 | P18: 0 | Q18: 0 | R18: 0 | S18: 0 | T18: 0 | U18: 0 | V18: 0 | W18: 0 | X18: 0 | Y18: 0 | Z18: 0 | AA18: 0 | AB18: 0 | AC18: 0 | AD18: 0 | AE18: 0 | AF18: 0 | AG18: 0 | AH18: 0 | AI18: 0 | AJ18: 0 | AK18: 0 | AL18: 0 | AM18: 0 | AN18: 0 | AO18: 0 | AP18: 0 | AQ18: 0 | AR18: 0 | AS18: 0 | AT18: 0 | AU18: 0 | AV18: 0 | AW18: 0 | AX18: 0 | AY18: 0 | AZ18: 0 | BA18: 0 | BB18: 0 | BC18: 0 | BD18: 0 | BE18: 0 | BF18: 0 | BG18: 0 | BH18: 0 | BI18: 0 | BJ18: 0 | BK18: 0 | BL18: 0 | BM18: 0 | BN18: 0 | BO18: 0 | BP18: 0 | BQ18: 0 | BR18: 0 | BS18: 0 | BT18: 0 | BU18: 0 | BV18: 0 | BW18: 0 | BX18: 0 | BY18: 0 | BZ18: 0 | CA18: 0 | CB18: 0 | CC18: 0 | CD18: 0 | CE18: 0 | CF18: 0 | CG18: 0 | CH18: 0 | CI18: 0 | CJ18: 0 | CK18: 0 | CL18: 0 | CM18: 0 | CN18: 0 | CO18: 0 | CP18: 0 | CQ18: 0 | CR18: 0 | CS18: 0 | CT18: 0 | CU18: 0 | CV18: 0 | CW18: 0 | CX18: 0 | CY18: 0 | CZ18: 0 | DA18: 0 | DB18: 0 | DC18: 0 | DD18: 0 | DE18: 0 | DF18: 0 | DG18: 0 | DH18: 0 | DI18: 0 | DJ18: 0 | DK18: 0 | DL18: 0 | DM18: 0 | DN18: 0 | DO18: 0 | DP18: 0 | DQ18: 0 | DR18: 0 | DS18: 0 | DT18: 0 | DU18: 0 | DV18: 0 | DW18: 0 | DX18: 0 | DY18: 0 | DZ18: 0 | EA18: 0 | EB18: 0 | EC18: 0 | ED18: 0 | EE18: 0 | EF18: 0 | EG18: 0 | EH18: 0 | EI18: 0 | EJ18: 0 | EK18: 0 | EL18: 0 | EM18: 0 | EN18: 0 | EO18: 0 | EP18: 0 | EQ18: 0 | ER18: 0 | ES18: 0 | ET18: 0 | EU18: 0 | EV18: 0 | EW18: 0 | EX18: 0 | EY18: 0 | EZ18: 0 | FA18: 0 | FB18: 0 | FC18: 0 | FD18: 0 | FE18: 0 | FF18: 0 | FG18: 0 | FH18: 0 | FI18: 0 | FJ18: 0 | FK18: 0 | FL18: 0 | FM18: 0 | FN18: 0 | FO18: 0 | FP18: 0 | FQ18: 0 | FR18: 0 | FS18: 0 | FT18: 0 | FU18: 0 | FV18: 0 | FW18: 0 | FX18: 0 | FY18: 0 | FZ18: 0 | GA18: 0 | GB18: 0 | GC18: 0 | GD18: 0 | GE18: 0 | GF18: 0 | GG18: 0 | GH18: 0 | GI18: 0 | GJ18: 0 | GK18: 0 | GL18: 0 | GM18: 0 | GN18: 0 | GO18: 0 | GP18: 0 | GQ18: 0 | GR18: 0 | GS18: 0 | GT18: 0 | GU18: 0 | GV18: 0 | GW18: 0 | GX18: 0 | GY18: 0 | GZ18: 0 | HA18: 0 | HF18: x | HG18: =HG17+1 -> 4 | HH18: =B18 -> Purchase Price | HL18: =SUM(HN18:HV18) -> 30000 | HN18: =SUMIF($K$14:$GT$14,HN$14,$K18:$GT18) -> 30000 | HO18: =SUMIF($K$14:$GT$14,HO$14,$K18:$GT18) -> 0 | HP18: =SUMIF($K$14:$GT$14,HP$14,$K18:$GT18) -> 0 | HQ18: =SUMIF($K$14:$GT$14,HQ$14,$K18:$GT18) -> 0 | HR18: =SUMIF($K$14:$GT$14,HR$14,$K18:$GT18) -> 0 | HS18: =SUMIF($K$14:$GT$14,HS$14,$K18:$GT18) -> 0 | HT18: =SUMIF($K$14:$GT$14,HT$14,$K18:$GT18) -> 0 | HU18: =SUMIF($K$14:$GT$14,HU$14,$K18:$GT18) -> 0 | HV18: =SUMIF($K$14:$GT$14,HV$14,$K18:$GT18) -> 0
B19: =Assumptions!B13 -> 0.0068666667 | I19: =SUM(K19:GT19) -> 206 | K19: =Assumptions!C13 -> 206 | L19: 0 | M19: 0 | N19: 0 | O19: 0 | P19: 0 | Q19: 0 | R19: 0 | S19: 0 | T19: 0 | U19: 0 | V19: 0 | W19: 0 | X19: 0 | Y19: 0 | Z19: 0 | AA19: 0 | AB19: 0 | AC19: 0 | AD19: 0 | AE19: 0 | AF19: 0 | AG19: 0 | AH19: 0 | AI19: 0 | AJ19: 0 | AK19: 0 | AL19: 0 | AM19: 0 | AN19: 0 | AO19: 0 | AP19: 0 | AQ19: 0 | AR19: 0 | AS19: 0 | AT19: 0 | AU19: 0 | AV19: 0 | AW19: 0 | AX19: 0 | AY19: 0 | AZ19: 0 | BA19: 0 | BB19: 0 | BC19: 0 | BD19: 0 | BE19: 0 | BF19: 0 | BG19: 0 | BH19: 0 | BI19: 0 | BJ19: 0 | BK19: 0 | BL19: 0 | BM19: 0 | BN19: 0 | BO19: 0 | BP19: 0 | BQ19: 0 | BR19: 0 | BS19: 0 | BT19: 0 | BU19: 0 | BV19: 0 | BW19: 0 | BX19: 0 | BY19: 0 | BZ19: 0 | CA19: 0 | CB19: 0 | CC19: 0 | CD19: 0 | CE19: 0 | CF19: 0 | CG19: 0 | CH19: 0 | CI19: 0 | CJ19: 0 | CK19: 0 | CL19: 0 | CM19: 0 | CN19: 0 | CO19: 0 | CP19: 0 | CQ19: 0 | CR19: 0 | CS19: 0 | CT19: 0 | CU19: 0 | CV19: 0 | CW19: 0 | CX19: 0 | CY19: 0 | CZ19: 0 | DA19: 0 | DB19: 0 | DC19: 0 | DD19: 0 | DE19: 0 | DF19: 0 | DG19: 0 | DH19: 0 | DI19: 0 | DJ19: 0 | DK19: 0 | DL19: 0 | DM19: 0 | DN19: 0 | DO19: 0 | DP19: 0 | DQ19: 0 | DR19: 0 | DS19: 0 | DT19: 0 | DU19: 0 | DV19: 0 | DW19: 0 | DX19: 0 | DY19: 0 | DZ19: 0 | EA19: 0 | EB19: 0 | EC19: 0 | ED19: 0 | EE19: 0 | EF19: 0 | EG19: 0 | EH19: 0 | EI19: 0 | EJ19: 0 | EK19: 0 | EL19: 0 | EM19: 0 | EN19: 0 | EO19: 0 | EP19: 0 | EQ19: 0 | ER19: 0 | ES19: 0 | ET19: 0 | EU19: 0 | EV19: 0 | EW19: 0 | EX19: 0 | EY19: 0 | EZ19: 0 | FA19: 0 | FB19: 0 | FC19: 0 | FD19: 0 | FE19: 0 | FF19: 0 | FG19: 0 | FH19: 0 | FI19: 0 | FJ19: 0 | FK19: 0 | FL19: 0 | FM19: 0 | FN19: 0 | FO19: 0 | FP19: 0 | FQ19: 0 | FR19: 0 | FS19: 0 | FT19: 0 | FU19: 0 | FV19: 0 | FW19: 0 | FX19: 0 | FY19: 0 | FZ19: 0 | GA19: 0 | GB19: 0 | GC19: 0 | GD19: 0 | GE19: 0 | GF19: 0 | GG19: 0 | GH19: 0 | GI19: 0 | GJ19: 0 | GK19: 0 | GL19: 0 | GM19: 0 | GN19: 0 | GO19: 0 | GP19: 0 | GQ19: 0 | GR19: 0 | GS19: 0 | GT19: 0 | GU19: 0 | GV19: 0 | GW19: 0 | GX19: 0 | GY19: 0 | GZ19: 0 | HA19: 0 | HF19: x | HG19: =HG18+1 -> 5 | HH19: =B19 -> 0.0068666667 | HL19: =SUM(HN19:HV19) -> 206 | HN19: =SUMIF($K$14:$GT$14,HN$14,$K19:$GT19) -> 206 | HO19: =SUMIF($K$14:$GT$14,HO$14,$K19:$GT19) -> 0 | HP19: =SUMIF($K$14:$GT$14,HP$14,$K19:$GT19) -> 0 | HQ19: =SUMIF($K$14:$GT$14,HQ$14,$K19:$GT19) -> 0 | HR19: =SUMIF($K$14:$GT$14,HR$14,$K19:$GT19) -> 0 | HS19: =SUMIF($K$14:$GT$14,HS$14,$K19:$GT19) -> 0 | HT19: =SUMIF($K$14:$GT$14,HT$14,$K19:$GT19) -> 0 | HU19: =SUMIF($K$14:$GT$14,HU$14,$K19:$GT19) -> 0 | HV19: =SUMIF($K$14:$GT$14,HV$14,$K19:$GT19) -> 0
B20: Total Acquisition Costs | I20: =SUM(K20:GT20) -> 30206 | K20: =SUBTOTAL(9,K18:K19) -> 30206 | L20: =SUBTOTAL(9,L18:L19) -> 0 | M20: =SUBTOTAL(9,M18:M19) -> 0 | N20: =SUBTOTAL(9,N18:N19) -> 0 | O20: =SUBTOTAL(9,O18:O19) -> 0 | P20: =SUBTOTAL(9,P18:P19) -> 0 | Q20: =SUBTOTAL(9,Q18:Q19) -> 0 | R20: =SUBTOTAL(9,R18:R19) -> 0 | ... HA20: =SUBTOTAL(9,HA18:HA19) -> 0 | HF20: x | HG20: =HG19+1 -> 6 | HH20: =B20 -> Total Acquisition Costs | HL20: =SUM(HN20:HV20) -> 30206 | HN20: =SUMIF($K$14:$GT$14,HN$14,$K20:$GT20) -> 30206 | HO20: =SUMIF($K$14:$GT$14,HO$14,$K20:$GT20) -> 0 | HP20: =SUMIF($K$14:$GT$14,HP$14,$K20:$GT20) -> 0 | HQ20: =SUMIF($K$14:$GT$14,HQ$14,$K20:$GT20) -> 0 | HR20: =SUMIF($K$14:$GT$14,HR$14,$K20:$GT20) -> 0 | HS20: =SUMIF($K$14:$GT$14,HS$14,$K20:$GT20) -> 0 | HT20: =SUMIF($K$14:$GT$14,HT$14,$K20:$GT20) -> 0 | HU20: =SUMIF($K$14:$GT$14,HU$14,$K20:$GT20) -> 0 | HV20: =SUMIF($K$14:$GT$14,HV$14,$K20:$GT20) -> 0
C21: Start | E21: End | F21: ="Costs to Date"&" - "&TEXT($D$13,"mmm-yy") -> Costs to Date - Jan-23 | G21: New Budget | H21: Budget | HF21: x | HG21: =HG20+1 -> 7
B22: CapEx 2023
B23: Suite 300 Elevator | C23: 80 | E23: 88 | G23: =Assumptions!L76 -> 250 | H23: =G23 -> 250 | I23: =SUMIF($K$13:$GT$13,"<="&Assumptions!$L$17,'Monthly Cash Flow'!K23:GT23) -> 250 | CE23: =IF(AND(CE$13>=$C23,CE$13<=$E23),($H23-SUM($K23:CD23))/(($E23-CE$13+1)),0) -> 0 | CF23: =IF(AND(CF$13>=$C23,CF$13<=$E23),($H23-SUM($K23:CE23))/(($E23-CF$13+1)),0) -> 0 | CG23: =IF(AND(CG$13>=$C23,CG$13<=$E23),($H23-SUM($K23:CF23))/(($E23-CG$13+1)),0) -> 0 | CH23: =IF(AND(CH$13>=$C23,CH$13<=$E23),($H23-SUM($K23:CG23))/(($E23-CH$13+1)),0) -> 0 | CI23: =IF(AND(CI$13>=$C23,CI$13<=$E23),($H23-SUM($K23:CH23))/(($E23-CI$13+1)),0) -> 0 | CJ23: =IF(AND(CJ$13>=$C23,CJ$13<=$E23),($H23-SUM($K23:CI23))/(($E23-CJ$13+1)),0) -> 0 | CK23: =IF(AND(CK$13>=$C23,CK$13<=$E23),($H23-SUM($K23:CJ23))/(($E23-CK$13+1)),0) -> 0 | CL23: =IF(AND(CL$13>=$C23,CL$13<=$E23),($H23-SUM($K23:CK23))/(($E23-CL$13+1)),0) -> 0 | ... GT23: =IF(AND(GT$13>=$C23,GT$13<=$E23),($H23-SUM($K23:GS23))/(($E23-GT$13+1)),0) -> 0 | HF23: x | HG23: =HG22+1 -> 1
B24: Common Area | C24: 80 | E24: 86 | F24: =SUMIF($K$13:$GT$13,"<="&$C$13,'Monthly Cash Flow'!K24:GT24) -> 0 | G24: =Assumptions!L75 -> 240 | H24: =G24 -> 240 | I24: =SUMIF($K$13:$GT$13,"<="&Assumptions!$L$17,'Monthly Cash Flow'!K24:GT24) -> 240 | L24: 0 | M24: 0 | N24: 0 | O24: 0 | P24: 0 | Q24: 0 | R24: 0 | S24: 0 | T24: 0 | U24: 0 | V24: 0 | W24: 0 | X24: 0 | Y24: 0 | Z24: 0 | AA24: 0 | AB24: 0 | AC24: 0 | AD24: 0 | AE24: 0 | AF24: 0 | AG24: 0 | AH24: 0 | AI24: 0 | AJ24: 0 | AK24: 0 | AL24: 0 | AM24: 0 | AN24: 0 | AO24: 0 | AP24: 0 | AQ24: 0 | AR24: 0 | AS24: 0 | AT24: 0 | AU24: 0 | AV24: 0 | AW24: 0 | AX24: 0 | AY24: 0 | AZ24: 0 | BA24: 0 | BB24: 0 | BC24: 0 | BD24: 0 | BE24: 0 | BF24: 0 | BG24: 0 | BH24: 0 | BI24: 0 | BJ24: 0 | BK24: 0 | BL24: =IF(AND(BL$13>=$C24,BL$13<=$E24),($H24-SUM($K24:BK24))/(($E24-BL$13+1)),0) -> 0 | BM24: =IF(AND(BM$13>=$C24,BM$13<=$E24),($H24-SUM($K24:BL24))/(($E24-BM$13+1)),0) -> 0 | BN24: =IF(AND(BN$13>=$C24,BN$13<=$E24),($H24-SUM($K24:BM24))/(($E24-BN$13+1)),0) -> 0 | BO24: =IF(AND(BO$13>=$C24,BO$13<=$E24),($H24-SUM($K24:BN24))/(($E24-BO$13+1)),0) -> 0 | BP24: =IF(AND(BP$13>=$C24,BP$13<=$E24),($H24-SUM($K24:BO24))/(($E24-BP$13+1)),0) -> 0 | BQ24: =IF(AND(BQ$13>=$C24,BQ$13<=$E24),($H24-SUM($K24:BP24))/(($E24-BQ$13+1)),0) -> 0 | BR24: =IF(AND(BR$13>=$C24,BR$13<=$E24),($H24-SUM($K24:BQ24))/(($E24-BR$13+1)),0) -> 0 | BS24: =IF(AND(BS$13>=$C24,BS$13<=$E24),($H24-SUM($K24:BR24))/(($E24-BS$13+1)),0) -> 0 | ... GS24: =IF(AND(GS$13>=$C24,GS$13<=$E24),($H24-SUM($K24:GR24))/(($E24-GS$13+1)),0) -> 0
B25: Historical CapEx Spends | C25: 1 | E25: 66 | F25: =SUMIF($K$13:$GT$13,"<="&$C$13,'Monthly Cash Flow'!K25:GT25) -> 1824.3238 | H25: =SUM(F25:G25) -> 1824.3238 | I25: =SUMIF($K$13:$GT$13,"<="&Assumptions!$L$17,'Monthly Cash Flow'!K25:GT25) -> 1824.3238 | K25: 0 | L25: 0 | M25: 0 | N25: 0 | O25: 0 | P25: 0 | Q25: 0 | R25: 0 | S25: 0 | T25: 0 | U25: 36.0885 | V25: 0 | W25: 47.94 | X25: 0 | Y25: 0 | Z25: 232.8555 | AA25: 0 | AB25: 361.59281 | AC25: 0 | AD25: 0 | AE25: 403.9507 | AF25: 67.99761 | AG25: 145.09164 | AH25: 0 | AI25: 0 | AJ25: 0 | AK25: 0 | AL25: 1.98 | AM25: 0 | AN25: 16.798 | AO25: 0 | AP25: 0 | AQ25: 3.873 | AR25: 0 | AS25: 0 | AT25: 0 | AU25: 0 | AV25: 0 | AW25: 0 | AX25: 0 | AY25: 15.5 | AZ25: 0 | BA25: 0 | BB25: 0 | BC25: 142.1 | BD25: 23.258 | BE25: 0 | BF25: 0 | BG25: 0 | BH25: 0 | BI25: 0 | BJ25: 0 | BK25: 0 | BL25: 0 | BM25: 0 | BN25: 0 | BO25: 0 | BP25: 0 | BQ25: 0 | BR25: =65924/1000 -> 65.924 | BS25: 0 | BT25: 0 | BU25: 0 | BV25: 0 | BW25: 0 | BX25: 0 | BY25: =84080/1000 -> 84.08 | BZ25: 0 | CA25: 0 | CB25: 0 | CC25: 0 | CD25: =(80957/1000)+(94337/1000) -> 175.294 | CE25: 0 | CF25: 0 | CG25: 0 | CH25: 0 | CI25: =IF(AND(CI$13>=$C25,CI$13<=$E25),($H25-SUM($K25:CH25))/(($E25-CI$13+1)),0) -> 0 | CJ25: =IF(AND(CJ$13>=$C25,CJ$13<=$E25),($H25-SUM($K25:CI25))/(($E25-CJ$13+1)),0) -> 0 | CK25: =IF(AND(CK$13>=$C25,CK$13<=$E25),($H25-SUM($K25:CJ25))/(($E25-CK$13+1)),0) -> 0 | CL25: =IF(AND(CL$13>=$C25,CL$13<=$E25),($H25-SUM($K25:CK25))/(($E25-CL$13+1)),0) -> 0 | CM25: =IF(AND(CM$13>=$C25,CM$13<=$E25),($H25-SUM($K25:CL25))/(($E25-CM$13+1)),0) -> 0 | CN25: =IF(AND(CN$13>=$C25,CN$13<=$E25),($H25-SUM($K25:CM25))/(($E25-CN$13+1)),0) -> 0 | CO25: =IF(AND(CO$13>=$C25,CO$13<=$E25),($H25-SUM($K25:CN25))/(($E25-CO$13+1)),0) -> 0 | CP25: =IF(AND(CP$13>=$C25,CP$13<=$E25),($H25-SUM($K25:CO25))/(($E25-CP$13+1)),0) -> 0 | ... GT25: =IF(AND(GT$13>=$C25,GT$13<=$E25),($H25-SUM($K25:GS25))/(($E25-GT$13+1)),0) -> 0 | HF25: x | HG25: =HG23+1 -> 2
A26: HC | B26: =+Assumptions!B17 -> CapEx | G26: =SUM(G22:G25) -> 490 | H26: =SUM(H22:H25) -> 2314.3238 | I26: =SUMIF($K$13:$GT$13,"<="&Assumptions!$L$17,'Monthly Cash Flow'!K26:GT26) -> 2314.3238 | K26: =SUBTOTAL(9,K22:K25) -> 0 | L26: =SUBTOTAL(9,L22:L25) -> 0 | M26: =SUBTOTAL(9,M22:M25) -> 0 | N26: =SUBTOTAL(9,N22:N25) -> 0 | O26: =SUBTOTAL(9,O22:O25) -> 0 | P26: =SUBTOTAL(9,P22:P25) -> 0 | Q26: =SUBTOTAL(9,Q22:Q25) -> 0 | R26: =SUBTOTAL(9,R22:R25) -> 0 | ... BV26: =SUBTOTAL(9,BV22:BV25) -> 0 | BW26: =SUBTOTAL(9,BW23:BW25) -> 0 | BX26: =SUBTOTAL(9,BX23:BX25) -> 0 | BY26: =SUBTOTAL(9,BY22:BY25) -> 84.08 | BZ26: =SUBTOTAL(9,BZ22:BZ25) -> 0 | CA26: =SUBTOTAL(9,CA22:CA25) -> 0 | CB26: =SUBTOTAL(9,CB22:CB25) -> 0 | CC26: =SUBTOTAL(9,CC22:CC25) -> 0 | CD26: =SUBTOTAL(9,CD22:CD25) -> 175.294 | CE26: =SUBTOTAL(9,CE22:CE25) -> 0 | CF26: =SUBTOTAL(9,CF22:CF25) -> 0 | ... GT26: =SUBTOTAL(9,GT22:GT25) -> 0 | HF26: x | HG26: =HG25+1 -> 3 | HH26: =+B26 -> CapEx | HL26: =SUM(HN26:HV26) -> 2314.3238 | HN26: =SUMIF($K$14:$GT$14,HN$14,$K26:$GT26) -> 0 | HO26: =SUMIF($K$14:$GT$14,HO$14,$K26:$GT26) -> 84.0285 | HP26: =SUMIF($K$14:$GT$14,HP$14,$K26:$GT26) -> 1211.4883 | HQ26: =SUMIF($K$14:$GT$14,HQ$14,$K26:$GT26) -> 22.651 | HR26: =SUMIF($K$14:$GT$14,HR$14,$K26:$GT26) -> 180.858 | HS26: =SUMIF($K$14:$GT$14,HS$14,$K26:$GT26) -> 65.924 | HT26: =SUMIF($K$14:$GT$14,HT$14,$K26:$GT26) -> 259.374 | HU26: =SUMIF($K$14:$GT$14,HU$14,$K26:$GT26) -> 310.31746 | HV26: =SUMIF($K$14:$GT$14,HV$14,$K26:$GT26) -> 179.68254
B27: Soft Costs | C27: =Assumptions!J13 -> 68 | E27: 71 | F27: =SUMIF($K$13:$GT$13,"<="&$C$13,'Monthly Cash Flow'!K27:GT27) -> 798.309 | H27: =SUM(F27:G27) -> 798.309 | I27: =SUMIF($K$13:$GT$13,"<="&Assumptions!$L$17,'Monthly Cash Flow'!K27:GT27) -> 798.309 | K27: 0 | L27: 0 | M27: 0 | N27: 0 | O27: 0 | P27: 0 | Q27: 0 | R27: 0 | S27: 0 | T27: 0 | U27: 138.72733 | V27: 0 | W27: 0 | X27: 0 | Y27: 0 | Z27: 226.13481 | AA27: 0 | AB27: 87.18598 | AC27: 0 | AD27: 0 | AE27: 83.58834 | AF27: 79.022689 | AG27: 49.54032 | AH27: 0 | AI27: 4.365 | AJ27: 0 | AK27: 0 | AL27: 5.449 | AM27: 0 | AN27: 11.14665 | AO27: 0 | AP27: 0 | AQ27: 5.652 | AR27: 0 | AS27: 0 | AT27: 0 | AU27: 0 | AV27: 0 | AW27: 0 | AX27: 0 | AY27: 0 | AZ27: 0 | BA27: 0 | BB27: 0 | BC27: 0 | BD27: 0 | BE27: 0 | BF27: 0 | BG27: 0 | BH27: 0 | BI27: 0 | BJ27: 0 | BK27: 0 | BL27: 0 | BM27: 0 | BN27: 0 | BO27: 0 | BP27: 0 | BQ27: 0 | BR27: 0 | BS27: 0 | BT27: 0 | BU27: 0 | BV27: 0 | BW27: 0 | BX27: =5506.62/1000 -> 5.50662 | BY27: =3253.83/1000 -> 3.25383 | BZ27: 0 | CA27: =2500/1000 -> 2.5 | CB27: =5000/1000 -> 5 | CC27: 0 | CD27: =2000/1000 -> 2 | CE27: 0 | CF27: =(52949.96/1000)+(14000/1000) -> 66.94996 | CG27: =IF(AND(CG$13>=$C27,CG$13<=$E27),($H27-SUM($K27:CF27))/(($E27-CG$13+1)),0) -> 0 | CH27: =22286.47/1000 -> 22.28647 | CI27: =IF(AND(CI$13>=$C27,CI$13<=$E27),($H27-SUM($K27:CH27))/(($E27-CI$13+1)),0) -> 0 | CJ27: =IF(AND(CJ$13>=$C27,CJ$13<=$E27),($H27-SUM($K27:CI27))/(($E27-CJ$13+1)),0) -> 0 | CK27: =IF(AND(CK$13>=$C27,CK$13<=$E27),($H27-SUM($K27:CJ27))/(($E27-CK$13+1)),0) -> 0 | CL27: =IF(AND(CL$13>=$C27,CL$13<=$E27),($H27-SUM($K27:CK27))/(($E27-CL$13+1)),0) -> 0 | CM27: =IF(AND(CM$13>=$C27,CM$13<=$E27),($H27-SUM($K27:CL27))/(($E27-CM$13+1)),0) -> 0 | CN27: =IF(AND(CN$13>=$C27,CN$13<=$E27),($H27-SUM($K27:CM27))/(($E27-CN$13+1)),0) -> 0 | CO27: =IF(AND(CO$13>=$C27,CO$13<=$E27),($H27-SUM($K27:CN27))/(($E27-CO$13+1)),0) -> 0 | CP27: =IF(AND(CP$13>=$C27,CP$13<=$E27),($H27-SUM($K27:CO27))/(($E27-CP$13+1)),0) -> 0 | ... GT27: =IF(AND(GT$13>=$C27,GT$13<=$E27),($H27-SUM($K27:GS27))/(($E27-GT$13+1)),0) -> 0 | HF27: x | HG27: =HG26+1 -> 4
