Workbook
Name IQ_CH: 110000
Name IQ_CQ: 5000
Name IQ_CY: 10000
Name IQ_DAILY: 500000
Name IQ_FH: 100000
Name IQ_FQ: 500
Name IQ_FY: 1000
Name IQ_LTM: 2000
Name IQ_MONTH: 15000
Name IQ_NTM: 6000
Name IQ_WEEK: 50000
Name IQ_YTD: 3000

Sheet Cover
C9: CA South Development
C11: =+Dashboard!C5 -> 1425 4th Ave
C14: Preliminary
C16: =TODAY() -> 45037

Sheet Massing

Sheet Sheet2
C5: Mad Dog | D5: Charlotte
B6: Hard cost | C6: ='Budget Detail'!K66+'Budget Detail'!K68 -> 35728298 | D6: 30500000
B7: Total GSF | C7: =Assumptions!K34 -> 195551 | D7: 146824
B8: $/GSF | C8: =C6/C7 -> 182.70578 | D8: =D6/D7 -> 207.73171
B10: Interior Built SF | C10: =Assumptions!J36 -> 135381 | D10: 123355
B11: $/SF | C11: =C6/C10 -> 263.90925 | D11: =D6/D10 -> 247.25386
C13: =C7-C10 -> 60170 | D13: =D7-D10 -> 23469

Sheet Sheet1
B2: Hard Cost Comparison
C3: O'Neil Budget | D3: O'Neil Budget (Ben's Revisions) | E3: 1425 Budget Last Sent to Argosy | F3: 1425 Budget Current Update to Acieve 5.5% ROC
B5: Hard Costs | C5: 38130142 | D5: 36700000 | E5: 35008771 | F5: ='Budget Detail'!K68++'Budget Detail'!K66 -> 35728298
B6: Gross SF | C6: 196602 | D6: 196602 | E6: 196602 | F6: 196602
B7: $/SF | C7: =C5/C6 -> 193.94585 | D7: =D5/D6 -> 186.67155 | E7: =E5/E6 -> 178.06925 | F7: =F5/F6 -> 181.72907
B10: Hard Cost Comparison
C11: 1425 Budget Current Update to Acieve 5.5% ROC | D11: 405 40th Budget
B12: Hard Costs | C12: =F5 -> 35728298 | D12: 33058410
B13: Gross SF | C13: =F6 -> 196602 | D13: 149267
B14: $/SF | C14: =C12/C13 -> 181.72907 | D14: =D12/D13 -> 221.47166
E15: =(D14-C14)/C14 -> 0.21869144

Sheet Dashboard
B5: Name | C5: =Assumptions!E3 -> 1425 4th Ave
B6: Asset Class | C6: =Assumptions!E4 -> Multifamily
B7: Asset Disposition | C7: Stabilized Sale
B8: Leasable / Saleable SF | C8: =Assumptions!J35 -> 103297
B10: Residential Program Summary
B11: Unit Type | C11: Count | D11: Unit % | E11: Unit Size | F11: Total LSF | G11: LSF % | H11: Gross Annual Rent | I11: Rent/Unit | J11: Rent/Bedroom | K11: Rent/LSF | M11: Bed/Unit
B12: =Assumptions!B28 -> Studio | C12: =Assumptions!C28 -> 12 | D12: =C12/$C$18 -> 0.091603053 | E12: =Assumptions!E28 -> 458 | F12: =Assumptions!F28 -> 5496 | G12: =F12/$F$18 -> 0.053205805 | H12: =I12*C12*12 -> 216000 | I12: ='Rent Comps'!D70 -> 1500 | J12: =I12/M12 -> 1500 | K12: =I12/E12 -> 3.2751092 | M12: 1
B13: =Assumptions!B29 -> 1 bed | C13: =Assumptions!C29 -> 76 | D13: =C13/$C$18 -> 0.58015267 | E13: =Assumptions!E29 -> 702.18421 | F13: =Assumptions!F29 -> 53366 | G13: =F13/$F$18 -> 0.51662681 | H13: =I13*C13*12 -> 1732800 | I13: ='Rent Comps'!D71 -> 1900 | J13: =I13/M13 -> 1900 | K13: =I13/E13 -> 2.7058427 | M13: 1
B14: =Assumptions!B30 -> 2 Bed | C14: =Assumptions!C30 -> 37 | D14: =C14/$C$18 -> 0.28244275 | E14: =Assumptions!E30 -> 1016.8919 | F14: =Assumptions!F30 -> 37625 | G14: =F14/$F$18 -> 0.36424098 | H14: =I14*C14*12 -> 1287600 | I14: ='Rent Comps'!D72 -> 2900 | J14: =I14/M14 -> 1450 | K14: =I14/E14 -> 2.8518272 | M14: 2
B15: =Assumptions!B31 -> 2 Bed Plus | C15: =Assumptions!C31 -> 2 | D15: =C15/$C$18 -> 0.015267176 | E15: =Assumptions!E31 -> 1485 | F15: =Assumptions!F31 -> 2970 | G15: =F15/$F$18 -> 0.028752045 | H15: =I15*C15*12 -> 84000 | I15: ='Rent Comps'!D73 -> 3500 | J15: =I15/M15 -> 1750 | K15: =I15/E15 -> 2.3569024 | M15: 2
B16: Live/Work | C16: =Assumptions!C32 -> 4 | D16: =C16/$C$18 -> 0.030534351 | E16: =Assumptions!E32 -> 960 | F16: =Assumptions!F32 -> 3840 | G16: =F16/$F$18 -> 0.037174361 | H16: =I16*C16*12 -> 139200 | I16: ='Rent Comps'!D74 -> 2900 | J16: =I16/M16 -> 966.66667 | K16: =IFERROR(I16/E16,0) -> 3.0208333 | M16: 3
B18: Total | C18: =SUM(C12:C17) -> 131 | D18: =SUM(D12:D17) -> 1 | E18: =F18/C18 -> 788.52672 | F18: =SUM(F12:F17) -> 103297 | G18: =SUM(G12:G17) -> 1 | H18: =SUM(H12:H17) -> 3459600 | I18: =SUMPRODUCT(I12:I17,C12:C17)/C18 -> 2200.7634 | J18: =SUMPRODUCT(M12:M17,C12:C17,J12:J17)/SUMPRODUCT(M12:M17,C12:C17) -> 1619.6629 | K18: =I18/E18 -> 2.7909813
B20: STR Unit Mix / Rates
B21: Unit Type | C21: Count | D21: Unit % | E21: Unit Size | F21: Total LSF | G21: LSF % | H21: Gross Expected Revenue | I21: ADR | J21: Vacancy | K21: RevPar
B22: =B12 -> Studio | C22: =Assumptions!C28 -> 12 | D22: =C22/$C$26 -> 0.091603053 | E22: =Assumptions!E28 -> 458 | F22: =E22*C22 -> 5496 | G22: =F22/$F$26 -> 0.053205805 | H22: =((I22*365)*C22)*(1-J22) -> 830886 | I22: ='Assumptions MH'!E71 -> 271 | J22: =1-'Assumptions MH'!D71 -> 0.3 | K22: =I22*(1-J22) -> 189.7
B23: 1 bed | C23: =Assumptions!C29+Assumptions!C32 -> 80 | D23: =C23/$C$26 -> 0.61068702 | E23: =((Assumptions!C29*Assumptions!E29)+(Assumptions!C32*Assumptions!E32))/(Assumptions!C29+Assumptions!C32) -> 715.075 | F23: =E23*C23 -> 57206 | G23: =F23/$F$26 -> 0.55380118 | H23: =((I23*365)*C23)*(1-J23) -> 5539240 | I23: ='Assumptions MH'!E72 -> 271 | J23: =1-'Assumptions MH'!D72 -> 0.3 | K23: =I23*(1-J23) -> 189.7
B24: 2 Bed | C24: =Assumptions!C30+Assumptions!C31 -> 39 | D24: =C24/$C$26 -> 0.29770992 | E24: =((Assumptions!C30*Assumptions!E30)+(Assumptions!C31*Assumptions!E31))/(Assumptions!C30+Assumptions!C31) -> 1040.8974 | F24: =E24*C24 -> 40595 | G24: =F24/$F$26 -> 0.39299302 | H24: =((I24*365)*C24)*(1-J24) -> 2700379.5 | I24: ='Assumptions MH'!E73 -> 271 | J24: =1-'Assumptions MH'!D73 -> 0.3 | K24: =I24*(1-J24) -> 189.7
B26: Total | C26: =SUM(C22:C25) -> 131 | D26: =SUM(D22:D25) -> 1 | E26: =F26/C26 -> 788.52672 | F26: =SUM(F22:F25) -> 103297 | G26: =SUM(G22:G25) -> 1 | H26: =((I26*365)*C26)*(1-J26) -> 9070505.5 | I26: =SUMPRODUCT(I22:I25,C22:C25)/C26 -> 271 | J26: =1-(K26/I26) -> 0.3 | K26: =SUMPRODUCT(K22:K25,C22:C25)/C26 -> 189.7
B28: Uses | G28: Return-On-Cost | J28: Trended | K28: Un-Trended
C29: Total | D29: % Total | E29: $/LSF | G29: Stabilized Year | J29: 3
B30: Land | C30: =Assumptions!N12 -> 5200000 | D30: =+C30/C$37 -> 0.094572528 | E30: =C30/$C$8 -> 50.340281 | G30: Rent Growth at Stabilization | J30: ='Assumptions MH'!T6 -> 0.03
B31: Construction Costs + Contingency | C31: =Assumptions!N27 -> 38440298 | D31: =+C31/C$37 -> 0.69911464 | E31: =C31/$C$8 -> 372.13373 | G31: Expense Growth at Stabilization | J31: ='Assumptions MH'!T9 -> 0.03
B32: Soft Costs + Contingency | C32: =Assumptions!N33-C36-C34 -> 8322236.8 | D32: =+C32/C$37 -> 0.15135672 | E32: =C32/$C$8 -> 80.566103 | G32: Net Revenue - Residential | J32: =K32*(1+$J$30)^($J$29-1) -> 9622899.3 | K32: =H26 -> 9070505.5
B33: TI | C33: ='Budget Detail'!$K$72 -> 0 | D33: =+C33/C$37 -> 0 | E33: =C33/$C$8 -> 0
B34: Lease-Up Costs | C34: =Assumptions!E16+Assumptions!E20 -> 300000 | D34: =+C34/C$37 -> 0.0054561074 | E34: =C34/$C$8 -> 2.904247 | G34: Parking Income | J34: =K34*(1+$J$30)^($J$29-1) -> 429533.21 | K34: =(('Assumptions MH'!L41*'Assumptions MH'!L42*'Assumptions MH'!L43*'Assumptions MH'!L44*'Assumptions MH'!L45)*365)*0.75 -> 404876.25
B35: Total Budget | C35: =SUM(C30:C34) -> 52262535 | D35: =+C35/C$37 -> 0.9505 | E35: =SUM(E30:E34) -> 505.94436 | G35: Net Revenue | J35: =SUM(J32:J34) -> 10052432 | K35: =SUM(K32:K34) -> 9475381.8
B36: Construction Loan D/S | C36: ='Budget Detail'!K22+'Budget Detail'!K23 -> 2721720.6 | D36: =+C36/C$37 -> 0.0495 | E36: =C36/$C$8 -> 26.348496 | G36: Opex & Profit Split(1) | J36: =K36*(1+$J$31)^($J$29-1) -> -5588397.6 | K36: =(-'Stabalized NOI'!F42-'Stabalized NOI'!F63-'Stabalized NOI'!F69-'Stabalized NOI'!F80-'Stabalized NOI'!F86)-('RE Tax'!J44*Dashboard!C26)-((Assumptions!$I$82*Assumptions!$C$34)*12) -> -5267600.7
B37: Total Budget w/ Loan | C37: =SUM(C35:C36) -> 54984255 | D37: =+C37/C$37 -> 1 | E37: =C37/$C$8 -> 532.29286 | G37: Operating Income | J37: =J35+J36 -> 4464034.9 | K37: =K35+K36 -> 4207781
G38: Total Development Costs(2) | J38: =K38 -> 54984255 | K38: =C37 -> 54984255 | M38: =K37/K35 -> 0.44407509 | N38: <--- Profit Margin
G39: ROC | J39: =J37/J38 -> 0.081187512 | K39: =K37/K38 -> 0.076527017
B40: Sources | G40: (1) Inclusive of MH 10% profit split
D41: Total | E41: % Total | G41: (2) Inclusive of lease-up costs & interest reserve
B42: Debt | D42: ='Monthly-CF'!I109+'Monthly-CF'!I116 -> 32990553 | E42: =D42/$D$44 -> 0.6
B43: Equity | D43: ='Monthly-CF'!F105 -> 21993702 | E43: =D43/$D$44 -> 0.4 | G43: Exit Assumptions | K43: Residential | P43: DO NOT DELETE
B44: Total Sources & Uses | D44: =SUM(D42:D43) -> 54984255 | E44: =+SUM(E42:E43) -> 1 | G44: Exit Cap Rate | K44: =Assumptions!M55 -> 0.0525 | P44: =K37/K44 -> 80148210
B45: LP Equity | D45: =-SUMIFS('Monthly-Waterfall'!I58:DY58,'Monthly-Waterfall'!I58:DY58,"<"&0) -> 19794332 | E45: =+D45/D43 -> 0.9 | G45: Selling Costs | K45: =Assumptions!M56 -> 0.0125 | P45: =-P44*K45 -> -1001852.6
B46: GP / Sponsor Equity | D46: =-SUMIFS('Monthly-Waterfall'!I59:DY59,'Monthly-Waterfall'!I59:DY59,"<"&0) -> 2199370.2 | E46: =+D46/D43 -> 0.1 | G46: Exit Year(1) | K46: =Assumptions!M57 -> 10 | P46: =SUM(P44:P45) -> 79146357
B47: * Cost of debt assumes 300 bps + SOFR | P47: =P46/C18 -> 604170.67
G48: Residential | I48: Total | J48: $/Unit | K48: $/LSF
B49: Schedule | G49: Terminal Value | I49: =I51-I50 -> 86491038 | J49: =I49/$C$18 -> 660236.93 | K49: =I49/$F$18 -> 837.30445
...

Sheet Assumptions
D3: NAME | E3: 1425 4th Ave
D4: SUMMARY | E4: Multifamily | R4: FALSE
D5: DATE
D6: TYPE | E6: STABILIZED SALE
B8: Development Budget
B10: Development Budget Assumptions
B11: % of Tot. | C11: $ / LSQFT | D11: Detail | E11: Amount | F11: Start | G11: End | J11: ACRES | K11: SF | L11: $/SF | N11: Total | P11: / Unit
B12: =+E12/$E$23 -> 0.072848359 | C12: =E12/$J$35 -> 50.340281 | D12: Land | E12: =N12 -> 5200000 | F12: 1 | G12: 1 | I12: Land | J12: 1.12 | K12: =+J12*43650 -> 48888 | L12: =N12/K12 -> 106.36557 | N12: 5200000 | P12: =N12/C34 -> 39694.656
B13: =+E13/$E$23 -> 0.53852165 | C13: =E13/$J$35 -> 372.13373 | D13: Construction Costs + Contingency | E13: =N27 -> 38440298 | F13: ='Monthly-CF'!F70 -> 3 | G13: ='Monthly-CF'!H70 -> 19 | J13: Leaseable
B14: =+E14/$E$23 -> 0.11658871 | C14: =E14/$J$35 -> 80.566103 | D14: Soft Costs + Contingency | E14: =N33-E19-E18-E20 -> 8322236.8 | F14: ='Monthly-CF'!F71 -> 2 | G14: ='Monthly-CF'!H81 -> 0 | I14: Total investment acquisition
B15: =+E15/$E$23 -> 0 | C15: =E15/$J$35 -> 0 | D15: TI | E15: ='Budget Detail'!K72 -> 0 | F15: =G13-1 -> 18 | I15: Multi-Family | J15: x | K15: =F34 -> 103297 | L15: =N15/K15 -> 345.87934 | N15: ='Budget Detail'!K66+'Budget Detail'!K68 -> 35728298
B16: =+E16/$E$23 -> 0 | C16: =E16/$J$35 -> 0 | D16: LC | F16: =INDEX('Monthly-CF'!$L$10:$EA$10,MATCH(Assumptions!$H$59,'Monthly-CF'!$L$13:$EA$13,0)) -> 1 | G16: =INDEX('Monthly-CF'!$L$10:$EA$10,MATCH(Assumptions!$J$59,'Monthly-CF'!$L$13:$EA$13,0)) -> 1 | I16: Commercial | J16: x | K16: =F41 -> 0 | L16: 0
B17: =+E17/$E$23 -> 0.72795872 | C17: =E17/$J$35 -> 503.04011 | D17: Total before Interest | E17: =SUM(E10:E16) -> 51962535 | F17: =MIN(F12:F16) -> 1 | G17: =MAX(G12:G16) -> 19 | I17: Amenity / Unleaseable Space | K17: =F37+F38+F36+F39 -> 32084 | L17: 0
B18: =+E18/$E$23 -> 0.0034663091 | C18: =E18/$J$35 -> 2.3953179 | D18: Financing Costs | E18: =-'Monthly-CF'!I93 -> 247429.15 | F18: =INDEX('Monthly-CF'!$L$10:$EA$10,MATCH(-Assumptions!$E$18,'Monthly-CF'!$L$93:$EA$93,0)) -> 8 | G18: =F18 -> 8
B19: =+E19/$E$23 -> 0.034663091 | C19: =E19/$J$35 -> 23.953179 | D19: Const. Interest Reserve | E19: =-'Monthly-CF'!I94 -> 2474291.5
B20: =+E20/$E$23 -> 0.0042027899 | C20: =E20/$J$35 -> 2.904247 | D20: Op Inc Loss | E20: =-'Monthly-CF'!I75-'Monthly-CF'!I85 -> 300000 | I20: Garage | K20: =F45 -> 60170 | L20: 0
B21: =+E21/$E$23 -> 0.77029091 | C21: =E21/$J$35 -> 532.29286 | D21: Total Costs | E21: =SUM(E17:E20) -> 54984255
B22: =+E22/$E$23 -> 0.22970909 | C22: =E22/$J$35 -> 158.73549 | D22: Stab. Interest Exp | E22: =-'Monthly-CF'!I127 -> 16396900
B23: =+E23/$E$23 -> 1 | C23: =E23/$J$35 -> 691.02835 | D23: Costs + Stab Interest | E23: =SUM(E21:E22) -> 71381155
I24: Building Permits / Fees | N24: ='Budget Detail'!K65 -> 412125
B25: MF Unit Mix Assumptions | I25: Other Hard Costs | N25: ='Budget Detail'!K73+SUM('Budget Detail'!K69:K71) -> 513460
B26: Type | C26: Count | D26: Unit % | E26: Unit Size | F26: Total SF | G26: SF% Allocation | I26: Construction Contingency | M26: ='Budget Detail'!E67 -> 0.05 | N26: ='Budget Detail'!K67 -> 1786414.9
I27: Construction - Hard Costs | K27: =SUM(K15:K25) -> 195551 | L27: =N27/K27 -> 196.57428 | M27: =N27/SUM(K15:K19) -> 283.9416 | N27: =SUM(N15:N26) -> 38440298 | P27: =SUM(N26,N15:N23)/SUM(K15:K17) -> 277.10471
B28: Studio | C28: ='Unit Detail'!D23 -> 12 | D28: =C28/$C$34 -> 0.091603053 | E28: ='Unit Detail'!E23 -> 458 | F28: =E28*C28 -> 5496 | G28: =F28/$F$34 -> 0.053205805 | I28: Architect / Engineer | K28: =$K$27 -> 195551 | L28: =N28/K28 -> 6.9497729 | N28: ='Budget Detail'!K36+'Budget Detail'!K39 -> 1359035.1 | P28: =N28/$C$34 -> 10374.313
B29: 1 bed | C29: ='Unit Detail'!D24 -> 76 | D29: =C29/$C$34 -> 0.58015267 | E29: ='Unit Detail'!E24 -> 702.18421 | F29: =E29*C29 -> 53366 | G29: =F29/$F$34 -> 0.51662681 | I29: Project Manager | K29: =$K$27 -> 195551 | L29: =N29/K29 -> 0 | N29: ='Budget Detail'!K40 -> 0 | P29: =N29/$C$34 -> 0
B30: 2 Bed | C30: ='Unit Detail'!D25 -> 37 | D30: =C30/$C$34 -> 0.28244275 | E30: ='Unit Detail'!E25 -> 1016.8919 | F30: =E30*C30 -> 37625 | G30: =F30/$F$34 -> 0.36424098 | I30: Developer Fee | K30: =$K$27 -> 195551 | L30: =N30/K30 -> 8.5534497 | M30: ='Budget Detail'!E76 -> 0 | N30: ='Budget Detail'!K76+'Budget Detail'!K77 -> 1672635.6 | P30: =N30/$C$34 -> 12768.211
B31: 2 Bed Plus | C31: ='Unit Detail'!D26 -> 2 | D31: =C31/$C$34 -> 0.015267176 | E31: ='Unit Detail'!E26 -> 1485 | F31: =E31*C31 -> 2970 | G31: =F31/$F$34 -> 0.028752045
B32: Loft | C32: ='Unit Detail'!D27 -> 4 | D32: =C32/$C$34 -> 0.030534351 | E32: ='Unit Detail'!E27 -> 960 | F32: =E32*C32 -> 3840 | G32: =F32/$F$34 -> 0.037174361 | I32: Other Soft Costs | K32: =$K$27 -> 195551 | L32: =N32/K32 -> 42.507002 | N32: =SUM(,'Budget Detail'!K10:K18,'Budget Detail'!K22:K29,'Budget Detail'!K43,'Budget Detail'!K62,'Budget Detail'!K76:K77)-SUM(N28:N31) -> 8312286.7
I33: Construction - Soft Costs | N33: =SUM(N28:N32) -> 11343957
B34: Total | C34: =SUM(C27:C33) -> 131 | D34: =C34/$C$34 -> 1 | E34: =F34/C34 -> 788.52672 | F34: =SUM(F27:F33) -> 103297 | G34: =SUM(G27:G33) -> 1 | I34: Total Development Costs | K34: =K27 -> 195551 | L34: =N34/K34 -> 281.17604 | N34: =N33+N27+N12 -> 54984255
I35: Leaseable SF | J35: =SUMIFS(K15:K24,J15:J24,"x") -> 103297 | L35: =N34/$J$35 -> 532.29286
B36: Lobby | F36: ='Unit Detail'!F36 -> 3372 | I36: Interior Built SF | J36: =SUM(K15:K19) -> 135381
B37: Common Area / Courtyard | J37: =+J35/J36 -> 0.76300958
B38: Amenity Area | F38: ='Unit Detail'!F37+'Unit Detail'!F38+'Unit Detail'!F39 -> 10578
B39: Unleaseable Area | F39: 18134
B40: GSF Residential | F40: =SUM(F33:F39) -> 135381
B41: Retail Area
B42: Total Gross SF | F42: =SUM(F40:F41) -> 135381
B43: Total Leasable SF | F43: =F41+F34 -> 103297
B45: Garage SF | F45: 60170
...

Sheet Assumptions MH
B2: 1425 4th Ave (Nashville, TN) | Mint House Management Agreement Model
B3: Assumptions MH
B5: Deal Overview | I5: Rate Assumption | N5: Model Inputs | S5: Growth Rates | V5: =+W6&" Structure" -> Prioritized Hurdle Structure | Y5: Profit Share Assumptions
B6: Deal Name | G6: 1425 4th Ave | I6: Data Source | K6: Weight | L6: ADR | N6: Category | O6: Short Term | P6: Long Term | Q6: Blended | S6: ADR Annual Inflation | T6: 0.03 | V6: Type | W6: Prioritized Hurdle | Y6: Min. Monthly Pmt Growth | Z6: =+T7 -> 0.03
B7: Address | G7: 1425 4th Avenue South | I7: Mint House | K7: 0 | L7: 0 | N7: Number of Units | O7: =G29 -> 131 | P7: =G30 -> 0 | Q7: =G31 -> 131 | S7: Multifamily Rent Growth | T7: 0.03 | V7: Year # | W7: MF Rent % | Y7: Y1 MF Ramp | Z7: 0.685
B8: Market | G8: Nashville | I8: Comps - STR | K8: 0.25 | L8: 217.4433 | N8: ADR | O8: ='Assumptions MH'!L15 -> 271 | P8: =+'Assumptions MH'!L9 -> 0 | Q8: =SUMPRODUCT(O8:P8,$O$7:$P$7)/$Q$7 -> 271 | S8: Other Revenue Growth | T8: 0.03 | V8: 1 | W8: 0 | Y8: Margin on MF Rent [2] | Z8: 0.7
B9: City | G9: Nashville | I9: Comps - LTL | K9: 0 | L9: 0 | N9: Occupancy | O9: =+'Assumptions MH'!L27 -> 0.7 | P9: 0.75 | Q9: =SUMPRODUCT(O9:P9,$O$7:$P$7)/$Q$7 -> 0.7 | S9: Expense Growth | T9: 0.03 | V9: 2 | W9: 0
B10: State | G10: TN | I10: Smith Travel Research | K10: 0.55 | L10: 278.16259 | N10: RevPAR | O10: =PRODUCT(O8:O9) -> 189.7 | P10: =PRODUCT(P8:P9) -> 0 | Q10: =SUMPRODUCT(O10:P10,$O$7:$P$7)/$Q$7 -> 189.7 | S10: Hurdle Growth | V10: 3 | W10: 0 | Y10: Minimum Monthly Payment
B11: Zip Code | G11: 37210 | I11: Forward Rate Shop | K11: 0.2 | L11: 319.60761 | N11: Cleanings (per turn) | O11: 65 | P11: 60 | Q11: =SUMPRODUCT(O11:P11,$O$7:$P$7)/$Q$7 -> 65 | V11: 4 | W11: 0 | Y11: Year # | Z11: MF Rent %
B12: Submarket | G12: Wedgewood-Houston | I12: Market - T12 | K12: 0 | L12: 232.23069 | N12: Consumables (per turn) | O12: 10 | P12: 10 | Q12: =SUMPRODUCT(O12:P12,$O$7:$P$7)/$Q$7 -> 10 | S12: ADR Growth Rate | V12: 5 | W12: 0 | Y12: 1 | Z12: 0.6
B13: Total Property Units | G13: =Assumptions!C34 -> 131 | I13: Market - 2019 | K13: 0 | L13: 221.23977 | N13: OSE (per turn) | O13: 20 | P13: 20 | Q13: =SUMPRODUCT(O13:P13,$O$7:$P$7)/$Q$7 -> 20 | S13: Year | T13: Growth Rate | V13: 6 | W13: 0 | Y13: 2 | Z13: 0.5
B14: Year Built | G14: 2025 | I14: Manual | K14: 0 | L14: 0 | N14: Guest Services - Labor | O14: =+'Staffing Model MH'!H20 -> 298.94635 | P14: =+'Staffing Model MH'!H20 -> 298.94635 | Q14: =SUMPRODUCT(O14:P14,$O$7:$P$7)/$Q$7 -> 298.94635 | S14: 1 | T14: 0.03 | V14: 7 | W14: 0 | Y14: 3 | Z14: 0.4
B15: Year Renovated | G15: na | I15: Blended | K15: =SUM(K7:K14) -> 1 | L15: =ROUND(SUMPRODUCT(K7:K14,L7:L14),0) -> 271 | N15: G&A: Salaries & Benefits | O15: =+'Staffing Model MH'!H28 -> 283.80252 | P15: =+'Staffing Model MH'!H28 -> 283.80252 | Q15: =SUMPRODUCT(O15:P15,$O$7:$P$7)/$Q$7 -> 283.80252 | S15: 2 | T15: 0.03 | V15: 8 | W15: 0 | Y15: 4 | Z15: 0.4
B16: Multifamily Class | G16: A | N16: G&A: Operating Supplies | O16: 5 | P16: 20 | Q16: 5 | S16: 3 | T16: 0.03 | V16: 9 | W16: 0 | Y16: 5 | Z16: 0.4
I17: Occupancy Assumption | N17: Credit Card Fees | O17: 0.03 | P17: 0.03 | Q17: =SUMPRODUCT(O17:P17,$O$7:$P$7)/$Q$7 -> 0.03 | S17: 4 | T17: 0.03 | V17: 10 | W17: 0 | Y17: 6 | Z17: 0.4
B18: General Assumptions | I18: Data Source | K18: Weight | L18: Occupancy | N18: Utilities | O18: 100 | P18: 100 | Q18: =SUMPRODUCT(O18:P18,$O$7:$P$7)/$Q$7 -> 100 | S18: 5 | T18: 0.03 | Y18: 7 | Z18: 0.4
B19: Property Type | G19: Short Term | I19: Mint House | K19: 0 | L19: 0 | N19: In-Unit Maintenance | O19: 30 | P19: 35 | Q19: =SUMPRODUCT(O19:P19,$O$7:$P$7)/$Q$7 -> 30 | S19: 6 | T19: 0.03 | V19: Incentive Management Fee | Y19: 8 | Z19: 0.4
B20: Analysis Start | F20: Create calc based on development completion ---> | G20: 45658 | I20: Comps - STR | K20: 0 | L20: 0.75300254 | N20: Shared Services | O20: 150 | P20: 150 | Q20: =SUMPRODUCT(O20:P20,$O$7:$P$7)/$Q$7 -> 150 | S20: 7 | T20: 0.03 | V20: Year # | W20: MH Split (%) | Y20: 9 | Z20: 0.4
B21: Full Building | G21: 1 | I21: Smith Travel Research | K21: 0 | L21: 0.74090957 | N21: Sales & Marketing - Payroll | O21: ='Staffing Model MH'!$H$32 -> 97.455391 | P21: ='Staffing Model MH'!$H$32 -> 97.455391 | Q21: =SUMPRODUCT(O21:P21,$O$7:$P$7)/$Q$7 -> 97.455391 | S21: 8 | T21: 0.03 | V21: 1 | W21: 0.15 | Y21: 10 | Z21: 0.4
B22: Inflation Adjustment | G22: 1 | I22: Market - T12 | K22: 0 | L22: 0.64218422 | N22: Sales & Marketing - Direct to Consumer | O22: 0.005 | P22: 0.01 | Q22: =SUMPRODUCT(O22:P22,$O$7:$P$7)/$Q$7 -> 0.005 | S22: 9 | T22: 0.03 | V22: 2 | W22: 0.15
B23: ADR Recovery Year to 2019 | G23: 2022 | I23: Market - 2019 | K23: 0 | L23: 0.70739798 | N23: Platform Fees / Customer Acquisition | O23: 0.07 | P23: 0.045 | Q23: =SUMPRODUCT(O23:P23,$O$7:$P$7)/$Q$7 -> 0.07 | S23: 10 | T23: 0.03 | V23: 3 | W23: 0.15 | Y23: Profit Share
B24: Inflation Years | G24: =IF(YEAR(G20)-$G$23<0,0,ROUNDDOWN(YEAR(G20)-G23,0))*G22 -> 3 | I24: Manual | K24: 1 | L24: 0.7 | N24: Wifi / Cable | O24: 75 | P24: 75 | Q24: =SUMPRODUCT(O24:P24,$O$7:$P$7)/$Q$7 -> 75 | V24: 4 | W24: 0.15 | Y24: Year # | Z24: Owner Split (%)
B25: FF&E Financing | G25: Upfront | N25: Occupancy & Sales Tax (% of Rev) | O25: 0.1475 | P25: 0 | Q25: =SUMPRODUCT(O25:P25,$O$7:$P$7)/$Q$7 -> 0.1475 | S25: Average Length of Stay | V25: 5 | W25: 0.15 | Y25: 1 | Z25: 0.9
N26: Tax Pass Through | O26: 1 | P26: 1 | Q26: =SUMPRODUCT(O26:P26,$O$7:$P$7)/$Q$7 -> 1 | S26: Year | T26: ALOS | V26: 6 | W26: 0.15 | Y26: 2 | Z26: 0.9
B27: Unit Inputs | I27: Blended | K27: =SUM(K19:K24) -> 1 | L27: =ROUND(SUMPRODUCT(K19:K24,L19:L24),2) -> 0.7 | N27: Information Technology | O27: 0.02 | P27: 0.02 | Q27: =SUMPRODUCT(O27:P27,$O$7:$P$7)/$Q$7 -> 0.02 | S27: 1 | T27: 6 | V27: 7 | W27: 0.15 | Y27: 3 | Z27: 0.9
C28: Studio | D28: 1 Bed | E28: 2 Bed | F28: 3 Bed | G28: Total / AVG | N28: Management Fee | O28: 0.05 | P28: 0.05 | Q28: =SUMPRODUCT(O28:P28,$O$7:$P$7)/$Q$7 -> 0.05 | S28: 2 | T28: 6 | V28: 8 | W28: 0.15 | Y28: 4 | Z28: 0.9
B29: =IF($G$19<>"Long Term","Short Term Units (STR)","") -> Short Term Units (STR) | C29: =Assumptions!C28 -> 12 | D29: =Assumptions!C29+Assumptions!C32 -> 80 | E29: =Assumptions!C30+Assumptions!C31 -> 39 | F29: 0 | G29: =SUM(C29:F29) -> 131 | I29: Ramp | N29: Liability, FF&E Insurance / Permits | O29: 40 | P29: 40 | Q29: =SUMPRODUCT(O29:P29,$O$7:$P$7)/$Q$7 -> 40 | S29: 3 | T29: 6 | V29: 9 | W29: 0.15 | Y29: 5 | Z29: 0.9
B30: =IF($G$19<>"Short Term","Long Term Units (LTL)","") | G30: =SUM(C30:F30) -> 0 | I30: Start Date | L30: =+'Assumptions MH'!G20 -> 45658 | N30: Property Insurance | O30: 0 | P30: 60 | Q30: =SUMPRODUCT(O30:P30,$O$7:$P$7)/$Q$7 -> 0 | S30: 4 | T30: 6 | V30: 10 | W30: 0.15 | Y30: 6 | Z30: 0.9
B31: Blended Units | C31: =SUM(C29:C30) -> 12 | D31: =SUM(D29:D30) -> 80 | E31: =SUM(E29:E30) -> 39 | F31: =SUM(F29:F30) -> 0 | G31: =SUM(C31:F31) -> 131 | I31: Initial Ramp | L31: 0.35 | N31: Maintenance, Supplies, Subcontracting | O31: 90 | P31: 40 | Q31: =SUMPRODUCT(O31:P31,$O$7:$P$7)/$Q$7 -> 90 | S31: 5 | T31: 6 | Y31: 7 | Z31: 0.9
I32: Months to Stabilization | L32: 18 | S32: 6 | T32: 6 | V32: Multifamily Assumptions | Y32: 8 | Z32: 0.9
B33: Avg. Unit Size | C33: =Assumptions!E28 -> 458 | D33: =((Assumptions!C29*Assumptions!E29)+(Assumptions!C32*Assumptions!E32))/(Assumptions!C29+Assumptions!C32) -> 715.075 | E33: =((Assumptions!C30*Assumptions!E30)+(Assumptions!C31*Assumptions!E31))/(Assumptions!C30+Assumptions!C31) -> 1040.8974 | F33: 0 | G33: =SUMPRODUCT(C33:F33,$C$31:$F$31)/$G$31 -> 788.52672 | I33: Start Month | J33: End Month | K33: Step Up/Mo | L33: % Ramped | N33: Tax Assumptions | S33: 7 | T33: 6 | V33: Margin on MF Rent | W33: 0.581 | Y33: 9 | Z33: 0.9
I34: 1 | J34: 8 | K34: 0.0625 | L34: =+IF(J34>L32,"ERROR",MIN(L31+K34*(J34-I34),1)) -> 0.7875 | N34: Est. Property Taxes / Unit | S34: 8 | T34: 6 | V34: Multifamily Ramp | W34: 0 | Y34: 10 | Z34: 0.9
B35: =IF($G$19<>"Long Term","Multifamily Rent PSF - STR","") -> Multifamily Rent PSF - STR | C35: 3.4934498 | D35: 2.991453 | E35: 3.0365034 | F35: 0 | G35: =IFERROR(SUMPRODUCT(C35:F35,$C$29:$F$29)/$G$29,0) -> 3.0508494 | I35: =+IF(J34>=$L$32,"",J34+1) -> 9 | J35: =+IF(J34>=$L$32,"",L32) -> 18 | K35: =IFERROR(IF((1-L34)/(J35-I35+1)>0,(1-L34)/(J35-I35+1),0),"") -> 0.02125 | L35: =IFERROR(MIN(L34+K35*(J35-I35+1),1),"") -> 1 | N35: Est. STR Property Taxes | S35: 9 | T35: 6 | V35: Units Leased per Month | W35: 11
B36: =IF($G$19<>"Short Term","Multifamily Rent PSF - LTL","") | G36: =IFERROR(SUMPRODUCT(C36:F36,$C$30:$F$30)/$G$30,0) -> 0 | I36: ADR Recession Downturn | L36: 1 | N36: Source: Ownership | S36: 10 | T36: 6 | V36: MF Months to Stabilize | W36: =ROUNDUP(G31/W35,0) -> 12 | Y36: [2] To reflect staffing management, and leasing costs;
B37: Blended Rent PSF | C37: =IFERROR(SUMPRODUCT(C35:C36,C$29:C$30)/C$31,0) -> 3.4934498 | D37: =IFERROR(SUMPRODUCT(D35:D36,D$29:D$30)/D$31,0) -> 2.991453 | E37: =IFERROR(SUMPRODUCT(E35:E36,E$29:E$30)/E$31,0) -> 3.0365034 | F37: =IFERROR(SUMPRODUCT(F35:F36,F$29:F$30)/F$31,0) -> 0 | G37: =SUMPRODUCT(C37:F37,C31:F31)/G31 -> 3.0508494 | I37: Recession Recovery Rate | L37: 1 | V37: Y1 Multifamily Ramp % | W37: =IF(W34=1,SUM(W39:W50)/($G$31*12),1) -> 1 | Y37: fixed expenses (RE taxes, maintenance and insurance)
I38: Owner Priority Ramp | L38: 1 | N38: Ground Lease | S38: Capital Improvement | V38: Month # | W38: Units Ramped | Y38: not included
B39: =IF($G$19<>"Long Term","Multifamily Rent per Unit - STR","") -> Multifamily Rent per Unit - STR | C39: =C35*C33 -> 1600 | D39: =D35*D33 -> 2139.1132 | E39: =E35*E33 -> 3160.6886 | F39: =F35*F33 -> 0 | G39: =IFERROR(SUMPRODUCT(C39:F39,$C$29:$F$29)/$G$29,0) -> 2393.8619 | N39: Ground Lease | Q39: 0 | S39: Year | T39: FF&E Reserve | V39: 1 | W39: =+W35 -> 11
B40: =IF($G$19<>"Short Term","Multifamily Rent per Unit - LTL","") | C40: =C36*C33 -> 0 | D40: =D36*D33 -> 0 | E40: =E36*E33 -> 0 | F40: =F36*F33 -> 0 | G40: =IFERROR(SUMPRODUCT(C40:F40,$C$30:$F$30)/$G$30,0) -> 0 | I40: Parking [1] | S40: 1 | T40: 0 | V40: 2 | W40: =IF(COUNTA(V$39:V40)<$W$36,W39+$W$35,$G$31) -> 22
B41: Blended Rent per Unit | C41: =IFERROR(SUMPRODUCT(C39:C40,C$29:C$30)/C$31,0) -> 1600 | D41: =IFERROR(SUMPRODUCT(D39:D40,D$29:D$30)/D$31,0) -> 2139.1132 | E41: =IFERROR(SUMPRODUCT(E39:E40,E$29:E$30)/E$31,0) -> 3160.6886 | F41: =IFERROR(SUMPRODUCT(F39:F40,F$29:F$30)/F$31,0) -> 0 | G41: =SUMPRODUCT(C41:F41,C31:F31)/G31 -> 2393.8619 | I41: Parking Spots | L41: =Assumptions!$F$46 -> 145 | S41: 2 | T41: 0.01 | V41: 3 | W41: =IF(COUNTA(V$39:V41)<$W$36,W40+$W$35,$G$31) -> 33
I42: Mint House Nightly Rate | L42: 30 | S42: 3 | T42: 0.02 | V42: 4 | W42: =IF(COUNTA(V$39:V42)<$W$36,W41+$W$35,$G$31) -> 44
...

Sheet Budget Detail
B5: Build Tools COA
B7: CATEGORY CODE | C7: CATEGORY NAME | D7: Key for CF | E7: % EST. | G7: Spent To Date | H7: Remaining Costs | I7: Phase 1 | J7: Phase 2 | K7: Total | L7: Notes:
B8: 100 | C8: Land / Project Purchase
B9: 110 | C9: Project Purchase | D9: Land | G9: 5200000 | H9: =K9-G9 -> 0 | I9: =K9 -> 5200000 | K9: =Assumptions!N12 -> 5200000
B10: 115 | C10: Acquisition Fee | D10: Soft Costs (Excl. D/S) | E10: 0 | G10: 0 | H10: =K10-G10 -> 0 | I10: =K10 -> 0 | K10: =E10*K9 -> 0
B11: 120 | C11: Broker Fee | D11: Soft Costs (Excl. D/S) | E11: 0 | G11: 0 | H11: =K11-G11 -> 0 | I11: =K11 -> 0 | K11: =K9*E11 -> 0
B12: 130 | C12: Closing Costs | D12: Soft Costs (Excl. D/S) | G12: 12017 | H12: =K12-G12 -> 7983 | I12: =K12 -> 20000 | K12: 20000
B13: 135 | C13: Transfer Taxes | D13: Soft Costs (Excl. D/S) | G13: 19241 | H13: =K13-G13 -> 37936.836 | I13: =K13 -> 57177.836 | K13: =19241+0.115*((Dashboard!$D$42-2000)/100) -> 57177.836 | L13: Realty transfer tax: $0.37 per $100 of purchase price for the realty transfer; Mortgage tax: $0.115 per $100 of indebtedness. (The first $2,000 of the debt is exempt from taxation.)
B14: 140 | C14: Survey | D14: Soft Costs (Excl. D/S) | G14: 4542.57 | H14: =K14-G14 -> 0 | I14: =K14 -> 4542.57 | K14: 4542.57 | L14: Paid $4,542 through 11.15.2022 / Raegan Smith survey included in Civil line
B15: 150 | C15: Title | D15: Soft Costs (Excl. D/S) | G15: 0 | H15: =K15-G15 -> 2850 | I15: =K15 -> 2850 | K15: 2850
B16: 160 | C16: Geotechnical | D16: Soft Costs (Excl. D/S) | G16: 25506.11 | H16: =K16-G16 -> 4950 | I16: =K16 -> 30456.11 | K16: =12500+13006.11+4950 -> 30456.11 | L16: Terracon invoices / infiltration testing
B17: 170 | C17: Environmental | D17: Soft Costs (Excl. D/S) | G17: 16350 | H17: =K17-G17 -> 0 | I17: =K17 -> 16350 | K17: 16350 | L17: Phase 1 & 2
B18: 180 | C18: Due Diligence - Other | D18: Soft Costs (Excl. D/S) | G18: 16424.28 | H18: =K18-G18 -> 3575.72 | I18: =K18 -> 20000 | K18: 20000 | O18: Property Tax Estimate
C19: Total Land / Project Purchase | G19: =SUM(G9:G18) -> 5294081 | H19: =SUM(H9:H18) -> 57295.556 | I19: =SUM(I9:I18) -> 5351376.5 | J19: =SUM(J9:J18) -> 0 | K19: =SUM(K9:K18) -> 5351376.5 | P19: 44926 | Q19: =EOMONTH(P19,12) -> 45291 | R19: =EOMONTH(Q19,12) -> 45657 | S19: =EOMONTH(R19,12) -> 46022
O20: Total Market Value | P20: ='Tax Projection'!B15 -> 5200000 | Q20: ='Tax Projection'!B20 -> 32108209 | R20: ='Tax Projection'!B26 -> 43640298 | S20: ='Tax Projection'!B32 -> 44160298
B21: 200 | C21: Finance | I21: =K21 -> 0 | O21: Value Per Unit | P21: =P20/Assumptions!$M$77 -> 39694.656 | Q21: =Q20/Assumptions!$M$77 -> 245100.83 | R21: =R20/Assumptions!$M$77 -> 333132.05 | S21: =S20/Assumptions!$M$77 -> 337101.51
B22: 210 | C22: Loan Origination Fee | D22: Loan Fees | E22: =Assumptions!E62 -> 0.0075 | G22: 0 | H22: =K22-G22 -> 247429.15 | I22: =K22 -> 247429.15 | K22: =-'Monthly-CF'!I73 -> 247429.15
B23: 220 | C23: Loan Interest | D23: Interest | G23: 0 | H23: =K23-G23 -> 2474291.5 | I23: =K23 -> 2474291.5 | K23: ='Monthly-CF'!I109*7.5% -> 2474291.5 | L23: Assumes 12 months of debt service on fully drawn loan at 7.5% interest rate | O23: Assessment Ratio | P23: 0.4 | Q23: =P23 -> 0.4 | R23: =Q23 -> 0.4 | S23: =R23 -> 0.4
B24: 230 | C24: Real Estate Taxes | D24: Soft Costs (Excl. D/S) | G24: 29810.56 | H24: =K24-G24 -> 432120.96 | I24: =K24 -> 461931.52 | K24: =SUM('RE Tax'!G43:H43) -> 461931.52 | L24: See "RE Tax" tab for detail | O24: Tax Rate | P24: ='Tax Projection'!B17 -> 0.0335376 | Q24: ='Tax Projection'!B22 -> 0.034208352 | R24: ='Tax Projection'!B28 -> 0.034892519 | S24: ='Tax Projection'!B34 -> 0.035590369
B25: 240 | C25: Accounting | D25: Soft Costs (Excl. D/S) | G25: 3338.3 | H25: =K25-G25 -> 21661.7 | I25: =K25 -> 25000 | K25: 25000 | L25: Third party tax prep / accounting services | O25: Est. Valuation Haircut
B26: 250 | C26: Entity Expenses | D26: Soft Costs (Excl. D/S) | G26: 2493.47 | H26: =K26-G26 -> -2493.47 | I26: =K26 -> 0 | K26: 0 | O26: Assesed Value | P26: =P20*P23 -> 2080000 | Q26: =Q20*Q23 -> 12843283 | R26: =R20*R23 -> 17456119 | S26: =S20*S23 -> 17664119
B27: 260 | C27: Lease Up Costs | D27: Soft Costs (Excl. D/S) | G27: 0 | H27: =K27-G27 -> 0 | I27: =K27 -> 0 | K27: =Assumptions!M69 -> 0
B28: 270 | C28: Operating Expense Loss | G28: 0 | H28: =K28-G28 -> 300000 | I28: =K28 -> 300000 | K28: 300000 | O28: Est. Property Taxes Payable | P28: =P26*P24*(1-P25) -> 69758.208 | Q28: =Q26*Q24*(1-Q25) -> 439347.56 | R28: =R26*R24*(1-R25) -> 609087.97 | S28: =S26*S24*(1-S25) -> 628672.53
B29: 280 | C29: Financing Fees - Other | D29: Soft Costs (Excl. D/S) | G29: =+SUM(G30:G32) -> 400000 | H29: =K29-G29 -> 334905.53 | I29: =K29 -> 734905.53 | K29: =+SUM(K30:K32) -> 734905.53
C30: Debt Placement Fee | E30: 0.01 | G30: 0 | H30: =K30-G30 -> 329905.53 | I30: =K30 -> 329905.53 | K30: =E30*'Monthly-CF'!$I$109 -> 329905.53 | O30: Est. Payable during Constr. Period | P30: =SUM(P28:P29) -> 69758.208
C31: Land Loan / Carry Costs | G31: 400000 | H31: =K31-G31 -> 0 | I31: =K31 -> 400000 | K31: =G31 -> 400000 | O31: Taxes per Unit | Q31: =Q28/Assumptions!$C$34 -> 3353.7982 | R31: =R28/Assumptions!$C$34 -> 4649.5265 | S31: =S28/Assumptions!$C$34 -> 4799.0269
C32: Appraisal | G32: 0 | H32: =K32-G32 -> 5000 | I32: =K32 -> 5000 | K32: 5000
C33: Total Finance | G33: =SUM(G22:G29) -> 435642.33 | H33: =SUM(H22:H29) -> 3807915.4 | I33: =SUM(I22:I29) -> 4243557.7 | J33: =SUM(J22:J29) -> 0 | K33: =SUM(K22:K29) -> 4243557.7
B35: 300 | C35: Consultants | D35: Soft Costs (Excl. D/S) | G35: 0 | H35: =K35-G35 -> 0 | I35: =K35 -> 0
B36: 310 | C36: Architectural | D36: Soft Costs (Excl. D/S) | G36: 1036221.6 | H36: =K36-G36 -> 163778.38 | I36: =K36 -> 1200000 | K36: =630000+508450+61550 -> 1200000 | L36: Includes contracts for Pettas and Comma Design / added ~$60K to account for Comma construction admin and additional services
B37: 320 | C37: Landscape Architecture | D37: Soft Costs (Excl. D/S) | G37: 28325 | H37: =K37-G37 -> 1675 | I37: =K37 -> 30000 | K37: 30000 | L37: KVD Landscape Contract
B38: 330 | C38: Interior Design | D38: Soft Costs (Excl. D/S) | G38: 0 | H38: =K38-G38 -> 25000 | I38: =K38 -> 25000 | K38: 25000 | L38: Allowance
B39: 340 | C39: Civil Engineering | D39: Soft Costs (Excl. D/S) | G39: 119035.05 | H39: =K39-G39 -> 40000 | I39: =K39 -> 159035.05 | K39: =119035.05+40000 -> 159035.05 | L39: Includes Thomas & Hutton contract ($83.8K)/ $14k for traffic study / $17K Raegan Smith for Survey // $40K Soil management plan
B40: 350 | C40: Project Management / Coordination | D40: Soft Costs (Excl. D/S) | G40: 0 | H40: =K40-G40 -> 0 | I40: =K40 -> 0
G41: 0 | H41: =K41-G41 -> 0 | K41: 0
B42: 370 | C42: Consultants - Other | D42: Soft Costs (Excl. D/S) | G42: 660 | H42: =K42-G42 -> 49340 | I42: =K42 -> 50000 | K42: 50000 | L42: Allowance
C43: Total Consultants | G43: =SUM(G36:G42) -> 1184241.7 | H43: =SUM(H36:H42) -> 279793.38 | I43: =SUM(I36:I42) -> 1464035.1 | J43: =SUM(J36:J42) -> 0 | K43: =SUM(K36:K42) -> 1464035.1
B45: 400 | C45: Soft Costs | D45: Soft Costs (Excl. D/S) | G45: 0 | H45: =K45-G45 -> 0 | I45: =K45 -> 0
B46: 410 | C46: Insurance | D46: Soft Costs (Excl. D/S) | E46: 0.006 | F46: =K46/(K66+K68) -> 0.01440119 | G46: 689 | H46: =K46-G46 -> 513841 | I46: =K46 -> 514530 | K46: 514530 | L46: Builders Risk quote from Gallagher - 3.23.2303
B47: 420 | C47: Marketing | D47: Soft Costs (Excl. D/S) | G47: 0 | H47: =K47-G47 -> 30000 | I47: =K47 -> 30000 | K47: 30000
...

Sheet Annual-CF
W1: x
W2: x
W3: x
W4: x
C5: Annual Cash Flow | W5: x
W6: x
W7: x
L8: =EOMONTH('Monthly-CF'!L8,11) -> 45443 | M8: =EOMONTH(L8,12) -> 45808 | N8: =EOMONTH(M8,12) -> 46173 | O8: =EOMONTH(N8,12) -> 46538 | P8: =EOMONTH(O8,12) -> 46904 | Q8: =EOMONTH(P8,12) -> 47269 | R8: =EOMONTH(Q8,12) -> 47634 | S8: =EOMONTH(R8,12) -> 47999 | T8: =EOMONTH(S8,12) -> 48365 | U8: =EOMONTH(T8,12) -> 48730 | W8: x
L9: 1 | M9: =L9+1 -> 2 | N9: =M9+1 -> 3 | O9: =N9+1 -> 4 | P9: =O9+1 -> 5 | Q9: =P9+1 -> 6 | R9: =Q9+1 -> 7 | S9: =R9+1 -> 8 | T9: =S9+1 -> 9 | U9: =T9+1 -> 10 | W9: x
I10: Total | W10: x
D11: Residential Summary
D12: Occupancy | W12: x
D13: Occ - Multi-Family Ph.1 | I13: =MAX(L13:U13) -> 0 | L13: =_xlfn.MAXIFS('Monthly-CF'!$L13:$EA13,'Monthly-CF'!$L$9:$EA$9,'Annual-CF'!L$9) -> 0 | M13: =_xlfn.MAXIFS('Monthly-CF'!$L13:$EA13,'Monthly-CF'!$L$9:$EA$9,'Annual-CF'!M$9) -> 0 | N13: =_xlfn.MAXIFS('Monthly-CF'!$L13:$EA13,'Monthly-CF'!$L$9:$EA$9,'Annual-CF'!N$9) -> 0 | O13: =_xlfn.MAXIFS('Monthly-CF'!$L13:$EA13,'Monthly-CF'!$L$9:$EA$9,'Annual-CF'!O$9) -> 0 | P13: =_xlfn.MAXIFS('Monthly-CF'!$L13:$EA13,'Monthly-CF'!$L$9:$EA$9,'Annual-CF'!P$9) -> 0 | Q13: =_xlfn.MAXIFS('Monthly-CF'!$L13:$EA13,'Monthly-CF'!$L$9:$EA$9,'Annual-CF'!Q$9) -> 0 | R13: =_xlfn.MAXIFS('Monthly-CF'!$L13:$EA13,'Monthly-CF'!$L$9:$EA$9,'Annual-CF'!R$9) -> 0 | S13: =_xlfn.MAXIFS('Monthly-CF'!$L13:$EA13,'Monthly-CF'!$L$9:$EA$9,'Annual-CF'!S$9) -> 0 | ... U13: =_xlfn.MAXIFS('Monthly-CF'!$L13:$EA13,'Monthly-CF'!$L$9:$EA$9,'Annual-CF'!U$9) -> 0 | W13: x
D14: Occ - Multi-Family Ph.2 | I14: =MAX(L14:U14) -> 0 | L14: =_xlfn.MAXIFS('Monthly-CF'!$L14:$EA14,'Monthly-CF'!$L$9:$EA$9,'Annual-CF'!L$9) -> 0 | M14: =_xlfn.MAXIFS('Monthly-CF'!$L14:$EA14,'Monthly-CF'!$L$9:$EA$9,'Annual-CF'!M$9) -> 0 | N14: =_xlfn.MAXIFS('Monthly-CF'!$L14:$EA14,'Monthly-CF'!$L$9:$EA$9,'Annual-CF'!N$9) -> 0 | O14: =_xlfn.MAXIFS('Monthly-CF'!$L14:$EA14,'Monthly-CF'!$L$9:$EA$9,'Annual-CF'!O$9) -> 0 | P14: =_xlfn.MAXIFS('Monthly-CF'!$L14:$EA14,'Monthly-CF'!$L$9:$EA$9,'Annual-CF'!P$9) -> 0 | Q14: =_xlfn.MAXIFS('Monthly-CF'!$L14:$EA14,'Monthly-CF'!$L$9:$EA$9,'Annual-CF'!Q$9) -> 0 | R14: =_xlfn.MAXIFS('Monthly-CF'!$L14:$EA14,'Monthly-CF'!$L$9:$EA$9,'Annual-CF'!R$9) -> 0 | S14: =_xlfn.MAXIFS('Monthly-CF'!$L14:$EA14,'Monthly-CF'!$L$9:$EA$9,'Annual-CF'!S$9) -> 0 | ... U14: =_xlfn.MAXIFS('Monthly-CF'!$L14:$EA14,'Monthly-CF'!$L$9:$EA$9,'Annual-CF'!U$9) -> 0 | W14: x
D15: =CONCATENATE("Occ - ",Assumptions!$J$54) -> Occ - Ancillary Fees | I15: =MAX(L15:U15) -> 0 | L15: =_xlfn.MAXIFS('Monthly-CF'!$L15:$EA15,'Monthly-CF'!$L$9:$EA$9,'Annual-CF'!L$9) -> 0 | M15: =_xlfn.MAXIFS('Monthly-CF'!$L15:$EA15,'Monthly-CF'!$L$9:$EA$9,'Annual-CF'!M$9) -> 0 | N15: =_xlfn.MAXIFS('Monthly-CF'!$L15:$EA15,'Monthly-CF'!$L$9:$EA$9,'Annual-CF'!N$9) -> 0 | O15: =_xlfn.MAXIFS('Monthly-CF'!$L15:$EA15,'Monthly-CF'!$L$9:$EA$9,'Annual-CF'!O$9) -> 0 | P15: =_xlfn.MAXIFS('Monthly-CF'!$L15:$EA15,'Monthly-CF'!$L$9:$EA$9,'Annual-CF'!P$9) -> 0 | Q15: =_xlfn.MAXIFS('Monthly-CF'!$L15:$EA15,'Monthly-CF'!$L$9:$EA$9,'Annual-CF'!Q$9) -> 0 | R15: =_xlfn.MAXIFS('Monthly-CF'!$L15:$EA15,'Monthly-CF'!$L$9:$EA$9,'Annual-CF'!R$9) -> 0 | S15: =_xlfn.MAXIFS('Monthly-CF'!$L15:$EA15,'Monthly-CF'!$L$9:$EA$9,'Annual-CF'!S$9) -> 0 | ... U15: =_xlfn.MAXIFS('Monthly-CF'!$L15:$EA15,'Monthly-CF'!$L$9:$EA$9,'Annual-CF'!U$9) -> 0 | W15: x
W16: x
D17: Leased SF | L17: 0 | M17: =Assumptions!$H$56 -> 0.04 | N17: =((1+M17)*(1+Assumptions!$H$56))-1 -> 0.0816 | O17: =((1+N17)*(1+Assumptions!$H$56))-1 -> 0.124864 | P17: =((1+O17)*(1+Assumptions!$H$56))-1 -> 0.16985856 | Q17: =((1+P17)*(1+Assumptions!$H$56))-1 -> 0.2166529 | R17: =((1+Q17)*(1+Assumptions!$H$56))-1 -> 0.26531902 | S17: =((1+R17)*(1+Assumptions!$H$56))-1 -> 0.31593178 | T17: =((1+S17)*(1+Assumptions!$H$56))-1 -> 0.36856905 | U17: =((1+T17)*(1+Assumptions!$H$56))-1 -> 0.42331181 | W17: x
D18: PSF - Multi-Family Ph.1 | I18: =MAX(L18:U18) -> 0 | L18: =_xlfn.MAXIFS('Monthly-CF'!$L18:$EA18,'Monthly-CF'!$L$9:$EA$9,'Annual-CF'!L$9) -> 0 | M18: =_xlfn.MAXIFS('Monthly-CF'!$L18:$EA18,'Monthly-CF'!$L$9:$EA$9,'Annual-CF'!M$9) -> 0 | N18: =_xlfn.MAXIFS('Monthly-CF'!$L18:$EA18,'Monthly-CF'!$L$9:$EA$9,'Annual-CF'!N$9) -> 0 | O18: =_xlfn.MAXIFS('Monthly-CF'!$L18:$EA18,'Monthly-CF'!$L$9:$EA$9,'Annual-CF'!O$9) -> 0 | P18: =_xlfn.MAXIFS('Monthly-CF'!$L18:$EA18,'Monthly-CF'!$L$9:$EA$9,'Annual-CF'!P$9) -> 0 | Q18: =_xlfn.MAXIFS('Monthly-CF'!$L18:$EA18,'Monthly-CF'!$L$9:$EA$9,'Annual-CF'!Q$9) -> 0 | R18: =_xlfn.MAXIFS('Monthly-CF'!$L18:$EA18,'Monthly-CF'!$L$9:$EA$9,'Annual-CF'!R$9) -> 0 | S18: =_xlfn.MAXIFS('Monthly-CF'!$L18:$EA18,'Monthly-CF'!$L$9:$EA$9,'Annual-CF'!S$9) -> 0 | ... U18: =_xlfn.MAXIFS('Monthly-CF'!$L18:$EA18,'Monthly-CF'!$L$9:$EA$9,'Annual-CF'!U$9) -> 0 | W18: x
D19: PSF - Multi-Family Ph.2 | I19: =MAX(L19:U19) -> 0 | L19: =_xlfn.MAXIFS('Monthly-CF'!$L19:$EA19,'Monthly-CF'!$L$9:$EA$9,'Annual-CF'!L$9) -> 0 | M19: =_xlfn.MAXIFS('Monthly-CF'!$L19:$EA19,'Monthly-CF'!$L$9:$EA$9,'Annual-CF'!M$9) -> 0 | N19: =_xlfn.MAXIFS('Monthly-CF'!$L19:$EA19,'Monthly-CF'!$L$9:$EA$9,'Annual-CF'!N$9) -> 0 | O19: =_xlfn.MAXIFS('Monthly-CF'!$L19:$EA19,'Monthly-CF'!$L$9:$EA$9,'Annual-CF'!O$9) -> 0 | P19: =_xlfn.MAXIFS('Monthly-CF'!$L19:$EA19,'Monthly-CF'!$L$9:$EA$9,'Annual-CF'!P$9) -> 0 | Q19: =_xlfn.MAXIFS('Monthly-CF'!$L19:$EA19,'Monthly-CF'!$L$9:$EA$9,'Annual-CF'!Q$9) -> 0 | R19: =_xlfn.MAXIFS('Monthly-CF'!$L19:$EA19,'Monthly-CF'!$L$9:$EA$9,'Annual-CF'!R$9) -> 0 | S19: =_xlfn.MAXIFS('Monthly-CF'!$L19:$EA19,'Monthly-CF'!$L$9:$EA$9,'Annual-CF'!S$9) -> 0 | ... U19: =_xlfn.MAXIFS('Monthly-CF'!$L19:$EA19,'Monthly-CF'!$L$9:$EA$9,'Annual-CF'!U$9) -> 0 | W19: x
D20: =CONCATENATE("PSF - ",Assumptions!J54) -> PSF - Ancillary Fees | I20: =MAX(L20:U20) -> 0 | L20: =_xlfn.MAXIFS('Monthly-CF'!$L20:$EA20,'Monthly-CF'!$L$9:$EA$9,'Annual-CF'!L$9) -> 0 | M20: =_xlfn.MAXIFS('Monthly-CF'!$L20:$EA20,'Monthly-CF'!$L$9:$EA$9,'Annual-CF'!M$9) -> 0 | N20: =_xlfn.MAXIFS('Monthly-CF'!$L20:$EA20,'Monthly-CF'!$L$9:$EA$9,'Annual-CF'!N$9) -> 0 | O20: =_xlfn.MAXIFS('Monthly-CF'!$L20:$EA20,'Monthly-CF'!$L$9:$EA$9,'Annual-CF'!O$9) -> 0 | P20: =_xlfn.MAXIFS('Monthly-CF'!$L20:$EA20,'Monthly-CF'!$L$9:$EA$9,'Annual-CF'!P$9) -> 0 | Q20: =_xlfn.MAXIFS('Monthly-CF'!$L20:$EA20,'Monthly-CF'!$L$9:$EA$9,'Annual-CF'!Q$9) -> 0 | R20: =_xlfn.MAXIFS('Monthly-CF'!$L20:$EA20,'Monthly-CF'!$L$9:$EA$9,'Annual-CF'!R$9) -> 0 | S20: =_xlfn.MAXIFS('Monthly-CF'!$L20:$EA20,'Monthly-CF'!$L$9:$EA$9,'Annual-CF'!S$9) -> 0 | ... U20: =_xlfn.MAXIFS('Monthly-CF'!$L20:$EA20,'Monthly-CF'!$L$9:$EA$9,'Annual-CF'!U$9) -> 0 | W20: x
W21: x
D22: Revenue | W22: x
D23: Revenue - Multi-Family Ph.1 | I23: =SUM(K23:U23) -> 0 | L23: =SUMIFS('Monthly-CF'!$L23:$EA23,'Monthly-CF'!$L$9:$EA$9,'Annual-CF'!L$9) -> 0 | M23: =SUMIFS('Monthly-CF'!$L23:$EA23,'Monthly-CF'!$L$9:$EA$9,'Annual-CF'!M$9) -> 0 | N23: =SUMIFS('Monthly-CF'!$L23:$EA23,'Monthly-CF'!$L$9:$EA$9,'Annual-CF'!N$9) -> 0 | O23: =SUMIFS('Monthly-CF'!$L23:$EA23,'Monthly-CF'!$L$9:$EA$9,'Annual-CF'!O$9) -> 0 | P23: =SUMIFS('Monthly-CF'!$L23:$EA23,'Monthly-CF'!$L$9:$EA$9,'Annual-CF'!P$9) -> 0 | Q23: =SUMIFS('Monthly-CF'!$L23:$EA23,'Monthly-CF'!$L$9:$EA$9,'Annual-CF'!Q$9) -> 0 | R23: =SUMIFS('Monthly-CF'!$L23:$EA23,'Monthly-CF'!$L$9:$EA$9,'Annual-CF'!R$9) -> 0 | S23: =SUMIFS('Monthly-CF'!$L23:$EA23,'Monthly-CF'!$L$9:$EA$9,'Annual-CF'!S$9) -> 0 | ... U23: =SUMIFS('Monthly-CF'!$L23:$EA23,'Monthly-CF'!$L$9:$EA$9,'Annual-CF'!U$9) -> 0 | W23: x
D24: Revenue - Multi-Family Ph.2 | I24: =SUM(K24:U24) -> 0 | L24: =SUMIFS('Monthly-CF'!$L24:$EA24,'Monthly-CF'!$L$9:$EA$9,'Annual-CF'!L$9) -> 0 | M24: =SUMIFS('Monthly-CF'!$L24:$EA24,'Monthly-CF'!$L$9:$EA$9,'Annual-CF'!M$9) -> 0 | N24: =SUMIFS('Monthly-CF'!$L24:$EA24,'Monthly-CF'!$L$9:$EA$9,'Annual-CF'!N$9) -> 0 | O24: =SUMIFS('Monthly-CF'!$L24:$EA24,'Monthly-CF'!$L$9:$EA$9,'Annual-CF'!O$9) -> 0 | P24: =SUMIFS('Monthly-CF'!$L24:$EA24,'Monthly-CF'!$L$9:$EA$9,'Annual-CF'!P$9) -> 0 | Q24: =SUMIFS('Monthly-CF'!$L24:$EA24,'Monthly-CF'!$L$9:$EA$9,'Annual-CF'!Q$9) -> 0 | R24: =SUMIFS('Monthly-CF'!$L24:$EA24,'Monthly-CF'!$L$9:$EA$9,'Annual-CF'!R$9) -> 0 | S24: =SUMIFS('Monthly-CF'!$L24:$EA24,'Monthly-CF'!$L$9:$EA$9,'Annual-CF'!S$9) -> 0 | ... U24: =SUMIFS('Monthly-CF'!$L24:$EA24,'Monthly-CF'!$L$9:$EA$9,'Annual-CF'!U$9) -> 0 | W24: x
D25: =CONCATENATE("Revenue - ",Assumptions!J$54) -> Revenue - Ancillary Fees | I25: =SUM(K25:U25) -> 0 | L25: =SUMIFS('Monthly-CF'!$L25:$EA25,'Monthly-CF'!$L$9:$EA$9,'Annual-CF'!L$9) -> 0 | M25: =SUMIFS('Monthly-CF'!$L25:$EA25,'Monthly-CF'!$L$9:$EA$9,'Annual-CF'!M$9) -> 0 | N25: =SUMIFS('Monthly-CF'!$L25:$EA25,'Monthly-CF'!$L$9:$EA$9,'Annual-CF'!N$9) -> 0 | O25: =SUMIFS('Monthly-CF'!$L25:$EA25,'Monthly-CF'!$L$9:$EA$9,'Annual-CF'!O$9) -> 0 | P25: =SUMIFS('Monthly-CF'!$L25:$EA25,'Monthly-CF'!$L$9:$EA$9,'Annual-CF'!P$9) -> 0 | Q25: =SUMIFS('Monthly-CF'!$L25:$EA25,'Monthly-CF'!$L$9:$EA$9,'Annual-CF'!Q$9) -> 0 | R25: =SUMIFS('Monthly-CF'!$L25:$EA25,'Monthly-CF'!$L$9:$EA$9,'Annual-CF'!R$9) -> 0 | S25: =SUMIFS('Monthly-CF'!$L25:$EA25,'Monthly-CF'!$L$9:$EA$9,'Annual-CF'!S$9) -> 0 | ... U25: =SUMIFS('Monthly-CF'!$L25:$EA25,'Monthly-CF'!$L$9:$EA$9,'Annual-CF'!U$9) -> 0 | W25: x
W26: x
D27: Rent Concessions | I27: =SUM(K27:U27) -> 0 | L27: =SUMIFS('Monthly-CF'!$L27:$EA27,'Monthly-CF'!$L$9:$EA$9,'Annual-CF'!L$9) -> 0 | M27: =SUMIFS('Monthly-CF'!$L27:$EA27,'Monthly-CF'!$L$9:$EA$9,'Annual-CF'!M$9) -> 0 | N27: =SUMIFS('Monthly-CF'!$L27:$EA27,'Monthly-CF'!$L$9:$EA$9,'Annual-CF'!N$9) -> 0 | O27: =SUMIFS('Monthly-CF'!$L27:$EA27,'Monthly-CF'!$L$9:$EA$9,'Annual-CF'!O$9) -> 0 | P27: =SUMIFS('Monthly-CF'!$L27:$EA27,'Monthly-CF'!$L$9:$EA$9,'Annual-CF'!P$9) -> 0 | Q27: =SUMIFS('Monthly-CF'!$L27:$EA27,'Monthly-CF'!$L$9:$EA$9,'Annual-CF'!Q$9) -> 0 | R27: =SUMIFS('Monthly-CF'!$L27:$EA27,'Monthly-CF'!$L$9:$EA$9,'Annual-CF'!R$9) -> 0 | S27: =SUMIFS('Monthly-CF'!$L27:$EA27,'Monthly-CF'!$L$9:$EA$9,'Annual-CF'!S$9) -> 0 | ... U27: =SUMIFS('Monthly-CF'!$L27:$EA27,'Monthly-CF'!$L$9:$EA$9,'Annual-CF'!U$9) -> 0 | W27: x
D28: Net Revenue | I28: =SUM(K28:U28) -> 0 | L28: =SUM(L23:L25)+SUM(L27:L27) -> 0 | M28: =SUM(M23:M25)+SUM(M27:M27) -> 0 | N28: =SUM(N23:N25)+SUM(N27:N27) -> 0 | O28: =SUM(O23:O25)+SUM(O27:O27) -> 0 | P28: =SUM(P23:P25)+SUM(P27:P27) -> 0 | Q28: =SUM(Q23:Q25)+SUM(Q27:Q27) -> 0 | R28: =SUM(R23:R25)+SUM(R27:R27) -> 0 | S28: =SUM(S23:S25)+SUM(S27:S27) -> 0 | ... U28: =SUM(U23:U25)+SUM(U27:U27) -> 0 | W28: x
W29: x
L30: 0 | M30: =Assumptions!$I$81 -> 0.03 | N30: =((1+M30)*(1+Assumptions!$I$81))-1 -> 0.0609 | O30: =((1+N30)*(1+Assumptions!$I$81))-1 -> 0.092727 | P30: =((1+O30)*(1+Assumptions!$I$81))-1 -> 0.12550881 | Q30: =((1+P30)*(1+Assumptions!$I$81))-1 -> 0.15927407 | R30: =((1+Q30)*(1+Assumptions!$I$81))-1 -> 0.1940523 | S30: =((1+R30)*(1+Assumptions!$I$81))-1 -> 0.22987387 | T30: =((1+S30)*(1+Assumptions!$I$81))-1 -> 0.26677008 | U30: =((1+T30)*(1+Assumptions!$I$81))-1 -> 0.30477318 | W30: x
D31: Op Exp - Multi-Family Ph.1 | I31: =SUM(K31:U31) -> 0 | L31: =SUMIFS('Monthly-CF'!$L31:$EA31,'Monthly-CF'!$L$9:$EA$9,'Annual-CF'!L$9) -> 0 | M31: =SUMIFS('Monthly-CF'!$L31:$EA31,'Monthly-CF'!$L$9:$EA$9,'Annual-CF'!M$9) -> 0 | N31: =SUMIFS('Monthly-CF'!$L31:$EA31,'Monthly-CF'!$L$9:$EA$9,'Annual-CF'!N$9) -> 0 | O31: =SUMIFS('Monthly-CF'!$L31:$EA31,'Monthly-CF'!$L$9:$EA$9,'Annual-CF'!O$9) -> 0 | P31: =SUMIFS('Monthly-CF'!$L31:$EA31,'Monthly-CF'!$L$9:$EA$9,'Annual-CF'!P$9) -> 0 | Q31: =SUMIFS('Monthly-CF'!$L31:$EA31,'Monthly-CF'!$L$9:$EA$9,'Annual-CF'!Q$9) -> 0 | R31: =SUMIFS('Monthly-CF'!$L31:$EA31,'Monthly-CF'!$L$9:$EA$9,'Annual-CF'!R$9) -> 0 | S31: =SUMIFS('Monthly-CF'!$L31:$EA31,'Monthly-CF'!$L$9:$EA$9,'Annual-CF'!S$9) -> 0 | ... U31: =SUMIFS('Monthly-CF'!$L31:$EA31,'Monthly-CF'!$L$9:$EA$9,'Annual-CF'!U$9) -> 0 | W31: x
D32: Op Exp - Multi-Family Ph. 2 | I32: =SUM(K32:U32) -> 0 | L32: =SUMIFS('Monthly-CF'!$L32:$EA32,'Monthly-CF'!$L$9:$EA$9,'Annual-CF'!L$9) -> 0 | M32: =SUMIFS('Monthly-CF'!$L32:$EA32,'Monthly-CF'!$L$9:$EA$9,'Annual-CF'!M$9) -> 0 | N32: =SUMIFS('Monthly-CF'!$L32:$EA32,'Monthly-CF'!$L$9:$EA$9,'Annual-CF'!N$9) -> 0 | O32: =SUMIFS('Monthly-CF'!$L32:$EA32,'Monthly-CF'!$L$9:$EA$9,'Annual-CF'!O$9) -> 0 | P32: =SUMIFS('Monthly-CF'!$L32:$EA32,'Monthly-CF'!$L$9:$EA$9,'Annual-CF'!P$9) -> 0 | Q32: =SUMIFS('Monthly-CF'!$L32:$EA32,'Monthly-CF'!$L$9:$EA$9,'Annual-CF'!Q$9) -> 0 | R32: =SUMIFS('Monthly-CF'!$L32:$EA32,'Monthly-CF'!$L$9:$EA$9,'Annual-CF'!R$9) -> 0 | S32: =SUMIFS('Monthly-CF'!$L32:$EA32,'Monthly-CF'!$L$9:$EA$9,'Annual-CF'!S$9) -> 0 | ... U32: =SUMIFS('Monthly-CF'!$L32:$EA32,'Monthly-CF'!$L$9:$EA$9,'Annual-CF'!U$9) -> 0 | W32: x
D33: Total Operating Expenses | I33: =SUM(K33:U33) -> 0 | L33: =SUMIFS('Monthly-CF'!$L33:$EA33,'Monthly-CF'!$L$9:$EA$9,'Annual-CF'!L$9) -> 0 | M33: =SUMIFS('Monthly-CF'!$L33:$EA33,'Monthly-CF'!$L$9:$EA$9,'Annual-CF'!M$9) -> 0 | N33: =SUMIFS('Monthly-CF'!$L33:$EA33,'Monthly-CF'!$L$9:$EA$9,'Annual-CF'!N$9) -> 0 | O33: =SUMIFS('Monthly-CF'!$L33:$EA33,'Monthly-CF'!$L$9:$EA$9,'Annual-CF'!O$9) -> 0 | P33: =SUMIFS('Monthly-CF'!$L33:$EA33,'Monthly-CF'!$L$9:$EA$9,'Annual-CF'!P$9) -> 0 | Q33: =SUMIFS('Monthly-CF'!$L33:$EA33,'Monthly-CF'!$L$9:$EA$9,'Annual-CF'!Q$9) -> 0 | R33: =SUMIFS('Monthly-CF'!$L33:$EA33,'Monthly-CF'!$L$9:$EA$9,'Annual-CF'!R$9) -> 0 | S33: =SUMIFS('Monthly-CF'!$L33:$EA33,'Monthly-CF'!$L$9:$EA$9,'Annual-CF'!S$9) -> 0 | ... U33: =SUMIFS('Monthly-CF'!$L33:$EA33,'Monthly-CF'!$L$9:$EA$9,'Annual-CF'!U$9) -> 0 | W33: x
D34: Operating Income | I34: =SUM(K34:U34) -> 0 | L34: =L28+L33 -> 0 | M34: =M28+M33 -> 0 | N34: =N28+N33 -> 0 | O34: =O28+O33 -> 0 | P34: =P28+P33 -> 0 | Q34: =Q28+Q33 -> 0 | R34: =R28+R33 -> 0 | S34: =S28+S33 -> 0 | ... U34: =U28+U33 -> 0 | W34: x
W35: x
D36: Capital Reserve | I36: =SUM(K36:U36) -> 0 | L36: =SUMIFS('Monthly-CF'!$L36:$EA36,'Monthly-CF'!$L$9:$EA$9,'Annual-CF'!L$9) -> 0 | M36: =SUMIFS('Monthly-CF'!$L36:$EA36,'Monthly-CF'!$L$9:$EA$9,'Annual-CF'!M$9) -> 0 | N36: =SUMIFS('Monthly-CF'!$L36:$EA36,'Monthly-CF'!$L$9:$EA$9,'Annual-CF'!N$9) -> 0 | O36: =SUMIFS('Monthly-CF'!$L36:$EA36,'Monthly-CF'!$L$9:$EA$9,'Annual-CF'!O$9) -> 0 | P36: =SUMIFS('Monthly-CF'!$L36:$EA36,'Monthly-CF'!$L$9:$EA$9,'Annual-CF'!P$9) -> 0 | Q36: =SUMIFS('Monthly-CF'!$L36:$EA36,'Monthly-CF'!$L$9:$EA$9,'Annual-CF'!Q$9) -> 0 | R36: =SUMIFS('Monthly-CF'!$L36:$EA36,'Monthly-CF'!$L$9:$EA$9,'Annual-CF'!R$9) -> 0 | S36: =SUMIFS('Monthly-CF'!$L36:$EA36,'Monthly-CF'!$L$9:$EA$9,'Annual-CF'!S$9) -> 0 | ... U36: =SUMIFS('Monthly-CF'!$L36:$EA36,'Monthly-CF'!$L$9:$EA$9,'Annual-CF'!U$9) -> 0 | W36: x
D37: Operating Cash flow - Residential | I37: =SUM(K37:U37) -> 0 | L37: =L34+L36 -> 0 | M37: =M34+M36 -> 0 | N37: =N34+N36 -> 0 | O37: =O34+O36 -> 0 | P37: =P34+P36 -> 0 | Q37: =Q34+Q36 -> 0 | R37: =R34+R36 -> 0 | S37: =S34+S36 -> 0 | ... U37: =U34+U36 -> 0 | W37: x
W38: x
D39: Residential Summary - STR / MF | W39: x
D41: Income to Owner - After FF&E | I41: =SUM(K41:U41) -> 42410997 | L41: =SUMIFS('Monthly-CF'!$L41:$EA41,'Monthly-CF'!$L$9:$EA$9,'Annual-CF'!L$9) -> 0 | M41: =SUMIFS('Monthly-CF'!$L41:$EA41,'Monthly-CF'!$L$9:$EA$9,'Annual-CF'!M$9) -> 1008353.1 | N41: =SUMIFS('Monthly-CF'!$L41:$EA41,'Monthly-CF'!$L$9:$EA$9,'Annual-CF'!N$9) -> 4124076.8 | O41: =SUMIFS('Monthly-CF'!$L41:$EA41,'Monthly-CF'!$L$9:$EA$9,'Annual-CF'!O$9) -> 5125001.3 | P41: =SUMIFS('Monthly-CF'!$L41:$EA41,'Monthly-CF'!$L$9:$EA$9,'Annual-CF'!P$9) -> 5170334.9 | Q41: =SUMIFS('Monthly-CF'!$L41:$EA41,'Monthly-CF'!$L$9:$EA$9,'Annual-CF'!Q$9) -> 5202640.3 | R41: =SUMIFS('Monthly-CF'!$L41:$EA41,'Monthly-CF'!$L$9:$EA$9,'Annual-CF'!R$9) -> 5250319 | S41: =SUMIFS('Monthly-CF'!$L41:$EA41,'Monthly-CF'!$L$9:$EA$9,'Annual-CF'!S$9) -> 5342025.9 | ... U41: =SUMIFS('Monthly-CF'!$L41:$EA41,'Monthly-CF'!$L$9:$EA$9,'Annual-CF'!U$9) -> 5667355.3 | W41: x
...

Sheet Monthly-CF
EC1: x
EC2: x
EC3: x
EC4: x
C5: Monthly Cash Flow | EC5: x
EC6: x
EC7: x
L8: 45107 | M8: =EOMONTH(L8,1) -> 45138 | N8: =EOMONTH(M8,1) -> 45169 | O8: =EOMONTH(N8,1) -> 45199 | P8: =EOMONTH(O8,1) -> 45230 | Q8: =EOMONTH(P8,1) -> 45260 | R8: =EOMONTH(Q8,1) -> 45291 | S8: =EOMONTH(R8,1) -> 45322 | T8: =EOMONTH(S8,1) -> 45351 | ... EA8: =EOMONTH(DZ8,1) -> 48730 | EC8: x
L9: =ROUNDUP(L10/12,0) -> 1 | M9: =ROUNDUP(M10/12,0) -> 1 | N9: =ROUNDUP(N10/12,0) -> 1 | O9: =ROUNDUP(O10/12,0) -> 1 | P9: =ROUNDUP(P10/12,0) -> 1 | Q9: =ROUNDUP(Q10/12,0) -> 1 | R9: =ROUNDUP(R10/12,0) -> 1 | S9: =ROUNDUP(S10/12,0) -> 1 | ... EA9: =ROUNDUP(EA10/12,0) -> 10 | EC9: x
I10: Total | K10: Initial | L10: 1 | M10: =L10+1 -> 2 | N10: =M10+1 -> 3 | O10: =N10+1 -> 4 | P10: =O10+1 -> 5 | Q10: =P10+1 -> 6 | R10: =Q10+1 -> 7 | S10: =R10+1 -> 8 | T10: =S10+1 -> 9 | ... EA10: =DZ10+1 -> 120 | EC10: x
D11: Residential Summary
D12: Occupancy | EC12: x
D13: Occ - Multi-Family Ph.1 | I13: =MAX(L13:EA13) -> 0 | L13: =IF(L$8<=Assumptions!$M$58,IF(SUM($K$70:K$70)=$I$70,IF(K13=0,Assumptions!$H$59,MIN('Monthly-CF'!K13+Assumptions!$I$59,Assumptions!$J$59)),0),0) -> 0 | M13: =IF(M$8<=Assumptions!$M$58,IF(SUM($K$70:L$70)=$I$70,IF(L13=0,Assumptions!$H$59,MIN('Monthly-CF'!L13+Assumptions!$I$59,Assumptions!$J$59)),0),0) -> 0 | N13: =IF(N$8<=Assumptions!$M$58,IF(SUM($K$70:M$70)=$I$70,IF(M13=0,Assumptions!$H$59,MIN('Monthly-CF'!M13+Assumptions!$I$59,Assumptions!$J$59)),0),0) -> 0 | O13: =IF(O$8<=Assumptions!$M$58,IF(SUM($K$70:N$70)=$I$70,IF(N13=0,Assumptions!$H$59,MIN('Monthly-CF'!N13+Assumptions!$I$59,Assumptions!$J$59)),0),0) -> 0 | P13: =IF(P$8<=Assumptions!$M$58,IF(SUM($K$70:O$70)=$I$70,IF(O13=0,Assumptions!$H$59,MIN('Monthly-CF'!O13+Assumptions!$I$59,Assumptions!$J$59)),0),0) -> 0 | Q13: =IF(Q$8<=Assumptions!$M$58,IF(SUM($K$70:P$70)=$I$70,IF(P13=0,Assumptions!$H$59,MIN('Monthly-CF'!P13+Assumptions!$I$59,Assumptions!$J$59)),0),0) -> 0 | R13: =IF(R$8<=Assumptions!$M$58,IF(SUM($K$70:Q$70)=$I$70,IF(Q13=0,Assumptions!$H$59,MIN('Monthly-CF'!Q13+Assumptions!$I$59,Assumptions!$J$59)),0),0) -> 0 | S13: =IF(S$8<=Assumptions!$M$58,IF(SUM($K$70:R$70)=$I$70,IF(R13=0,Assumptions!$H$59,MIN('Monthly-CF'!R13+Assumptions!$I$59,Assumptions!$J$59)),0),0) -> 0 | ... EA13: =IF(EA$8<=Assumptions!$M$58,IF(SUM($K$70:DZ$70)=$I$70,IF(DZ13=0,Assumptions!$H$59,MIN('Monthly-CF'!DZ13+Assumptions!$I$59,Assumptions!$J$59)),0),0) -> 0 | EC13: x
D14: Occ - Multi-Family Ph.2 | I14: =MAX(L14:EA14) -> 0 | EC14: x
D15: =CONCATENATE("Occ - ",Assumptions!$J$54) -> Occ - Ancillary Fees | I15: =MAX(L15:EA15) -> 0 | L15: =IF(L13>0,IF(K15=0,Assumptions!$H$61,MIN('Monthly-CF'!K15+Assumptions!$I$61,Assumptions!$J$61)),0) -> 0 | M15: =IF(M13>0,IF(L15=0,Assumptions!$H$61,MIN('Monthly-CF'!L15+Assumptions!$I$61,Assumptions!$J$61)),0) -> 0 | N15: =IF(N13>0,IF(M15=0,Assumptions!$H$61,MIN('Monthly-CF'!M15+Assumptions!$I$61,Assumptions!$J$61)),0) -> 0 | O15: =IF(O13>0,IF(N15=0,Assumptions!$H$61,MIN('Monthly-CF'!N15+Assumptions!$I$61,Assumptions!$J$61)),0) -> 0 | P15: =IF(P13>0,IF(O15=0,Assumptions!$H$61,MIN('Monthly-CF'!O15+Assumptions!$I$61,Assumptions!$J$61)),0) -> 0 | Q15: =IF(Q13>0,IF(P15=0,Assumptions!$H$61,MIN('Monthly-CF'!P15+Assumptions!$I$61,Assumptions!$J$61)),0) -> 0 | R15: =IF(R13>0,IF(Q15=0,Assumptions!$H$61,MIN('Monthly-CF'!Q15+Assumptions!$I$61,Assumptions!$J$61)),0) -> 0 | S15: =IF(S13>0,IF(R15=0,Assumptions!$H$61,MIN('Monthly-CF'!R15+Assumptions!$I$61,Assumptions!$J$61)),0) -> 0 | ... EA15: =IF(EA13>0,IF(DZ15=0,Assumptions!$H$61,MIN('Monthly-CF'!DZ15+Assumptions!$I$61,Assumptions!$J$61)),0) -> 0 | EC15: x
EC16: x
D17: Leased SF | E17: Total SF | G17: Escalator | L17: =INDEX('Annual-CF'!$L$17:$U$17,MATCH('Monthly-CF'!L$9,'Annual-CF'!$L$9:$U$9,0)) -> 0 | M17: =INDEX('Annual-CF'!$L$17:$U$17,MATCH('Monthly-CF'!M$9,'Annual-CF'!$L$9:$U$9,0)) -> 0 | N17: =INDEX('Annual-CF'!$L$17:$U$17,MATCH('Monthly-CF'!N$9,'Annual-CF'!$L$9:$U$9,0)) -> 0 | O17: =INDEX('Annual-CF'!$L$17:$U$17,MATCH('Monthly-CF'!O$9,'Annual-CF'!$L$9:$U$9,0)) -> 0 | P17: =INDEX('Annual-CF'!$L$17:$U$17,MATCH('Monthly-CF'!P$9,'Annual-CF'!$L$9:$U$9,0)) -> 0 | Q17: =INDEX('Annual-CF'!$L$17:$U$17,MATCH('Monthly-CF'!Q$9,'Annual-CF'!$L$9:$U$9,0)) -> 0 | R17: =INDEX('Annual-CF'!$L$17:$U$17,MATCH('Monthly-CF'!R$9,'Annual-CF'!$L$9:$U$9,0)) -> 0 | S17: =INDEX('Annual-CF'!$L$17:$U$17,MATCH('Monthly-CF'!S$9,'Annual-CF'!$L$9:$U$9,0)) -> 0 | ... EA17: =INDEX('Annual-CF'!$L$17:$U$17,MATCH('Monthly-CF'!EA$9,'Annual-CF'!$L$9:$U$9,0)) -> 0.42331181 | EC17: x
D18: PSF - Multi-Family Ph.1 | E18: =Assumptions!F34 -> 103297 | G18: =Assumptions!H56 -> 0.04 | I18: =MAX(L18:EA18) -> 0 | L18: =L13*$E18 -> 0 | M18: =M13*$E18 -> 0 | N18: =N13*$E18 -> 0 | O18: =O13*$E18 -> 0 | P18: =P13*$E18 -> 0 | Q18: =Q13*$E18 -> 0 | R18: =R13*$E18 -> 0 | S18: =S13*$E18 -> 0 | ... EA18: =EA13*$E18 -> 0 | EC18: x
D19: PSF - Multi-Family Ph.2 | I19: =MAX(L19:EA19) -> 0 | L19: =L14*$E19 -> 0 | M19: =M14*$E19 -> 0 | N19: =N14*$E19 -> 0 | O19: =O14*$E19 -> 0 | P19: =P14*$E19 -> 0 | Q19: =Q14*$E19 -> 0 | R19: =R14*$E19 -> 0 | S19: =S14*$E19 -> 0 | ... EA19: =EA14*$E19 -> 0 | EC19: x
D20: =CONCATENATE("PSF - ",Assumptions!J54) -> PSF - Ancillary Fees | E20: =SUM(E18:E19) -> 103297 | G20: =Assumptions!J56 -> 0.04 | I20: =MAX(L20:EA20) -> 0 | L20: =L15*$E20 -> 0 | M20: =M15*$E20 -> 0 | N20: =N15*$E20 -> 0 | O20: =O15*$E20 -> 0 | P20: =P15*$E20 -> 0 | Q20: =Q15*$E20 -> 0 | R20: =R15*$E20 -> 0 | S20: =S15*$E20 -> 0 | ... EA20: =EA15*$E20 -> 0 | EC20: x
EC21: x
D22: Revenue | E22: Rent PSF / Mo | EC22: x
D23: Revenue - Multi-Family Ph.1 | E23: =Assumptions!H55 -> 2.7909813 | I23: =SUM(K23:EA23) -> 0 | L23: =IF(AND(L9>=1,L$9<=Assumptions!$M$57),(1+L17)*L13*$E$18*$E$23,0) -> 0 | M23: =IF(AND(M9>=1,M$9<=Assumptions!$M$57),(1+M17)*M13*$E$18*$E$23,0) -> 0 | N23: =IF(AND(N9>=1,N$9<=Assumptions!$M$57),(1+N17)*N13*$E$18*$E$23,0) -> 0 | O23: =IF(AND(O9>=1,O$9<=Assumptions!$M$57),(1+O17)*O13*$E$18*$E$23,0) -> 0 | P23: =IF(AND(P9>=1,P$9<=Assumptions!$M$57),(1+P17)*P13*$E$18*$E$23,0) -> 0 | Q23: =IF(AND(Q9>=1,Q$9<=Assumptions!$M$57),(1+Q17)*Q13*$E$18*$E$23,0) -> 0 | R23: =IF(AND(R9>=1,R$9<=Assumptions!$M$57),(1+R17)*R13*$E$18*$E$23,0) -> 0 | S23: =IF(AND(S9>=1,S$9<=Assumptions!$M$57),(1+S17)*S13*$E$18*$E$23,0) -> 0 | ... EA23: =IF(AND(EA9>=1,EA$9<=Assumptions!$M$57),(1+EA17)*EA13*$E$18*$E$23,0) -> 0 | EC23: x
D24: Revenue - Multi-Family Ph.2 | E24: =Assumptions!H55 -> 2.7909813 | I24: =SUM(K24:EA24) -> 0 | M24: =IF(AND(M10>=1,M$9<=Assumptions!$M$57),(1+M17)*M14*$E$19*$E$24,0) -> 0 | N24: =IF(AND(N10>=1,N$9<=Assumptions!$M$57),(1+N17)*N14*$E$19*$E$24,0) -> 0 | O24: =IF(AND(O10>=1,O$9<=Assumptions!$M$57),(1+O17)*O14*$E$19*$E$24,0) -> 0 | P24: =IF(AND(P10>=1,P$9<=Assumptions!$M$57),(1+P17)*P14*$E$19*$E$24,0) -> 0 | Q24: =IF(AND(Q10>=1,Q$9<=Assumptions!$M$57),(1+Q17)*Q14*$E$19*$E$24,0) -> 0 | R24: =IF(AND(R10>=1,R$9<=Assumptions!$M$57),(1+R17)*R14*$E$19*$E$24,0) -> 0 | S24: =IF(AND(S10>=1,S$9<=Assumptions!$M$57),(1+S17)*S14*$E$19*$E$24,0) -> 0 | T24: =IF(AND(T10>=1,T$9<=Assumptions!$M$57),(1+T17)*T14*$E$19*$E$24,0) -> 0 | ... EA24: =IF(AND(EA10>=1,EA$9<=Assumptions!$M$57),(1+EA17)*EA14*$E$19*$E$24,0) -> 0 | EC24: x
D25: =CONCATENATE("Revenue - ",Assumptions!J$54) -> Revenue - Ancillary Fees | E25: =Assumptions!J55 -> 0.18144767 | I25: =SUM(K25:EA25) -> 0 | L25: =IF(AND(L9>=1,L$9<=Assumptions!$M$57),(1+L17)*L15*$E$20*$E$25,0) -> 0 | M25: =IF(AND(M9>=1,M$9<=Assumptions!$M$57),(1+M17)*M15*$E$20*$E$25,0) -> 0 | N25: =IF(AND(N9>=1,N$9<=Assumptions!$M$57),(1+N17)*N15*$E$20*$E$25,0) -> 0 | O25: =IF(AND(O9>=1,O$9<=Assumptions!$M$57),(1+O17)*O15*$E$20*$E$25,0) -> 0 | P25: =IF(AND(P9>=1,P$9<=Assumptions!$M$57),(1+P17)*P15*$E$20*$E$25,0) -> 0 | Q25: =IF(AND(Q9>=1,Q$9<=Assumptions!$M$57),(1+Q17)*Q15*$E$20*$E$25,0) -> 0 | R25: =IF(AND(R9>=1,R$9<=Assumptions!$M$57),(1+R17)*R15*$E$20*$E$25,0) -> 0 | S25: =IF(AND(S9>=1,S$9<=Assumptions!$M$57),(1+S17)*S15*$E$20*$E$25,0) -> 0 | ... BQ25: =IF(AND(BQ9>=1,BQ$9<=Assumptions!$M$57),(1+BQ17)*BQ15*$E$20*$E$25,0) -> 0 | BR25: =IF(AND(BR9>=1,BR$8<=Assumptions!$M$58),(1+BR17)*BR15*$E$20*$E$25,0) -> 0 | BS25: =IF(AND(BS9>=1,BS$8<=Assumptions!$M$58),(1+BS17)*BS15*$E$20*$E$25,0) -> 0 | BT25: =IF(AND(BT9>=1,BT$9<=Assumptions!$M$57),(1+BT17)*BT15*$E$20*$E$25,0) -> 0 | BU25: =IF(AND(BU9>=1,BU$9<=Assumptions!$M$57),(1+BU17)*BU15*$E$20*$E$25,0) -> 0 | BV25: =IF(AND(BV9>=1,BV$9<=Assumptions!$M$57),(1+BV17)*BV15*$E$20*$E$25,0) -> 0 | BW25: =IF(AND(BW9>=1,BW$9<=Assumptions!$M$57),(1+BW17)*BW15*$E$20*$E$25,0) -> 0 | BX25: =IF(AND(BX9>=1,BX$9<=Assumptions!$M$57),(1+BX17)*BX15*$E$20*$E$25,0) -> 0 | BY25: =IF(AND(BY9>=1,BY$9<=Assumptions!$M$57),(1+BY17)*BY15*$E$20*$E$25,0) -> 0 | BZ25: =IF(AND(BZ9>=1,BZ$9<=Assumptions!$M$57),(1+BZ17)*BZ15*$E$20*$E$25,0) -> 0 | CA25: =IF(AND(CA9>=1,CA$9<=Assumptions!$M$57),(1+CA17)*CA15*$E$20*$E$25,0) -> 0 | ... EA25: =IF(AND(EA9>=1,EA$9<=Assumptions!$M$57),(1+EA17)*EA15*$E$20*$E$25,0) -> 0 | EC25: x
EC26: x
D27: Rent Concessions | I27: =SUM(K27:EA27) -> 0 | L27: =-IF(L9<=Assumptions!$M$57,(((L18-K18)*Assumptions!$I$77*$E$23*(1+L$17))+((L19-K19)*Assumptions!$I$77*$E$24*(1+L$17))),0) -> 0 | M27: =-IF(M9<=Assumptions!$M$57,(((M18-L18)*Assumptions!$I$77*$E$23*(1+M$17))+((M19-L19)*Assumptions!$I$77*$E$24*(1+M$17))),0) -> 0 | N27: =-IF(N9<=Assumptions!$M$57,(((N18-M18)*Assumptions!$I$77*$E$23*(1+N$17))+((N19-M19)*Assumptions!$I$77*$E$24*(1+N$17))),0) -> 0 | O27: =-IF(O9<=Assumptions!$M$57,(((O18-N18)*Assumptions!$I$77*$E$23*(1+O$17))+((O19-N19)*Assumptions!$I$77*$E$24*(1+O$17))),0) -> 0 | P27: =-IF(P9<=Assumptions!$M$57,(((P18-O18)*Assumptions!$I$77*$E$23*(1+P$17))+((P19-O19)*Assumptions!$I$77*$E$24*(1+P$17))),0) -> 0 | Q27: =-IF(Q9<=Assumptions!$M$57,(((Q18-P18)*Assumptions!$I$77*$E$23*(1+Q$17))+((Q19-P19)*Assumptions!$I$77*$E$24*(1+Q$17))),0) -> 0 | R27: =-IF(R9<=Assumptions!$M$57,(((R18-Q18)*Assumptions!$I$77*$E$23*(1+R$17))+((R19-Q19)*Assumptions!$I$77*$E$24*(1+R$17))),0) -> 0 | S27: =-IF(S9<=Assumptions!$M$57,(((S18-R18)*Assumptions!$I$77*$E$23*(1+S$17))+((S19-R19)*Assumptions!$I$77*$E$24*(1+S$17))),0) -> 0 | ... EA27: =-IF(EA9<=Assumptions!$M$57,(((EA18-DZ18)*Assumptions!$I$77*$E$23*(1+EA$17))+((EA19-DZ19)*Assumptions!$I$77*$E$24*(1+EA$17))),0) -> 0 | EC27: x
D28: Net Revenue | I28: =SUM(K28:EA28) -> 0 | L28: =SUM(L23:L25)+SUM(L27:L27) -> 0 | M28: =SUM(M23:M25)+SUM(M27:M27) -> 0 | N28: =SUM(N23:N25)+SUM(N27:N27) -> 0 | O28: =SUM(O23:O25)+SUM(O27:O27) -> 0 | P28: =SUM(P23:P25)+SUM(P27:P27) -> 0 | Q28: =SUM(Q23:Q25)+SUM(Q27:Q27) -> 0 | R28: =SUM(R23:R25)+SUM(R27:R27) -> 0 | S28: =SUM(S23:S25)+SUM(S27:S27) -> 0 | ... EA28: =SUM(EA23:EA25)+SUM(EA27:EA27) -> 0 | EC28: x
EC29: x
